Workbook
Name FORWASTforbrug: #REF!

Sheet Input
B2: Nykredits Smartbudget
B3: Inputtal fra brugere | D3: Alle celler udpeget med --> er inputceller
C4: -->
B5: Voksne i husstanden:
B6: Antal mænd: | C6: --> | D6: 1
B7: Antal kvinder: | C7: --> | D7: 1
B8: Voksne i alt: | D8: =SUM(D6:D7) -> 2
B10: Gift eller ugift
B12: Indtægter pr. måned: | D12: Efter skat | E12: Før skat
B13: Person 1 | C13: --> | D13: 10000 | E13: =Skatteprocenter!Q108 -> 17685.593
B14: Person 2 | C14: --> | D14: 100000 | E14: =Skatteprocenter!Q109 -> 176855.93
B15: Person 3 | C15: --> | D15: 0 | E15: =Skatteprocenter!Q110 -> 0
B16: Person 4 | C16: --> | D16: 0 | E16: =Skatteprocenter!Q111 -> 0
B17: Person 5 | C17: --> | D17: 0 | E17: =Skatteprocenter!Q112 -> 0
B18: Person 6 | C18: --> | D18: 0 | E18: =Skatteprocenter!Q113 -> 0
B19: Løn pr. måned i alt: | D19: =SUM(D13:D18) -> 110000 | E19: =SUM(E13:E18) -> 194541.52
B21: Andre indtægter pr. måned:
B22: f.eks. udbytter mv. | C22: --> | D22: 1
B24: Børn: | D24: Skriv antal
B25: 0-2 år | C25: --> | D25: 1
B26: 3-6 år | C26: --> | D26: 0
B27: 7-14 år | C27: --> | D27: 0
B28: 15-17 år | C28: --> | D28: 0
B29: Antal børn i alt: | D29: =D25+D26+D27+D28 -> 1
B31: Bolig:
B32: Kommune | C32: -->
B33: Boligudgift pr. måned | C33: --> | D33: 0
B34: Boligtype | C34: -->
B35: Antal m2 bolig | C35: --> | D35: 0 | F35: 1 | G35: <-- Hvis antal m2 bolig mindre end dette, så bruges DS tal
B36: Varmekilde | C36: -->
B37: Ejendomsskat (grundskyld) | C37: --> | D37: 0
B39: Biler:
B40: Bil 1 - vælg | C40: --> | G40: Lille bil kører over 20 kilometer på en liter benzin
B41: Bil 2 - vælg | C41: --> | G41: Mellemstor bil kører ca. 14 kilometer på en liter benzin
B42: Bil 3 - vælg | C42: --> | G42: Stor bil kører ca.10 kilometer på en liter benzin
G43: Meget stor bil kører 6-7 kilometer på en liter benzin
B44: Benzin - forbrug pr. måned | C44: --> | D44: 0
B45: Billån pr. måned | C45: --> | D45: 0
B47: Renteudgifter til andre lån pr. måned | C47: --> | D47: 0
B49: Opsparing pr. måned | C49: --> | D49: 0

Sheet Budget
B2: Nykredits Smartbudget
B3: Outputtal til brugerne | J3: Faktorer til at beregne CO2
J4: Enlig uden børn: | K4: Enlig med børn:
B5: Familien: | J5: 7 | K5: 10
B6: Antal voksne: | D6: =Input!D8 -> 2 | J6: 2 v uden børn: | K6: 2 v med børn:
B7: Antal børn: | D7: =Input!D29 -> 1 | J7: 13 | K7: 16
B8: Antal biler: | D8: =Data!K41 -> 0
B9: Boligtype: | D9: =Dialog!B14 -> Alle boliger
B10: Kommune: | D10: =VLOOKUP(Dialog!M3,Kommunedata!B4:D101,3) -> Albertslund
B11: Budgettet
B12: Udgifter pr. måned i alt: | D12: =SUM(D13:D17) -> 24351.639 | E12: Indtægter pr. måned: | F12: =SUM(F13:F17) -> 111533 | G12: Overskud | H12: =F12-D12 -> 87181.361 | I12: kr. pr. måned | K12: ='Data-DS'!H8 -> Enlig uden børn: | L12: =IF(AND(D6=1,D7=0),1,"")
B13: Privatforbrug | D13: =E21 -> 14155.608 | E13: Indtægt i alt | F13: =Input!D13+Input!D14+Input!D15+Input!D16 -> 110000 | G13: Overskud | H13: =H12*12 -> 1046176.3 | I13: kr. pr. år | K13: ='Data-DS'!I8 -> Enlig med børn: | L13: =IF(AND(D6=1,D7>0),2,"")
B14: Bolig | D14: =E30 -> 3202.6833 | E14: Andre indtægter | F14: =Input!D22 -> 1 | G14: Opsparing | H14: =Input!D49 -> 0 | I14: kr. pr. måned | K14: ='Data-DS'!H11 -> 2 v uden børn: | L14: =IF(AND(D6>=2,D7=0),3,"")
B15: Familie | D15: =E44 -> 6624.2214 | G15: Opsparing | H15: =H14*12 -> 0 | I15: kr. pr. år | K15: ='Data-DS'!I11 -> 2 v med børn: | L15: =IF(AND(D6>=2,D7>0),4,"") -> 4
B16: Transport | D16: =E62 -> 369.1272 | G16: Overskud herefter | H16: =H12-H14 -> 87181.361 | I16: kr. pr. måned | K16: Valg | L16: =MAX(L12:L15) -> 4
B17: Renter på andre lån | D17: =Input!D47 -> 0 | E17: Børnecheck | F17: =IF(Modeller!E13<=0,0,Modeller!E13/12) -> 1532 | G17: Overskud herefter | H17: =H13-H15 -> 1046176.3 | I17: kr. pr. år
A20: ID | D20: Pr. år | E20: Pr. måned | F20: CO2 (ton) per husstand | G20: Per person | H20: Hvem? | I20: Huske | J20: Opdateret
B21: Privatforbrug | D21: =SUM(D22:D28) -> 169867.29 | E21: =D21/12 -> 14155.608
A22: 1 | B22: Dagligvarer og husholdning | D22: ='Data-DS'!E14 -> 73716.985 | E22: =D22/12 -> 6143.082 | H22: Hans | J22: 2020 | K22: Danmarks Statistik
A23: 2 | B23: Tøj og sko | D23: ='Data-DS'!E25 -> 21331.811 | E23: =D23/12 -> 1777.6509 | H23: Hans | J23: 2020 | K23: Danmarks Statistik
A24: 3 | B24: Boligudstyr og indretning | D24: ='Data-DS'!E36 -> 19307.109 | E24: =D24/12 -> 1608.9258 | H24: Hans | J24: 2020 | K24: Danmarks Statistik
A25: 4 | B25: Medicin og øvrige lægeudgifter | D25: ='Data-DS'!E47 -> 4991.1343 | E25: =D25/12 -> 415.92786 | H25: Hans | J25: 2020 | K25: Danmarks Statistik
A26: 5 | B26: Tandlæge | D26: ='Data-DS'!E58 -> 2821.4548 | E26: =D26/12 -> 235.12123 | H26: Hans | J26: 2020 | K26: Danmarks Statistik
A27: 6 | B27: Gaver | D27: ='Data-DS'!E69 -> 4900 | E27: =D27/12 -> 408.33333 | H27: Hans | J27: 2020 | K27: Egne tal
A28: 7 | B28: Ferie, fritid og underholdning | D28: ='Data-DS'!E80 -> 42798.796 | E28: =D28/12 -> 3566.5663 | H28: Hans | J28: 2020 | K28: Danmarks Statistik
B30: Bolig | D30: =SUM(D31:D42) -> 38432.2 | E30: =SUM(E31:E42) -> 3202.6833
A31: 8 | B31: Boligudgift | D31: =Input!D33*12 -> 0 | E31: =D31/12 -> 0 | H31: Bruger | K31: Bruger
A32: 9 | B32: Husforsikring | D32: =Dialog!S8 -> 5764 | E32: =D32/12 -> 480.33333 | H32: Nykredit | J32: 2020 | K32: Nykredit Forsikring - efter kommune
A33: 10 | B33: Indboforsikring | D33: =Dialog!R8 -> 3434 | E33: =D33/12 -> 286.16667 | H33: Nykredit | J33: 2020 | K33: Nykredit Forsikring - efter kommune
A34: 11 | B34: Vedligeholdelse | D34: =IF(Input!D35>=Input!F35,Modeller!E195,'Data-DS'!C185) -> 4611.1 | E34: =D34/12 -> 384.25833 | H34: Hans | K34: Model
A35: 12 | B35: Ejendomsskat | D35: =Input!D37 -> 0 | E35: =D35/12 -> 0 | H35: BBR | K35: BBR efter adresse
A36: 13 | B36: Grundejerforening | C36: --> | D36: 0 | E36: =D36/12 -> 0 | H36: Bruger | K36: Bruger
A37: 14 | B37: Fællesudgifter | C37: --> | D37: 0 | E37: =D37/12 -> 0 | H37: Bruger | K37: Bruger
A38: 15 | B38: Fritidshus udgifter | C38: --> | D38: 0 | E38: =D38/12 -> 0 | H38: Bruger | K38: Bruger
A39: 16 | B39: Varme | D39: =IF((Input!D8+Input!D29)=0,0,IF(Input!D35>=Input!F35,Modeller!E38,'Data-DS'!C186)) -> 12715 | E39: =D39/12 -> 1059.5833 | H39: Hans | K39: Beregnet ud fra boligtype, m2 og varmekilde. Se under modeller
A40: 17 | B40: Brænde | C40: --> | D40: 0 | E40: =D40/12 -> 0 | H40: Bruger | K40: Bruger
A41: 18 | B41: El/gas | D41: =IF((Input!D8+Input!D29)=0,0,IF(Input!D35>=Input!F35,Modeller!E95,'Data-DS'!C187)) -> 7365.3 | E41: =D41/12 -> 613.775 | H41: Hans | K41: Beregnet ud fra m2 og antal personer. Se under modeller.
A42: 19 | B42: Vand | D42: =IF((Input!D8+Input!D29)=0,0,IF(Input!D35>=Input!F35,Modeller!E115,'Data-DS'!C188)) -> 4542.8 | E42: =D42/12 -> 378.56667 | H42: Hans | K42: Beregnet ud fra antal m2 og antal personer. Se under modeller
B44: Familie | D44: =SUM(D45:D60) -> 79490.656 | E44: =SUM(E45:E60) -> 6624.2214
A45: 20 | B45: Skole | C45: --> | D45: 0 | E45: =D45/12 -> 0 | H45: Bruger | K45: Bruger - f.eks. privatskole
...

Sheet Data-DS
A1: Voksenækvivalenterne | B1: OECD | C1: I model | D1: Hvis(valg… | J1: Familierne antallet af forbrugsenheder: | AI1: Personer | AJ1: Forbrugsenheder
A2: Første person > 14 år | B2: 1 | C2: 1 | D2: Forbrug for | G2: Fra Danmarks Statistik | J2: Enlig uden børn: | K2: 1 | L2: Enlig med børn: | M2: 1.5 | AJ2: (voksenækvivalenter) | AL2: Voksenækvivalenterne | AM2: OECD | AN2: I model
A3: Efterfølgende > 14 år | B3: 0.5 | C3: 0.5 | D3: 1. En forsørger | E3: Valg af antal | F3: Valg af | G3: Alle | H3: Under 60 | I3: Under 60 | J3: 2 v uden børn: | K3: 1.5 | L3: 2 v med børn: | M3: 2.1 | AH3: Antal voksne i familien | AI3: =Input!D8 -> 2 | AL3: Første person > 14 år | AM3: 1 | AN3: 1
A4: Børn 0-14 år | B4: 0.3 | C4: 0.3 | D4: 2. Flere forsørgere | E4: forsørgere: | F4: antal børn: | G4: husstande | H4: Ingen børn | I4: med børn | L4: Alle husstande | M4: 1.5 | AH4: Børn 0-2 år --> | AI4: =Input!D25 -> 1 | AL4: Efterfølgende > 14 år | AM4: 0.5 | AN4: 0.5
A5: Efter to børn | C5: 0.2 | D5: Valgt antal voksne / antal børn | E5: =Input!D8 -> 2 | F5: =Input!D29 -> 1 | K5: Valgte antal forbrugsenheder | M5: =AJ11 -> 1.8 | AH5: Børn 3-6 år --> | AI5: =Input!D26 -> 0 | AL5: Børn 0-14 år | AM5: 0.3 | AN5: 0.3
AF6: Copy | AH6: Børn 7-14 år --> | AI6: =Input!D27 -> 0 | AL6: Efter to børn | AN6: 0.2
A7: Privatforbrug | C7: Tjek | H7: Tal der styrer: | I7: Juster efter disse: | J7: Forbrugsenheder pr. barn: | L7: Antal børn --> | M7: 0 | N7: =M7+1 -> 1 | O7: =N7+1 -> 2 | P7: =O7+1 -> 3 | Q7: =P7+1 -> 4 | R7: =Q7+1 -> 5 | S7: =R7+1 -> 6 | T7: =S7+1 -> 7 | U7: =T7+1 -> 8 | V7: Forbrugsenhed: | W7: Vækst år til år --> | X7: 0-1 | Y7: 1-2 | Z7: 2-3 | AA7: 3-4 | AB7: 4-5 | AC7: 5-6 | AD7: 6-7 | AE7: 7-8 | AF7: =ROUND(H10,0) -> 29246 | AH7: Børn 15-17 år --> | AI7: =Input!D28 -> 0
A8: Dagligvarer og husholdning | C8: 2018 ok | H8: Enlig uden børn: | I8: Enlig med børn: | J8: Enlig uden børn: | K8: Enlig med børn: | L8: % op --> | M8: 0 | N8: =X8 -> 36.7 | O8: =Y8 -> 23.3 | P8: =Z8 -> 17 | Q8: =AA8 -> 10.2 | R8: =AB8 -> 8.3 | S8: =AC8 -> 6.9 | T8: =AD8 -> 5.8 | U8: =AE8 -> 4.9 | V8: =K8 -> Enlig med børn: | W8: % op --> | X8: =ROUND(X10*100/M10,1) -> 36.7 | Y8: =ROUND(Y10*100/N10,1) -> 23.3 | Z8: =ROUND(Z10*100/O10,1) -> 17 | AA8: =ROUND(AA10*100/P10,1) -> 10.2 | AB8: =ROUND(AB10*100/Q10,1) -> 8.3 | AC8: =ROUND(AC10*100/R10,1) -> 6.9 | AD8: =ROUND(AD10*100/S10,1) -> 5.8 | AE8: =ROUND(AE10*100/T10,1) -> 4.9 | AF8: =M8&"; "&N8&"; "&O8&"; "&P8&"; "&Q8&"; "&R8&"; "&S8&"; "&T8&"; "&U8 -> 0; 36,7; 23,3; 17; 10,2; 8,3; 6,9; 5,8; 4,9 | AH8: Voksne i alt >14 år | AI8: =AI3+AI7 -> 2 | AJ8: =SUM(AM8:AO8) -> 1.5 | AL8: Beregning af FE-voksne: | AM8: =IF(AI8<1,0,1) -> 1 | AN8: =IF(AM8>=1,(AI8-1)*AN4,0) -> 0.5
A9: Forbrugsenheder | B9: --> | G9: =A9 -> Forbrugsenheder | H9: 0.80712006 | I9: 1.3602925
C10: Én | D10: 1. Dagligvarer og husholdning | E10: =IF(Data!$E$4=1,F10,IF(Data!$E$4=2,0,0)) -> 0 | F10: =IF(Data!$E$5=0,M10,IF(Data!$E$5=1,N10,IF(Data!$E$5=2,O10,IF(Data!$E$5=3,P10,IF(Data!$E$5=4,Q10,IF(Data!$E$5=5,R10,IF(Data!$E$5=6,S10,IF(Data!$E$5=7,T10,U10)))))))) -> 39978.908 | H10: =G15*H9 -> 29245.726 | I10: =G15*I9 -> 49289.744 | J10: =H10*$C$4/$K$2 -> 8773.7179 | K10: =I10*$C$4/$M$2 -> 9857.9487 | L10: kr. pr. år --> | M10: =H10 -> 29245.726 | N10: =M10+M10*N8% -> 39978.908 | O10: =N10+N10*O8% -> 49293.993 | P10: =O10+O10*P8% -> 57673.972 | Q10: =P10+P10*Q8% -> 63556.717 | R10: =Q10+Q10*R8% -> 68831.925 | S10: =R10+R10*S8% -> 73581.328 | T10: =S10+S10*T8% -> 77849.045 | U10: =T10+T10*U8% -> 81663.648 | V10: =K10 -> 9857.9487 | W10: Kroner op --> | X10: =700+(I10-H10)/2 -> 10722.009 | Y10: =I10-(H10+X10) -> 9322.0086 | Z10: =Y10*90% -> 8389.8078 | AA10: =Z10*70% -> 5872.8654 | AB10: =AA10*90% -> 5285.5789 | AC10: =AB10*90% -> 4757.021 | AD10: =AC10*90% -> 4281.3189 | AE10: =AD10*90% -> 3853.187 | AF10: =ROUND(H13,0) -> 55426 | AH10: Børn i alt <14 år | AI10: =SUM(AI4:AI6) -> 1 | AJ10: =SUM(AM10:AO10) -> 0.3 | AL10: Beregning af FE-børn: | AM10: =IF(AI10<1,0,AN5) -> 0.3 | AN10: =IF(AI10>1,AN5,0) -> 0 | AO10: =IF(AI10>2,(AI10-2)*AN6,0) -> 0
B11: =(H13/1.5)*0.5 -> 18475.435 | H11: 2 v uden børn: | I11: 2 v med børn: | J11: 2 v uden børn: | K11: 2 v med børn: | L11: % op --> | M11: 0 | N11: =X11 -> 33 | O11: =Y11 -> 22.9 | P11: =Z11 -> 16.8 | Q11: =AA11 -> 10 | R11: =AB11 -> 8.2 | S11: =AC11 -> 6.8 | T11: =AD11 -> 5.8 | U11: =AE11 -> 4.9 | V11: =K11 -> 2 v med børn: | W11: % op --> | X11: =ROUND(X13*100/M13,1) -> 33 | Y11: =ROUND(Y13*100/N13,1) -> 22.9 | Z11: =ROUND(Z13*100/O13,1) -> 16.8 | AA11: =ROUND(AA13*100/P13,1) -> 10 | AB11: =ROUND(AB13*100/Q13,1) -> 8.2 | AC11: =ROUND(AC13*100/R13,1) -> 6.8 | AD11: =ROUND(AD13*100/S13,1) -> 5.8 | AE11: =ROUND(AE13*100/T13,1) -> 4.9 | AF11: =M11&"; "&N11&"; "&O11&"; "&P11&"; "&Q11&"; "&R11&"; "&S11&"; "&T11&"; "&U11 -> 0; 33; 22,9; 16,8; 10; 8,2; 6,8; 5,8; 4,9 | AH11: Forbrugsenheder i alt | AJ11: =SUM(AJ8:AJ10) -> 1.8
A12: =A9 -> Forbrugsenheder | B12: --> | G12: =A12 -> Forbrugsenheder | H12: 1.5296485 | I12: 2.5
A13: Flere end 2 voksne så pr. stk. | B13: =H13*0.5/1.5 -> 18475.435 | C13: To | D13: 2. Dagligvarer og husholdning | E13: =IF(Data!$E$4=1,0,IF(Data!$E$4=2,F13,F13+B13*Data!G4)) -> 73716.985 | F13: =IF(Data!$E$5=0,M13,IF(Data!$E$5=1,N13,IF(Data!$E$5=2,O13,IF(Data!$E$5=3,P13,IF(Data!$E$5=4,Q13,IF(Data!$E$5=5,R13,IF(Data!$E$5=6,S13,IF(Data!$E$5=7,T13,U13)))))))) -> 73716.985 | H13: =G15*H12 -> 55426.304 | I13: =G15*I12 -> 90586.667 | J13: =H13*$C$4/$K$3 -> 11085.261 | K13: =I13*$C$4/$M$3 -> 12940.952 | L13: kr. pr. år --> | M13: =H13 -> 55426.304 | N13: =M13+M13*N11% -> 73716.985 | O13: =N13+N13*O11% -> 90598.174 | P13: =O13+O13*P11% -> 105818.67 | Q13: =P13+P13*Q11% -> 116400.53 | R13: =Q13+Q13*R11% -> 125945.38 | S13: =R13+R13*S11% -> 134509.66 | T13: =S13+S13*T11% -> 142311.22 | U13: =T13+T13*U11% -> 149284.47 | V13: =K13 -> 12940.952 | W13: Kroner op --> | X13: =700+(I13-H13)/2 -> 18280.181 | Y13: =I13-(H13+X13) -> 16880.181 | Z13: =Y13*90% -> 15192.163 | AA13: =Z13*70% -> 10634.514 | AB13: =AA13*90% -> 9571.0628 | AC13: =AB13*90% -> 8613.9565 | AD13: =AC13*90% -> 7752.5608 | AE13: =AD13*90% -> 6977.3048 | AF13: =ROUND(B13,0) -> 18475
D14: Valg 1, 2 eller flere | E14: =IF(Data!$E$4=0,0,IF(Data!$E$4=1,E10,IF(Data!$E$4=2,E13,E13))) -> 73716.985 | G14: ='DS-tal-valgte'!D13 -> 54352 | H14: Forbrugsenheder aktuelt: | I14: I alt efter forbrugsenheder:
D15: Kroner pr. forbrugsenhed | E15: =E14/$AJ$11 -> 40953.88 | G15: =G14/$M$4 -> 36234.667 | H15: =$AJ$11 -> 1.8 | I15: =H15*G15 -> 65222.4
D16: Test: Endeligt forbrug pr. måned: | E16: =E14/12 -> 6143.082
H18: Tal der styrer: | I18: Juster efter disse: | J18: Forbrugsenheder pr. barn: | L18: Antal børn --> | M18: 0 | N18: =M18+1 -> 1 | O18: =N18+1 -> 2 | P18: =O18+1 -> 3 | Q18: =P18+1 -> 4 | R18: =Q18+1 -> 5 | S18: =R18+1 -> 6 | T18: =S18+1 -> 7 | U18: =T18+1 -> 8 | V18: Forbrugsenhed: | W18: Vækst år til år --> | X18: 0-1 | Y18: 1-2 | Z18: 2-3 | AA18: 3-4 | AB18: 4-5 | AC18: 5-6 | AD18: 6-7 | AE18: 7-8 | AF18: =ROUND(H21,0) -> 8004
A19: Tøj/sko | C19: =$C$8 -> 2018 ok | H19: Enlig uden børn: | I19: Enlig med børn: | J19: Enlig uden børn: | K19: Enlig med børn: | L19: % op --> | M19: 0 | N19: =X19 -> 28.7 | O19: =Y19 -> 8.7 | P19: =Z19 -> 7.2 | Q19: =AA19 -> 4.7 | R19: =AB19 -> 4 | S19: =AC19 -> 3.5 | T19: =AD19 -> 3 | U19: =AE19 -> 2.7 | V19: =K19 -> Enlig med børn: | W19: % op --> | X19: =ROUND(X21*100/M21,1) -> 28.7 | Y19: =ROUND(Y21*100/N21,1) -> 8.7 | Z19: =ROUND(Z21*100/O21,1) -> 7.2 | AA19: =ROUND(AA21*100/P21,1) -> 4.7 | AB19: =ROUND(AB21*100/Q21,1) -> 4 | AC19: =ROUND(AC21*100/R21,1) -> 3.5 | AD19: =ROUND(AD21*100/S21,1) -> 3 | AE19: =ROUND(AE21*100/T21,1) -> 2.7 | AF19: =M19&"; "&N19&"; "&O19&"; "&P19&"; "&Q19&"; "&R19&"; "&S19&"; "&T19&"; "&U19 -> 0; 28,7; 8,7; 7,2; 4,7; 4; 3,5; 3; 2,7
A20: =$A$9 -> Forbrugsenheder | G20: =A20 -> Forbrugsenheder | H20: 0.85508123 | I20: 1.1955281
C21: Én | D21: 1. Tøj/sko | E21: =IF(Data!$E$4=1,F21,IF(Data!$E$4=2,0,0)) -> 0 | F21: =IF(Data!$E$5=0,M21,IF(Data!$E$5=1,N21,IF(Data!$E$5=2,O21,IF(Data!$E$5=3,P21,IF(Data!$E$5=4,Q21,IF(Data!$E$5=5,R21,IF(Data!$E$5=6,S21,IF(Data!$E$5=7,T21,U21)))))))) -> 10300.582 | H21: =G26*H20 -> 8003.5603 | I21: =G26*I20 -> 11190.143 | J21: =H21*$C$4/$K$2 -> 2401.0681 | K21: =I21*$C$4/$M$2 -> 2238.0286 | L21: kr. pr. år --> | M21: =H21 -> 8003.5603 | N21: =M21+M21*N19% -> 10300.582 | O21: =N21+N21*O19% -> 11196.733 | P21: =O21+O21*P19% -> 12002.898 | Q21: =P21+P21*Q19% -> 12567.034 | R21: =Q21+Q21*R19% -> 13069.715 | S21: =R21+R21*S19% -> 13527.155 | T21: =S21+S21*T19% -> 13932.97 | U21: =T21+T21*U19% -> 14309.16 | V21: =K21 -> 2238.0286 | W21: Kroner op --> | X21: =700+(I21-H21)/2 -> 2293.2914 | Y21: =I21-(H21+X21) -> 893.29141 | Z21: =Y21*90% -> 803.96227 | AA21: =Z21*70% -> 562.77359 | AB21: =AA21*90% -> 506.49623 | AC21: =AB21*90% -> 455.84661 | AD21: =AC21*90% -> 410.26194 | AE21: =AD21*90% -> 369.23575 | AF21: =ROUND(H24,0) -> 19393
H22: 2 v uden børn: | I22: 2 v med børn: | J22: 2 v uden børn: | K22: 2 v med børn: | L22: % op --> | M22: 0 | N22: =X22 -> 10 | O22: =Y22 -> 2.5 | P22: =Z22 -> 2.2 | Q22: =AA22 -> 1.5 | R22: =AB22 -> 1.4 | S22: =AC22 -> 1.2 | T22: =AD22 -> 1.1 | U22: =AE22 -> 1 | V22: =K22 -> 2 v med børn: | W22: % op --> | X22: =ROUND(X24*100/M24,1) -> 10 | Y22: =ROUND(Y24*100/N24,1) -> 2.5 | Z22: =ROUND(Z24*100/O24,1) -> 2.2 | AA22: =ROUND(AA24*100/P24,1) -> 1.5 | AB22: =ROUND(AB24*100/Q24,1) -> 1.4 | AC22: =ROUND(AC24*100/R24,1) -> 1.2 | AD22: =ROUND(AD24*100/S24,1) -> 1.1 | AE22: =ROUND(AE24*100/T24,1) -> 1 | AF22: =M22&"; "&N22&"; "&O22&"; "&P22&"; "&Q22&"; "&R22&"; "&S22&"; "&T22&"; "&U22 -> 0; 10; 2,5; 2,2; 1,5; 1,4; 1,2; 1,1; 1
A23: =$A$9 -> Forbrugsenheder | G23: =A23 -> Forbrugsenheder | H23: 2.0718542 | I23: 2.3372833
A24: Flere end 2 voksne så pr. stk. | B24: =(H24/1.5)*0.5 -> 6464.1852 | C24: To | D24: 2. Tøj/sko | E24: =IF(Data!$E$4=1,0,IF(Data!$E$4=2,F24,F24+B24*Data!G4)) -> 21331.811 | F24: =IF(Data!$E$5=0,M24,IF(Data!$E$5=1,N24,IF(Data!$E$5=2,O24,IF(Data!$E$5=3,P24,IF(Data!$E$5=4,Q24,IF(Data!$E$5=5,R24,IF(Data!$E$5=6,S24,IF(Data!$E$5=7,T24,U24)))))))) -> 21331.811 | H24: =G26*H23 -> 19392.556 | I24: =G26*I23 -> 21876.972 | J24: =H24*$C$4/$K$3 -> 3878.5111 | K24: =I24*$C$4/$M$3 -> 3125.2817 | L24: kr. pr. år --> | M24: =H24 -> 19392.556 | N24: =M24+M24*N22% -> 21331.811 | O24: =N24+N24*O22% -> 21865.107 | P24: =O24+O24*P22% -> 22346.139 | Q24: =P24+P24*Q22% -> 22681.331 | R24: =Q24+Q24*R22% -> 22998.87 | S24: =R24+R24*S22% -> 23274.856 | T24: =S24+S24*T22% -> 23530.88 | U24: =T24+T24*U22% -> 23766.188 | V24: =K24 -> 3125.2817 | W24: Kroner op --> | X24: =700+(I24-H24)/2 -> 1942.2081 | Y24: =I24-(H24+X24) -> 542.20806 | Z24: =Y24*90% -> 487.98725 | AA24: =Z24*70% -> 341.59108 | AB24: =AA24*90% -> 307.43197 | AC24: =AB24*90% -> 276.68877 | AD24: =AC24*90% -> 249.0199 | AE24: =AD24*90% -> 224.11791 | AF24: =ROUND(B24,0) -> 6464
D25: Valg 1, 2 eller flere | E25: =IF(Data!$E$4=0,0,IF(Data!$E$4=1,E21,IF(Data!$E$4=2,E24,E24))) -> 21331.811 | G25: ='DS-tal-valgte'!D22 -> 14040 | H25: =$H$14 -> Forbrugsenheder aktuelt: | I25: =$I$14 -> I alt efter forbrugsenheder:
D26: Kroner pr. forbrugsenhed | E26: =E25/$AJ$11 -> 11851.006 | G26: =G25/$M$4 -> 9360 | H26: =$AJ$11 -> 1.8 | I26: =H26*G26 -> 16848
D27: Test: Endeligt forbrug pr. måned: | E27: =E25/12 -> 1777.6509
H29: Tal der styrer: | I29: Juster efter disse: | J29: Forbrugsenheder pr. barn: | L29: Antal børn --> | M29: 0 | N29: =M29+1 -> 1 | O29: =N29+1 -> 2 | P29: =O29+1 -> 3 | Q29: =P29+1 -> 4 | R29: =Q29+1 -> 5 | S29: =R29+1 -> 6 | T29: =S29+1 -> 7 | U29: =T29+1 -> 8 | V29: Forbrugsenhed: | W29: Vækst år til år --> | X29: 0-1 | Y29: 1-2 | Z29: 2-3 | AA29: 3-4 | AB29: 4-5 | AC29: 5-6 | AD29: 6-7 | AE29: 7-8 | AF29: =ROUND(H32,0) -> 7614
A30: Boligudstyr og indretning | C30: =$C$8 -> 2018 ok | G30: Alle | H30: Enlig uden børn: | I30: Enlig med børn: | J30: Enlig uden børn: | K30: Enlig med børn: | L30: % op --> | M30: 0 | N30: =X30 -> 16.1 | O30: =Y30 -> 2.5 | P30: =Z30 -> 2.2 | Q30: =AA30 -> 1.5 | R30: =AB30 -> 1.4 | S30: =AC30 -> 1.2 | T30: =AD30 -> 1.1 | U30: =AE30 -> 1 | V30: =K30 -> Enlig med børn: | W30: % op --> | X30: =ROUND(X32*100/M32,1) -> 16.1 | Y30: =ROUND(Y32*100/N32,1) -> 2.5 | Z30: =ROUND(Z32*100/O32,1) -> 2.2 | AA30: =ROUND(AA32*100/P32,1) -> 1.5 | AB30: =ROUND(AB32*100/Q32,1) -> 1.4 | AC30: =ROUND(AC32*100/R32,1) -> 1.2 | AD30: =ROUND(AD32*100/S32,1) -> 1.1 | AE30: =ROUND(AE32*100/T32,1) -> 1 | AF30: =M30&"; "&N30&"; "&O30&"; "&P30&"; "&Q30&"; "&R30&"; "&S30&"; "&T30&"; "&U30 -> 0; 16,1; 2,5; 2,2; 1,5; 1,4; 1,2; 1,1; 1
A31: =$A$9 -> Forbrugsenheder | G31: =A31 -> Forbrugsenheder | H31: 0.88130345 | I31: 1.0490098
C32: Én | D32: 1. Boligudstyr og indretning | E32: =IF(Data!$E$4=1,F32,IF(Data!$E$4=2,0,0)) -> 0 | F32: =IF(Data!$E$5=0,M32,IF(Data!$E$5=1,N32,IF(Data!$E$5=2,O32,IF(Data!$E$5=3,P32,IF(Data!$E$5=4,Q32,IF(Data!$E$5=5,R32,IF(Data!$E$5=6,S32,IF(Data!$E$5=7,T32,U32)))))))) -> 8840.3902 | H32: =G37*H31 -> 7614.4618 | I32: =G37*I31 -> 9063.4449 | J32: =H32*$C$4/$K$2 -> 2284.3385 | K32: =I32*$C$4/$M$2 -> 1812.689 | L32: kr. pr. år --> | M32: =H32 -> 7614.4618 | N32: =M32+M32*N30% -> 8840.3902 | O32: =N32+N32*O30% -> 9061.3999 | P32: =O32+O32*P30% -> 9260.7507 | Q32: =P32+P32*Q30% -> 9399.662 | R32: =Q32+Q32*R30% -> 9531.2572 | S32: =R32+R32*S30% -> 9645.6323 | T32: =S32+S32*T30% -> 9751.7343 | U32: =T32+T32*U30% -> 9849.2516 | V32: =K32 -> 1812.689 | W32: Kroner op --> | X32: =500+(I32-H32)/2 -> 1224.4915 | Y32: =I32-(H32+X32) -> 224.49153 | Z32: =Y32*90% -> 202.04237 | AA32: =Z32*70% -> 141.42966 | AB32: =AA32*90% -> 127.2867 | AC32: =AB32*90% -> 114.55803 | AD32: =AC32*90% -> 103.10222 | AE32: =AD32*90% -> 92.792001 | AF32: =ROUND(H35,0) -> 16687
H33: 2 v uden børn: | I33: 2 v med børn: | J33: 2 v uden børn: | K33: 2 v med børn: | L33: % op --> | M33: 0 | N33: =X33 -> 15.7 | O33: =Y33 -> 8.4 | P33: =Z33 -> 0.8 | Q33: =AA33 -> 0.5 | R33: =AB33 -> 0.5 | S33: =AC33 -> 0.4 | T33: =AD33 -> 0.4 | U33: =AE33 -> 0.3 | V33: =K33 -> 2 v med børn: | W33: % op --> | X33: =ROUND(X35*100/M35,1) -> 15.7 | Y33: =ROUND(Y35*100/N35,1) -> 8.4 | Z33: =ROUND(Z35*100/O35,1) -> 0.8 | AA33: =ROUND(AA35*100/P35,1) -> 0.5 | AB33: =ROUND(AB35*100/Q35,1) -> 0.5 | AC33: =ROUND(AC35*100/R35,1) -> 0.4 | AD33: =ROUND(AD35*100/S35,1) -> 0.4 | AE33: =ROUND(AE35*100/T35,1) -> 0.3 | AF33: =M33&"; "&N33&"; "&O33&"; "&P33&"; "&Q33&"; "&R33&"; "&S33&"; "&T33&"; "&U33 -> 0; 15,7; 8,4; 0,8; 0,5; 0,5; 0,4; 0,4; 0,3
A34: =$A$9 -> Forbrugsenheder | G34: =A34 -> Forbrugsenheder | H34: 1.9313908 | I34: 2.4204682
A35: Flere end 2 voksne så pr. stk. | B35: =(H35/1.5)*0.5 -> 5562.4055 | C35: To | D35: 2. Boligudstyr og indretning | E35: =IF(Data!$E$4=1,0,IF(Data!$E$4=2,F35,F35+B35*Data!G4)) -> 19307.109 | F35: =IF(Data!$E$5=0,M35,IF(Data!$E$5=1,N35,IF(Data!$E$5=2,O35,IF(Data!$E$5=3,P35,IF(Data!$E$5=4,Q35,IF(Data!$E$5=5,R35,IF(Data!$E$5=6,S35,IF(Data!$E$5=7,T35,U35)))))))) -> 19307.109 | H35: =G37*H34 -> 16687.216 | I35: =G37*I34 -> 20912.845 | J35: =H35*$C$4/$K$3 -> 3337.4433 | K35: =I35*$C$4/$M$3 -> 2987.5493 | L35: kr. pr. år --> | M35: =H35 -> 16687.216 | N35: =M35+M35*N33% -> 19307.109 | O35: =N35+N35*O33% -> 20928.907 | P35: =O35+O35*P33% -> 21096.338 | Q35: =P35+P35*Q33% -> 21201.819 | R35: =Q35+Q35*R33% -> 21307.829 | S35: =R35+R35*S33% -> 21393.06 | T35: =S35+S35*T33% -> 21478.632 | U35: =T35+T35*U33% -> 21543.068 | V35: =K35 -> 2987.5493 | W35: Kroner op --> | X35: =500+(I35-H35)/2 -> 2612.8145 | Y35: =I35-(H35+X35) -> 1612.8145 | Z35: =Y35*10% -> 161.28145 | AA35: =Z35*70% -> 112.89701 | AB35: =AA35*90% -> 101.60731 | AC35: =AB35*90% -> 91.44658 | AD35: =AC35*90% -> 82.301922 | AE35: =AD35*90% -> 74.07173 | AF35: =ROUND(B35,0) -> 5562
D36: Valg 1, 2 eller flere | E36: =IF(Data!$E$4=0,0,IF(Data!$E$4=1,E32,IF(Data!$E$4=2,E35,E35))) -> 19307.109 | G36: ='DS-tal-valgte'!D29 -> 12960 | H36: =$H$14 -> Forbrugsenheder aktuelt: | I36: =$I$14 -> I alt efter forbrugsenheder:
D37: Kroner pr. forbrugsenhed | E37: =E36/$AJ$11 -> 10726.172 | G37: =G36/$M$4 -> 8640 | H37: =$AJ$11 -> 1.8 | I37: =H37*G37 -> 15552
D38: Test: Endeligt forbrug pr. måned: | E38: =E36/12 -> 1608.9258
H40: Tal der styrer: | I40: Juster efter disse: | J40: Forbrugsenheder pr. barn: | L40: Antal børn --> | M40: 0 | N40: =M40+1 -> 1 | O40: =N40+1 -> 2 | P40: =O40+1 -> 3 | Q40: =P40+1 -> 4 | R40: =Q40+1 -> 5 | S40: =R40+1 -> 6 | T40: =S40+1 -> 7 | U40: =T40+1 -> 8 | V40: Forbrugsenhed: | W40: Vækst år til år --> | X40: 0-1 | Y40: 1-2 | Z40: 2-3 | AA40: 3-4 | AB40: 4-5 | AC40: 5-6 | AD40: 6-7 | AE40: 7-8 | AF40: =ROUND(H43,0) -> 2279
A41: Medicin og lægeudgifter | C41: =$C$8 -> 2018 ok | G41: Alle | H41: Enlig uden børn: | I41: Enlig med børn: | J41: Enlig uden børn: | K41: Enlig med børn: | L41: % op --> | M41: 0 | N41: =X41 -> 3.2 | O41: =Y41 -> 6.5 | P41: =Z41 -> 3.7 | Q41: =AA41 -> 0 | R41: =AB41 -> 0 | S41: =AC41 -> 0 | T41: =AD41 -> 0 | U41: =AE41 -> 0 | V41: =K41 -> Enlig med børn: | W41: % op --> | X41: =ROUND(X43*100/M43,1) -> 3.2 | Y41: =ROUND(Y43*100/N43,1) -> 6.5 | Z41: =ROUND(Z43*100/O43,1) -> 3.7 | AA41: =ROUND(AA43*100/P43,1) -> 0 | AB41: =ROUND(AB43*100/Q43,1) -> 0 | AC41: =ROUND(AC43*100/R43,1) -> 0 | AD41: =ROUND(AD43*100/S43,1) -> 0 | AE41: =ROUND(AE43*100/T43,1) -> 0 | AF41: =M41&"; "&N41&"; "&O41&"; "&P41&"; "&Q41&"; "&R41&"; "&S41&"; "&T41&"; "&U41 -> 0; 3,2; 6,5; 3,7; 0; 0; 0; 0; 0
A42: =$A$9 -> Forbrugsenheder | G42: =A42 -> Forbrugsenheder | H42: 0.65303936 | I42: 0.71797468
C43: Én | D43: 1. Medicin og lægeudgifter | E43: =IF(Data!$E$4=1,F43,IF(Data!$E$4=2,0,0)) -> 0 | F43: =IF(Data!$E$5=0,M43,IF(Data!$E$5=1,N43,IF(Data!$E$5=2,O43,IF(Data!$E$5=3,P43,IF(Data!$E$5=4,Q43,IF(Data!$E$5=5,R43,IF(Data!$E$5=6,S43,IF(Data!$E$5=7,T43,U43)))))))) -> 2351.5895 | H43: =G48*H42 -> 2278.672 | I43: =G48*I42 -> 2505.253 | J43: =H43*$C$4/$K$2 -> 683.6016 | K43: =I43*$C$4/$M$2 -> 501.0506 | L43: kr. pr. år --> | M43: =H43 -> 2278.672 | N43: =M43+M43*N41% -> 2351.5895 | O43: =N43+N43*O41% -> 2504.4428 | P43: =O43+O43*P41% -> 2597.1072 | Q43: =P43+P43*Q41% -> 2597.1072 | R43: =Q43+Q43*R41% -> 2597.1072 | S43: =R43+R43*S41% -> 2597.1072 | T43: =S43+S43*T41% -> 2597.1072 | U43: =T43+T43*U41% -> 2597.1072 | V43: =K43 -> 501.0506 | W43: Kroner op --> | X43: =-40+(I43-H43)/2 -> 73.290489 | Y43: =I43-(H43+X43) -> 153.29049 | Z43: =Y43*60% -> 91.974293 | AA43: =Z43*0% -> 0 | AB43: =AA43*90% -> 0 | AC43: =AB43*90% -> 0 | AD43: =AC43*90% -> 0 | AE43: =AD43*90% -> 0 | AF43: =ROUND(H46,0) -> 5431
...

Sheet Skatteprocenter
E1: Kommune | F1: Kirke | G1: I alt | H1: Grundskyld | M1: Kommune | N1: Kirke | O1: I alt | P1: Grundskyld
E2: 2020 | F2: 2020 | G2: 2020 | H2: 2020 | K2: id-nr. | M2: 2020 | N2: 2020 | O2: 2020 | P2: 2020
B3: 1 | C3: 165 | D3: Albertslund | E3: 25.6 | F3: 0.8 | G3: =E3+F3 -> 26.4 | H3: 33.94 | K3: 101 | L3: København | M3: 23.8 | N3: 0.8 | O3: =M3+N3 -> 24.6 | P3: 34
B4: 2 | C4: 201 | D4: Allerød | E4: 24.3 | F4: 0.58 | G4: =E4+F4 -> 24.88 | H4: 23.8 | K4: 147 | L4: Frederiksberg | M4: 22.8 | N4: 0.5 | O4: =M4+N4 -> 23.3 | P4: 24.75
B5: 3 | C5: 420 | D5: Assens | E5: 26.1 | F5: 0.95 | G5: =E5+F5 -> 27.05 | H5: 22.12 | K5: 151 | L5: Ballerup | M5: 25.5 | N5: 0.72 | O5: =M5+N5 -> 26.22 | P5: 28.89
B6: 4 | C6: 151 | D6: Ballerup | E6: 25.5 | F6: 0.72 | G6: =E6+F6 -> 26.22 | H6: 28.89 | K6: 153 | L6: Brøndby | M6: 24.3 | N6: 0.8 | O6: =M6+N6 -> 25.1 | P6: 20.5
B7: 5 | C7: 530 | D7: Billund | E7: 24 | F7: 0.89 | G7: =E7+F7 -> 24.89 | H7: 18.48 | K7: 155 | L7: Dragør | M7: 24.8 | N7: 0.61 | O7: =M7+N7 -> 25.41 | P7: 24.47
B8: 6 | C8: 400 | D8: Bornholm | E8: 26.2 | F8: 0.93 | G8: =E8+F8 -> 27.13 | H8: 34 | K8: 157 | L8: Gentofte | M8: 22.8 | N8: 0.39 | O8: =M8+N8 -> 23.19 | P8: 16
B9: 7 | C9: 153 | D9: Brøndby | E9: 24.3 | F9: 0.8 | G9: =E9+F9 -> 25.1 | H9: 20.5 | K9: 159 | L9: Gladsaxe | M9: 23.6 | N9: 0.75 | O9: =M9+N9 -> 24.35 | P9: 23
B10: 8 | C10: 810 | D10: Brønderslev | E10: 26.9 | F10: 1.09 | G10: =E10+F10 -> 27.99 | H10: 31.23 | K10: 161 | L10: Glostrup | M10: 23.6 | N10: 0.8 | O10: =M10+N10 -> 24.4 | P10: 25
B11: 9 | C11: 155 | D11: Dragør | E11: 24.8 | F11: 0.61 | G11: =E11+F11 -> 25.41 | H11: 24.47 | K11: 163 | L11: Herlev | M11: 23.7 | N11: 0.75 | O11: =M11+N11 -> 24.45 | P11: 24.3
B12: 10 | C12: 240 | D12: Egedal | E12: 25.7 | F12: 0.76 | G12: =E12+F12 -> 26.46 | H12: 23.98 | K12: 165 | L12: Albertslund | M12: 25.6 | N12: 0.8 | O12: =M12+N12 -> 26.4 | P12: 33.94
B13: 11 | C13: 561 | D13: Esbjerg | E13: 25.8 | F13: 0.81 | G13: =E13+F13 -> 26.61 | H13: 25.29 | K13: 167 | L13: Hvidovre | M13: 25.5 | N13: 0.72 | O13: =M13+N13 -> 26.22 | P13: 29.7
B14: 12 | C14: 563 | D14: Fanø | E14: 24.9 | F14: 1.14 | G14: =E14+F14 -> 26.04 | H14: 34 | K14: 169 | L14: Høje-Taastrup | M14: 24.6 | N14: 0.8 | O14: =M14+N14 -> 25.4 | P14: 24.4
... B100: 98 | C100: 751 | D100: Aarhus | E100: 24.4 | F100: 0.74 | G100: =E100+F100 -> 25.14 | H100: 24.58 | K100: 860 | L100: Hjørring | M100: 26.1 | N100: 1.19 | O100: =M100+N100 -> 27.29 | P100: 34
D101: Gns. for kommuner | E101: 24.954 | F101: 0.674 | G101: 25.628 | H101: 26.196888 | L101: Gns. for kommuner | M101: 24.954 | N101: 0.674 | O101: 25.628 | P101: 26.196888
D103: =VLOOKUP(Dialog!$M$3,B4:H101,3) -> #N/A | E103: =VLOOKUP(Dialog!M3,B3:H101,4) -> 25.6 | F103: =VLOOKUP(Dialog!M3,B3:H101,5) -> 0.8 | G103: =VLOOKUP(Dialog!M3,B3:H101,6) -> 26.4 | L103: =VLOOKUP(Dialog!$N$3,K3:P101,2) -> Albertslund | M103: =VLOOKUP(Dialog!$N$3,K3:P101,3) -> 25.6 | N103: =VLOOKUP(Dialog!$N$3,K3:P101,4) -> 0.8 | O103: =VLOOKUP(Dialog!$N$3,K3:P101,5) -> 26.4
D105: Skatteprocent | E105: =G103+12.14 -> 38.54 | F105: inkl. bundskat | L105: Skatteprocent | M105: =O103+12.14 -> 38.54 | N105: inkl. bundskat
E106: Pr. måned | F106: Hele året | G106: Hele året | H106: Hele året | I106: Før skat | M106: Pr. måned | N106: Hele året | O106: Hele året | P106: Hele året | Q106: Før skat
E107: efter skat | F107: efter skat | G107: før skat | H107: før AM-bidrag | I107: pr. måned | M107: efter skat | N107: efter skat | O107: før skat | P107: før AM-bidrag | Q107: pr. måned
D108: Person 1 - indtægt før skat | E108: =Input!D13 -> 10000 | F108: =E108*12 -> 120000 | G108: =F108/(1-($E$105/100)) -> 195248.94 | H108: =G108/(1-0.08) -> 212227.11 | I108: =H108/12 -> 17685.593 | L108: Person 1 - indtægt før skat | M108: =Input!D13 -> 10000 | N108: =M108*12 -> 120000 | O108: =N108/(1-($M$105/100)) -> 195248.94 | P108: =O108/(1-0.08) -> 212227.11 | Q108: =P108/12 -> 17685.593
D109: Person 2 - indtægt før skat | E109: =Input!D14 -> 100000 | F109: =E109*12 -> 1200000 | G109: =F109/(1-($E$105/100)) -> 1952489.4 | H109: =G109/(1-0.08) -> 2122271.1 | I109: =H109/12 -> 176855.93 | L109: Person 2 - indtægt før skat | M109: =Input!D14 -> 100000 | N109: =M109*12 -> 1200000 | O109: =N109/(1-($M$105/100)) -> 1952489.4 | P109: =O109/(1-0.08) -> 2122271.1 | Q109: =P109/12 -> 176855.93
D110: Person 3 - indtægt før skat | E110: =Input!D15 -> 0 | F110: =E110*12 -> 0 | G110: =F110/(1-($E$105/100)) -> 0 | H110: =G110/(1-0.08) -> 0 | I110: =H110/12 -> 0 | L110: Person 3 - indtægt før skat | M110: =Input!D15 -> 0 | N110: =M110*12 -> 0 | O110: =N110/(1-($M$105/100)) -> 0 | P110: =O110/(1-0.08) -> 0 | Q110: =P110/12 -> 0
D111: Person 4 - indtægt før skat | E111: =Input!D16 -> 0 | F111: =E111*12 -> 0 | G111: =F111/(1-($E$105/100)) -> 0 | H111: =G111/(1-0.08) -> 0 | I111: =H111/12 -> 0 | L111: Person 4 - indtægt før skat | M111: =Input!D16 -> 0 | N111: =M111*12 -> 0 | O111: =N111/(1-($M$105/100)) -> 0 | P111: =O111/(1-0.08) -> 0 | Q111: =P111/12 -> 0
D112: Person 5 - indtægt før skat | E112: =Input!D17 -> 0 | F112: =E112*12 -> 0 | G112: =F112/(1-($E$105/100)) -> 0 | H112: =G112/(1-0.08) -> 0 | I112: =H112/12 -> 0 | L112: Person 5 - indtægt før skat | M112: =Input!D17 -> 0 | N112: =M112*12 -> 0 | O112: =N112/(1-($M$105/100)) -> 0 | P112: =O112/(1-0.08) -> 0 | Q112: =P112/12 -> 0
D113: Person 6 - indtægt før skat | E113: =Input!D18 -> 0 | F113: =E113*12 -> 0 | G113: =F113/(1-($E$105/100)) -> 0 | H113: =G113/(1-0.08) -> 0 | I113: =H113/12 -> 0 | L113: Person 6 - indtægt før skat | M113: =Input!D18 -> 0 | N113: =M113*12 -> 0 | O113: =N113/(1-($M$105/100)) -> 0 | P113: =O113/(1-0.08) -> 0 | Q113: =P113/12 -> 0

Sheet Data
D1: Nøgletal for hele landet:
D3: Nøgletal fra dialog:
D4: Antal forsørgere: | E4: =Input!D8 -> 2 | F4: Flere end to --> | G4: =E4-2 -> 0
D5: Antal børn i alt: | E5: =Input!D29 -> 1 | F5: =Input!B25 -> 0-2 år | G5: =Input!D25 -> 1 | H5: =Input!B26 -> 3-6 år | I5: =Input!D26 -> 0 | J5: =Input!B27 -> 7-14 år | K5: =Input!D27 -> 0 | L5: =Input!B28 -> 15-17 år | M5: =Input!D28 -> 0
D6: Bolig:
D7: Feriebolig:
D8: Antal biler | E8: =SUM(Input!D40:D43) -> 0
D10: Simple valg
E11: Valgkolonne
E12: Hele året
D13: Diverse udgifter | E13: 2020 | F13: Måned/kvartal/halvårligt/årligt | G13: Evt. moms | H13: Antal | I13: Antal andre enheder
B14: Opdateret 2020 | D14: Sygesikringen Danmark, Gruppe 5 | E14: =(F14+F14*G14/100)*H14 -> 1520 | F14: 380 | G14: 0 | H14: 4 | J14: https://www.sygeforsikring.dk/grupper#tabs-5556
B15: =B14 -> Opdateret 2020 | D15: Falck: vejhjælp start | E15: =(F15+F15*G15/100)*H15 -> 708 | F15: 59 | H15: 12 | J15: https://www.falck.dk/vejhjaelp/produkter/autohjaelp/#productpage-configurator
B16: =B15 -> Opdateret 2020 | D16: FDM (Medlemskab uden autohjælp) | E16: =(F16+F16*G16/100)*H16 -> 660 | F16: 660 | H16: 1 | J16: https://fdm.dk/bliv-medlem?gclid=EAIaIQobChMI7Jzu9vTh2AIV1xbTCh2KWQ9TEAAYAiAAEgIuIvD_BwE
B17: =B16 -> Opdateret 2020 | D17: TV-licens | E17: =F17*H17 -> 1353 | F17: 1353 | H17: 1 | J17: http://www.dr.dk/OmDR/Licens/Fakta%20om%20Licens/Priser_1.htm
B18: =B17 -> Opdateret 2020 | D18: A-kasse | E18: =I99 -> 5914.5 | J18: Se længere nede
B19: =B18 -> Opdateret 2020 | D19: Fagforening | E19: =E99 -> 3625.25 | J19: Se længere nede
B22: Opdateret | C22: 2020
D23: Bil - Grøn ejerafgift - benzindrevne | E23: Af personbiler, der er indregistreret første gang før 1. juli 1997 betales vægt­afgift,
D24: A. Benzindrevne personbiler mv. | E24: Afgift pr. personbil: | F24: http://www.skm.dk/skatteomraadet/talogstatistik/satser_og_beloeb/183.html | I24: <-- Grøn ejerafgift benzinbiler --> | M24: http://www.grønafgift.dk/groen-ejerafgift-personbiler/
E25: halvt år | F25: Helt år | G25: Pr. måned | I25: Bil | J25: Km/liter | K25: Pr. år | L25: Pr. måned
C26: 1 | D26: Vælg:
C27: =C26+1 -> 2 | D27: > 20 | E27: 330 | F27: =E27*2 -> 660 | G27: =F27/12 -> 55 | H27: Lille | J27: =D27 -> > 20 | K27: =F27 -> 660 | L27: =K27/12 -> 55 | M27: Lille
C28: =C27+1 -> 3 | D28: 20 - 18,2 | E28: 640 | F28: =E28*2 -> 1280 | G28: =F28/12 -> 106.66667 | J28: =D32 -> 14,3 - 13,3 | K28: =F32 -> 3740 | L28: =K28/12 -> 311.66667 | M28: Mellem
C29: =C28+1 -> 4 | D29: 18,2 - 16,7 | E29: 940 | F29: =E29*2 -> 1880 | G29: =F29/12 -> 156.66667 | J29: =D37 -> 10,5 - 10,0 | K29: =F37 -> 6820 | L29: =K29/12 -> 568.33333 | M29: Stor
C30: =C29+1 -> 5 | D30: 16,7 - 15,4 | E30: 1260 | F30: =E30*2 -> 2520 | G30: =F30/12 -> 210 | J30: =D43 -> 6,7 - 6,3 | K30: =F43 -> 14220 | L30: =K30/12 -> 1185 | M30: Meget stor
C31: =C30+1 -> 6 | D31: 15,4 - 14,3 | E31: 1570 | F31: =E31*2 -> 3140 | G31: =F31/12 -> 261.66667 | H31: Mellem
C32: =C31+1 -> 7 | D32: 14,3 - 13,3 | E32: 1870 | F32: =E32*2 -> 3740 | G32: =F32/12 -> 311.66667 | I32: Beregningsmodel for grøn ejerafgift:
C33: =C32+1 -> 8 | D33: 13,3 - 12,5 | E33: 2180 | F33: =E33*2 -> 4360 | G33: =F33/12 -> 363.33333 | I33: Benzin-biler: | J33: Kroner pr. år | K33: Valgt antal
C34: =C33+1 -> 9 | D34: 12,5 - 11,8 | E34: 2480 | F34: =E34*2 -> 4960 | G34: =F34/12 -> 413.33333 | I34: Lille | J34: =K27 -> 660 | K34: =Dialog!F19 -> 0
C35: =C34+1 -> 10 | D35: 11,8 - 11,1 | E35: 2790 | F35: =E35*2 -> 5580 | G35: =F35/12 -> 465 | I35: Mellem | J35: 3140 | K35: =Dialog!F20 -> 0
C36: =C35+1 -> 11 | D36: 11,1 - 10,5 | E36: 3100 | F36: =E36*2 -> 6200 | G36: =F36/12 -> 516.66667 | I36: Stor | J36: =K29 -> 6820 | K36: =Dialog!F21 -> 0
C37: =C36+1 -> 12 | D37: 10,5 - 10,0 | E37: 3410 | F37: =E37*2 -> 6820 | G37: =F37/12 -> 568.33333 | H37: Stor | I37: Meget stor | J37: =K30 -> 14220 | K37: =Dialog!F22 -> 0
C38: =C37+1 -> 13 | D38: 10,0 - 9,1 | E38: 4010 | F38: =E38*2 -> 8020 | G38: =F38/12 -> 668.33333
C39: =C38+1 -> 14 | D39: 9,1 - 8,3 | E39: 4650 | F39: =E39*2 -> 9300 | G39: =F39/12 -> 775 | I39: Grøn ejerafgift | J39: =J34*K34+J35*K35+J36*K36+J37*K37 -> 0
C40: =C39+1 -> 15 | D40: 8,3 - 7,7 | E40: 5260 | F40: =E40*2 -> 10520 | G40: =F40/12 -> 876.66667
C41: =C40+1 -> 16 | D41: 7,7 - 7,1 | E41: 5870 | F41: =E41*2 -> 11740 | G41: =F41/12 -> 978.33333 | I41: Antal biler i alt | K41: =SUM(K34:K37) -> 0
C42: =C41+1 -> 17 | D42: 7,1 - 6,7 | E42: 6480 | F42: =E42*2 -> 12960 | G42: =F42/12 -> 1080
C43: =C42+1 -> 18 | D43: 6,7 - 6,3 | E43: 7110 | F43: =E43*2 -> 14220 | G43: =F43/12 -> 1185 | H43: Meget stor | I43: Forsikring for bil 1, bil og bil 3 - Dialog og Kommunedata
C44: =C43+1 -> 19 | D44: 6,3 - 5,9 | E44: 7720 | F44: =E44*2 -> 15440 | G44: =F44/12 -> 1286.6667 | I44: Bil 1: | J44: =Dialog!H27 -> 0
...

Sheet DS-tal-valgte
A1: Valgte | D1: Gennemsnit - D | E1: Enlige uden børn - F | F1: Enlig med børn - H | G1: 2 voksne uden børn - J | H1: 2 voksne med børn - L
A2: familie | C2: ='DS-tal-alle'!C16 -> FORBRUG I ALT | D2: ='DS-tal-alle'!D16 -> 300480.3 | E2: ='DS-tal-alle'!F16 -> 183861.1 | F2: ='DS-tal-alle'!G16 -> 246764.4 | G2: ='DS-tal-alle'!H16 -> 330719.8 | H2: ='DS-tal-alle'!I16 -> 417210.8 | I2: Eget hus | J2: Lejet hus | K2: Ejerlejlighed | L2: Lejet lejlighed | M2: Andelsbolig
A3: =Budget!$L$16 -> 4 | B3: Dagligvarer og husholdning | D3: =D13 -> 54352 | E3: =E13 -> 27546.9 | F3: =F13 -> 46426.6 | G3: =G13 -> 52206.7 | H3: =H13 -> 88783.9
C4: ='DS-tal-alle'!C17 -> 01 FØDEVARER OG IKKE-ALKOHOLISKE DRIKKEVARER | D4: ='DS-tal-alle'!D17 -> 38606 | E4: ='DS-tal-alle'!F17 -> 20252.9 | F4: ='DS-tal-alle'!G17 -> 34015.5 | G4: ='DS-tal-alle'!H17 -> 39231 | H4: ='DS-tal-alle'!I17 -> 55719.1
C5: ='DS-tal-alle'!C79 -> 02 ALKOHOLISKE DRIKKEVARER OG TOBAK | D5: ='DS-tal-alle'!D79 -> 6705 | E5: ='DS-tal-alle'!F79 -> 4723.2 | F5: ='DS-tal-alle'!G79 -> 5018.4 | G5: ='DS-tal-alle'!H79 -> 8032.3 | H5: ='DS-tal-alle'!I79 -> 7011.1
C6: ='DS-tal-alle'!C165 -> 05.6.1.1 Rengøringsartikler | D6: ='DS-tal-alle'!D165 -> 779 | E6: ='DS-tal-alle'!F165 -> 382.3 | F6: ='DS-tal-alle'!G165 -> 609.4 | G6: ='DS-tal-alle'!H165 -> 871.1 | H6: ='DS-tal-alle'!I165 -> 1220.7
C7: ='DS-tal-alle'!C166 -> 05.6.1.2 Andre ikke-varige små husholdningsartikler | D7: ='DS-tal-alle'!D166 -> 1089 | E7: ='DS-tal-alle'!F166 -> 607.4 | F7: ='DS-tal-alle'!G166 -> 1167.3 | G7: ='DS-tal-alle'!H166 -> 1406.7 | H7: ='DS-tal-alle'!I166 -> 1703.6
C8: ='DS-tal-alle'!C169 -> 05.6.2.9 Rengøring og vinduespudsning | D8: ='DS-tal-alle'!D169 -> 805 | E8: ='DS-tal-alle'!F169 -> 142.6 | F8: ='DS-tal-alle'!G169 -> 398.2 | G8: ='DS-tal-alle'!H169 -> 401.4 | H8: ='DS-tal-alle'!I169 -> 1178.6
C9: ='DS-tal-alle'!C282 -> 12.1.1.1 Frisør til mænd og børn | D9: ='DS-tal-alle'!D282 -> 506 | E9: ='DS-tal-alle'!F282 -> 377.9 | F9: ='DS-tal-alle'!G282 -> 266.5 | G9: ='DS-tal-alle'!H282 -> 543.6 | H9: ='DS-tal-alle'!I282 -> 689.2
C10: ='DS-tal-alle'!C283 -> 12.1.1.2 Frisør til kvinder | D10: ='DS-tal-alle'!D283 -> 1516 | E10: ='DS-tal-alle'!F283 -> 940.1 | F10: ='DS-tal-alle'!G283 -> 349.3 | G10: ='DS-tal-alle'!H283 -> 1300.1 | H10: ='DS-tal-alle'!I283 -> 1568.1
C11: ='DS-tal-alle'!C284 -> 12.1.1.3 Personlige plejebehandlinger | D11: ='DS-tal-alle'!D284 -> 806 | E11: ='DS-tal-alle'!F284 -> 120.5 | F11: ='DS-tal-alle'!G284 -> 809.7 | G11: ='DS-tal-alle'!H284 -> 420.5 | H11: ='DS-tal-alle'!I284 -> 545.9
C12: ='DS-tal-alle'!C297 -> 12.4.0.1 Børnepasning | D12: ='DS-tal-alle'!D297 -> 3540 | E12: ='DS-tal-alle'!F297 -> 0 | F12: ='DS-tal-alle'!G297 -> 3792.3 | G12: ='DS-tal-alle'!H297 -> 0 | H12: ='DS-tal-alle'!I297 -> 19147.6
C13: I alt | D13: =SUM(D4:D12) -> 54352 | E13: =SUM(E4:E12) -> 27546.9 | F13: =SUM(F4:F12) -> 46426.6 | G13: =SUM(G4:G12) -> 52206.7 | H13: =SUM(H4:H12) -> 88783.9
B15: Tøj og sko | D15: =D22 -> 14040 | E15: =E22 -> 7442 | F15: =F22 -> 10405 | G15: =G22 -> 18031.9 | H15: =H22 -> 20342
C16: ='DS-tal-alle'!C94 -> 03 BEKLÆDNING OG FODTØJ | D16: ='DS-tal-alle'!D94 -> 12115 | E16: ='DS-tal-alle'!F94 -> 6691.3 | F16: ='DS-tal-alle'!G94 -> 9371.5 | G16: ='DS-tal-alle'!H94 -> 15252 | H16: ='DS-tal-alle'!I94 -> 18301.2
C17: ='DS-tal-alle'!C290 -> 12.3.1.1 Smykker | D17: ='DS-tal-alle'!D290 -> 497 | E17: ='DS-tal-alle'!F290 -> 334.7 | F17: ='DS-tal-alle'!G290 -> 157.3 | G17: ='DS-tal-alle'!H290 -> 355.6 | H17: ='DS-tal-alle'!I290 -> 842.5
C18: ='DS-tal-alle'!C291 -> 12.3.1.2 Ure | D18: ='DS-tal-alle'!D291 -> 666 | E18: ='DS-tal-alle'!F291 -> 134.3 | F18: ='DS-tal-alle'!G291 -> 125.9 | G18: ='DS-tal-alle'!H291 -> 766.2 | H18: ='DS-tal-alle'!I291 -> 342.6
C19: ='DS-tal-alle'!C292 -> 12.3.1.3 Reparation af smykker og ure | D19: ='DS-tal-alle'!D292 -> 3 | E19: ='DS-tal-alle'!F292 -> 125.1 | F19: ='DS-tal-alle'!G292 -> 0 | G19: ='DS-tal-alle'!H292 -> 52.2 | H19: ='DS-tal-alle'!I292 -> 8.4
C20: ='DS-tal-alle'!C293 -> 12.3.2.1 Tasker, rygsække o.l. | D20: ='DS-tal-alle'!D293 -> 582 | E20: ='DS-tal-alle'!F293 -> 156.2 | F20: ='DS-tal-alle'!G293 -> 481.4 | G20: ='DS-tal-alle'!H293 -> 447.9 | H20: ='DS-tal-alle'!I293 -> 726.3
C21: ='DS-tal-alle'!C294 -> 12.3.2.2 Artikler til babyer | D21: ='DS-tal-alle'!D294 -> 177 | E21: ='DS-tal-alle'!F294 -> 0.4 | F21: ='DS-tal-alle'!G294 -> 268.9 | G21: ='DS-tal-alle'!H294 -> 1158 | H21: ='DS-tal-alle'!I294 -> 121
C22: I alt | D22: =SUM(D16:D21) -> 14040 | E22: =SUM(E16:E21) -> 7442 | F22: =SUM(F16:F21) -> 10405 | G22: =SUM(G16:G21) -> 18031.9 | H22: =SUM(H16:H21) -> 20342
B24: Boligudstyr og indretning | D24: =D29 -> 12960 | E24: =E29 -> 7770.1 | F24: =F29 -> 9248.7 | G24: =G29 -> 17028.3 | H24: =H29 -> 21340.3
C25: ='DS-tal-alle'!C131 -> 05 MØBLER, HUSHOLDNINGSUDSTYR OG HUSHOLDNINGSTJENESTER | D25: ='DS-tal-alle'!D131 -> 15633 | E25: ='DS-tal-alle'!F131 -> 8902.4 | F25: ='DS-tal-alle'!G131 -> 11423.6 | G25: ='DS-tal-alle'!H131 -> 19707.5 | H25: ='DS-tal-alle'!I131 -> 25443.2
C26: ='DS-tal-alle'!C165 -> 05.6.1.1 Rengøringsartikler | D26: =-'DS-tal-alle'!D165 -> -779 | E26: =-'DS-tal-alle'!F165 -> -382.3 | F26: =-'DS-tal-alle'!G165 -> -609.4 | G26: =-'DS-tal-alle'!H165 -> -871.1 | H26: =-'DS-tal-alle'!I165 -> -1220.7
C27: ='DS-tal-alle'!C166 -> 05.6.1.2 Andre ikke-varige små husholdningsartikler | D27: =-'DS-tal-alle'!D166 -> -1089 | E27: =-'DS-tal-alle'!F166 -> -607.4 | F27: =-'DS-tal-alle'!G166 -> -1167.3 | G27: =-'DS-tal-alle'!H166 -> -1406.7 | H27: =-'DS-tal-alle'!I166 -> -1703.6
C28: ='DS-tal-alle'!C169 -> 05.6.2.9 Rengøring og vinduespudsning | D28: =-'DS-tal-alle'!D169 -> -805 | E28: =-'DS-tal-alle'!F169 -> -142.6 | F28: =-'DS-tal-alle'!G169 -> -398.2 | G28: =-'DS-tal-alle'!H169 -> -401.4 | H28: =-'DS-tal-alle'!I169 -> -1178.6
C29: I alt | D29: =SUM(D25:D28) -> 12960 | E29: =SUM(E25:E28) -> 7770.1 | F29: =SUM(F25:F28) -> 9248.7 | G29: =SUM(G25:G28) -> 17028.3 | H29: =SUM(H25:H28) -> 21340.3
B31: Medicin og øvrige lægeudgifter | D31: =D34 -> 5234 | E31: =E34 -> 2214.5 | F31: =F34 -> 2434.7 | G31: =G34 -> 5278.1 | H31: =H34 -> 4424.1
C32: ='DS-tal-alle'!C170 -> 06 SUNDHED | D32: ='DS-tal-alle'!D170 -> 8073 | E32: ='DS-tal-alle'!F170 -> 3543.7 | F32: ='DS-tal-alle'!G170 -> 4333.4 | G32: ='DS-tal-alle'!H170 -> 8316.3 | H32: ='DS-tal-alle'!I170 -> 6607
C33: ='DS-tal-alle'!C180 -> 06.2.2.0 Tandlæge | D33: =-'DS-tal-alle'!D180 -> -2839 | E33: =-'DS-tal-alle'!F180 -> -1329.2 | F33: =-'DS-tal-alle'!G180 -> -1898.7 | G33: =-'DS-tal-alle'!H180 -> -3038.2 | H33: =-'DS-tal-alle'!I180 -> -2182.9
C34: I alt | D34: =SUM(D32:D33) -> 5234 | E34: =SUM(E32:E33) -> 2214.5 | F34: =SUM(F32:F33) -> 2434.7 | G34: =SUM(G32:G33) -> 5278.1 | H34: =SUM(H32:H33) -> 4424.1
B36: Tandlæge | D36: =D38 -> 2839 | E36: =E38 -> 1329.2 | F36: =F38 -> 1898.7 | G36: =G38 -> 3038.2 | H36: =H38 -> 2182.9
C37: ='DS-tal-alle'!C180 -> 06.2.2.0 Tandlæge | D37: ='DS-tal-alle'!D180 -> 2839 | E37: ='DS-tal-alle'!F180 -> 1329.2 | F37: ='DS-tal-alle'!G180 -> 1898.7 | G37: ='DS-tal-alle'!H180 -> 3038.2 | H37: ='DS-tal-alle'!I180 -> 2182.9
C38: I alt | D38: =SUM(D37) -> 2839 | E38: =SUM(E37) -> 1329.2 | F38: =SUM(F37) -> 1898.7 | G38: =SUM(G37) -> 3038.2 | H38: =SUM(H37) -> 2182.9
B40: Ferie, fritid og underholdning | D40: =D54 -> 44710 | E40: =E54 -> 24416.1 | F40: =F54 -> 30892.5 | G40: =G54 -> 49283.5 | H40: =H54 -> 49797.5
C41: ='DS-tal-alle'!C219 -> 09 FRITID OG KULTUR | D41: ='DS-tal-alle'!D219 -> 31279 | E41: ='DS-tal-alle'!F219 -> 16387.1 | F41: ='DS-tal-alle'!G219 -> 21078.3 | G41: ='DS-tal-alle'!H219 -> 34003.3 | H41: ='DS-tal-alle'!I219 -> 35426.7
C42: ='DS-tal-alle'!C253 -> 09.4.2.3 Tv og radiolicens, abonnementer | D42: ='DS-tal-alle'!D253 -> 5269 | E42: ='DS-tal-alle'!F253 -> 4251.5 | F42: ='DS-tal-alle'!G253 -> 4852.8 | G42: ='DS-tal-alle'!H253 -> 5999.4 | H42: ='DS-tal-alle'!I253 -> 6541.6
C43: ='DS-tal-alle'!C258 -> 09.5.1.1 Skønlitteratur | D43: =-'DS-tal-alle'!D258 -> -351 | E43: =-'DS-tal-alle'!F258 -> -233.3 | F43: =-'DS-tal-alle'!G258 -> -120.9 | G43: =-'DS-tal-alle'!H258 -> -617.1 | H43: =-'DS-tal-alle'!I258 -> -637.2
C44: ='DS-tal-alle'!C259 -> 09.5.1.2 Fag-, studiebøger | D44: =-'DS-tal-alle'!D259 -> -238 | E44: =-'DS-tal-alle'!F259 -> -278 | F44: =-'DS-tal-alle'!G259 -> -402.1 | G44: =-'DS-tal-alle'!H259 -> -305.3 | H44: =-'DS-tal-alle'!I259 -> -355.3
C45: ='DS-tal-alle'!C260 -> 09.5.1.3 Andre fagbøger | D45: =-'DS-tal-alle'!D260 -> -154 | E45: =-'DS-tal-alle'!F260 -> -107.6 | F45: =-'DS-tal-alle'!G260 -> -46.5 | G45: =-'DS-tal-alle'!H260 -> -142.7 | H45: =-'DS-tal-alle'!I260 -> -99.7
...

Sheet Modeller
B1: Modeller
D2: Børnecheck
B3: 2020 | C3: ok | E3: I alt | F3: 0-2 år | G3: 3-6 år | H3: 7-14 år | I3: 15-17 år | J3: Se Skat.dk om takster: | K3: http://www.skm.dk/skattetal/satser/satser-og-beloebsgraenser/boerne-og-ungeydelsesloven/ | N3: Vælg år i kolonne B | O3: Tal ændres til højre --> | P3: =IF($B$3=2018,Y3,"") | Q3: 2014 | R3: 2014 | S3: 2015 | T3: 2015 | U3: 2016 | V3: 2016 | W3: 2017 | X3: 2017 | Y3: 2018 | Z3: 2018 | AA3: 2020 | AB3: 2020
D4: Pr. kvartal / måned | F4: 4596 | G4: 3639 | H4: 2862 | I4: 954 | K4: https://www.borger.dk/familie-og-boern/Familieydelser-oversigt/Boerne-ungeydelse | Q4: Pr. år | R4: Kvartal/måned | S4: Pr. år | T4: Kvartal/måned | U4: Pr. år | V4: Kvartal/måned | W4: Pr. år | X4: Kvartal/måned | Y4: Pr. år | Z4: Kvartal/måned | AA4: Pr. år | AB4: Kvartal/måned
D5: Pr. år | F5: =F4*4 -> 18384 | G5: =G4*4 -> 14556 | H5: =H4*4 -> 11448 | I5: =I4*12 -> 11448 | P5: 0-2 år | Q5: 17616 | R5: 4404 | S5: 17772 | T5: 4443 | U5: =V5*4 -> 17880 | V5: 4470 | W5: =X5*4 -> 17964 | X5: 4491 | Y5: =Z5*4 -> 18024 | Z5: 4506 | AA5: =AB5*4 -> 18384 | AB5: 4596
D6: Valg efter antal børn - før reduktion | E6: =SUM(F6:I6) -> 18384 | F6: =Data!G5*F5 -> 18384 | G6: =Data!I5*G5 -> 0 | H6: =Data!K5*H5 -> 0 | I6: =I5*Data!M5 -> 0 | P6: 3-6 år | Q6: 13944 | R6: 3486 | S6: 14076 | T6: 3519 | U6: =V6*4 -> 14148 | V6: 3537 | W6: =X6*4 -> 14220 | X6: 3555 | Y6: =Z6*4 -> 14268 | Z6: 3567 | AA6: =AB6*4 -> 14556 | AB6: 3639
D7: Max. på den samlede ydelse | E7: =E6 -> 18384 | J7: Dette maks er ophævet fra 2012. | P7: 7-14 år | Q7: 10980 | R7: 2745 | S7: 11076 | T7: 2769 | U7: =V7*4 -> 11136 | V7: 2784 | W7: =X7*4 -> 11184 | X7: 2796 | Y7: =Z7*4 -> 11232 | Z7: 2808 | AA7: =AB7*4 -> 11448 | AB7: 2862
D8: Ydelse over max. | E8: =E6-E7 -> 0 | J8: Dette maks er ophævet fra 2012. | P8: 15-17 år | Q8: 10980 | R8: 915 | S8: 11076 | T8: 923 | U8: =V8*12 -> 11136 | V8: 928 | W8: =X8*12 -> 11184 | X8: 932 | Y8: =Z8*12 -> 11232 | Z8: 936 | AA8: =AB8*12 -> 11448 | AB8: 954
D9: Overgangsordning I for 2011 - beskæringen kan højest udgøre 1/3-del af ydelsen over max. | E9: =IF(E8/3<=0,0,E8/3) -> 0 | J9: Dette maks er ophævet fra 2012.
D10: Overgangsordning 2 for 2011 - beskæring på max. 12000 | E10: =IF(E9>=12000,12000,E9) -> 0 | J10: Dette maks er ophævet fra 2012. | P10: =IF($B$3=2018,Y10,"") | S10: 723100 | U10: 732900 | W10: 749000 | Y10: 765000
D11: Udbetaling før eventuel fratræk for høj indkomst | E11: =E6 -> 18384 | G11: =E11/12 -> 1532
D12: Fratræk for høj indkomst | E12: =Aftrapning!F21 -> 0
D13: Børnecheck efter fratræk for høje indkomster pr. år | E13: =E11-E12 -> 18384 | F13: pr. måned: | G13: =E13/12 -> 1532
B15: 2018 | C15: ok | D15: Varme | E15: Model fra: Danish Building Research Institute - Kirsten Gram-Hanssen. http://vbn.aau.dk/files/14395277/SBi_2005-09.pdf side 6
D16: Varmeforbrug i parcelhuse: 4816 kWh + 104kWh/m2 * kvadratmeter bolig. | H16: Det valgte fyr er: | J16: =VLOOKUP(K16,G19:J25,2) -> Fjernvarme | K16: =Dialog!D3 -> 5 | P16: Baseret på følgende beregninger:
D17: Konstant 1 | E17: 4816 | F17: kWh
D18: Konstant 2 | E18: 104 | F18: kWh | H18: Priser pr. kWh: | P18: Oliefyr: | Q18: Aktuel pris: 11.02.2014 | R18: =U23 -> 43838
D19: Kvadratmeter boligareal (valgt i Start) | E19: =Input!D35 -> 0 | F19: m2 | G19: 1 | H19: Oliefyr (nyt) | J19: =Q23 -> 1.2011579 | K19: kr./kWh | L19: 1 | P19: 1 liter olie indeholder optimalt | Q19: 10 | R19: kWh pr. liter olie
D20: Antal kWh til opvarmning af bolig | E20: =E17+E18*E19 -> 4816 | F20: kWh | G20: 2 | H20: Oliefyr (gammelt) | J20: =Q24 -> 1.6301429 | K20: kr./kWh | L20: 2 | P20: Ny oliefyr - virkningsgrad er 95 procent | Q20: =Q19*95% -> 9.5 | R20: kWh pr. liter olie
D21: Hvis boligen opvarmes med el (det er kwh-timer over dette der bruges til opvarmning og får rabat) | E21: =IF($K$16=6,4000,0) -> 0 | F21: kWh | G21: 3 | H21: Gasfyr (nyt) | J21: =Q31 -> 0.4905303 | K21: kr./kWh | L21: 3 | P21: Gammelt oliefyr - virkningsgrad 70 procent | Q21: =Q19*70% -> 7 | R21: kWh pr. liter olie | S21: Fyr fra 1977 eller før.
D22: Resterende antal kwh til opvarmning | E22: =E20-E21 -> 4816 | F22: kWh | G22: 4 | H22: Gasfyr (gammelt) | J22: =Q32 -> 0.62787879 | K22: kr./kWh | L22: 4 | P22: Aktuel pris på fyringsolie: | Q22: =T23/1000 -> 11.411 | R22: kr. pr. liter | S22: https://bestilfyringsolie.dk/order-page/olietype-olietank/
D23: Prisen pr. kWh for det valgte fyr | E23: =VLOOKUP(K16,G19:J25,4) -> 0.7019337 | F23: kr./kWh | G23: 5 | H23: Fjernvarme | J23: =Q45 -> 0.7019337 | K23: kr./kWh | L23: 5 | P23: Nyt oliefyr: | Q23: =Q22/Q20 -> 1.2011579 | R23: kr. pr. kWh inklusiv moms | S23: Prisen --> | T23: 11411 | U23: 43838
D24: Varmeudgift til det valgte fyr | E24: =E22*E23 -> 3380.5127 | F24: kr. | G24: 6 | H24: El | J24: =J27-0.7813 -> 1.4687 | K24: kr./kWh | L24: 6 | N24: Der er trukket fra for rabat ved el-varme. Se note. | P24: Gammelt oliefyr: | Q24: =Q22/Q21 -> 1.6301429 | R24: kr. pr. kWh inklusiv moms
G25: 7 | H25: Træpillefyr | J25: =Q40 -> 0.48225309 | K25: kr./kWh | L25: 7
D26: Varmeforbrug i etageboliger: -2577 kWh +119 kWh/m2 * kvadratmeter bolig | P26: Gasfyr | Q26: Aktuel pris: Hos DONG. Det kan være billigere, men også dyrere. | R26: 43838
D27: Konstant | E27: -2577 | F27: kWh | H27: El uden varmerabat | I27: --> | J27: 2.25 | K27: kr./kWh | N27: https://www.seas-nve.dk/privat/el/elvarme | P27: 1 kubikmeter naturgas indeholder optimalt | Q27: 11 | R27: kWh pr. kubikmeter naturgas
D28: Variabel efter kvadratmeter | E28: 119 | F28: kWh | H28: Se side om el-opvarmning: | P28: Nyt gasfyr - virkningsgrad 96 procent | Q28: =Q27*96% -> 10.56 | R28: kWh pr. kubikmeter naturgas
D29: Kvadratmeter boligareal | E29: =Input!D35 -> 0 | F29: m2 | P29: Gammelt gasfyr - virkningsgrad 75 procent | Q29: =Q27*75% -> 8.25 | R29: kWh pr. kubikmeter naturgas
D30: Antal kWh til opvarmning af bolig | E30: =E27+E28*E29 -> -2577 | F30: kWh | P30: Aktuelt pris på naturgas: | Q30: 5.18 | R30: kr. pr. m3 | S30: http://gasprisguiden.dk/#
D31: Hvis boligen opvarmes med el (det er kwh-timer over dette der bruges til opvarmning og får rabat) | E31: =IF($K$16=6,4000,0) -> 0 | F31: kWh | P31: Nyt gasfyr: | Q31: =Q30/Q28 -> 0.4905303 | R31: kr. pr. kWh inklusiv moms
D32: Resterende antal kwh til opvarmning | E32: =E30-E31 -> -2577 | F32: kWh | P32: Gammelt gasfyr: | Q32: =Q30/Q29 -> 0.62787879 | R32: kr. pr. kWh inklusiv moms
D33: Prisen pr. kWh for det valgte fyr | E33: =VLOOKUP(K16,G19:J25,4) -> 0.7019337 | F33: kr./kWh
D34: Varmeudgift til det valgte fyr | E34: =E30*E33 -> -1808.8831 | F34: kr. | P34: Pillefyr | Q34: Aktuel pris hos Dalmosebraende.dk | R34: 43838
P35: 1 kg træpiller indeholder | Q35: 4.86 | R35: kWh
D36: Den valgte bolig er: | E36: =Dialog!$B$3 -> 1 | F36: =IF(AND(E36>=1,E36<=3),"Hus",IF(AND(E36>=4,E36<=7),"Lejlighed","")) -> Hus | P36: Nyt pillefyr - virkningsgrad 95 % | Q36: =Q35*95% -> 4.617 | R36: kWh pr. kg | S36: http://www.dalmosebraende.dk/
D37: Valg mellem de to | E37: =IF(F36="Hus",E24,E34) -> 3380.5127 | F37: kr.
D38: 0-stilling hvis negativ | E38: =IF(E37<=0,0,E37) -> 3380.5127
P39: Prisen på et kilo træpiller: | Q39: =1995/896 -> 2.2265625 | R39: <-- ret ved prisændringer | S39: https://www.dalmosebraende.dk/traepiller-i-saekke.html
D40: El | E40: Model fra: Danish Building Research Institute - Kirsten Gram-Hanssen. http://www.en.sbi.dk/miljo-og-energi/livsstil-og-adferd/husholdningers-energi-og-vandforbrug/sammenfatning | P40: Nyt pillefyr: | Q40: =Q39/Q36 -> 0.48225309 | R40: kr. pr. kWh inklusiv moms
D41: Elforbrug i parcelhus: 530 kWh + 12 kWh/m2*kvadratmeter bolig + 690 kWh/pers. * antal personer
...

Sheet Aftrapning
B1: Reduktion af børne- og ungeydelsen hvis høje indtægter | C1: ok 2020
B2: Hvis der er børn under 18 år i husstanden, skal der ekstra spørgsmål ind i tungerne for navn og indtægt:
D5: Valg af indkomst pr. måned | E5: Valg af indkomst pr. år | F5: Indkomst over beskatningsgrundlag | G5: Styring af valg
B6: Hvis der kun er én voksen: | G6: =IF(Input!D8<=1,1,0) -> 0
B7: Månedsløn før skat --> | C7: =Input!E13 -> 17685.593 | D7: =IF(G6=1,C7,"") | E7: =IF(D7="","",D7*12) | F7: =IF(E7="","",IF(E7-$C$23>0,E7-$C$23,""))
B9: Hvis der er flere end én voksen:
B10: Er I gift eller ugift? --> | C10: =IF(G10=1,"Ugifte","Gifte") -> Ugifte | G10: =Dialog!P3 -> 1 | I10: 1 = ugifte 2 = gifte (Vælges i "Dialog")
B12: Hvis ugifte:
B13: Indkomst før skat hos den, der modtager børne- og ungeydelsen --> | C13: =I20 -> 17685.593 | D13: =IF(AND(G6=0,G10=1),C13,"") -> 17685.593 | E13: =IF(D13="","",D13*12) -> 212227.11 | F13: =IF(E13="","",IF(E13-$C$23>0,E13-$C$23,"")) | I13: Den mindste løn:
I14: =Input!E13 -> 17685.593
B15: Hvis gifte: | I15: =Input!E14 -> 176855.93
B16: Indkomst pr. måned før skat hos person 1 --> | C16: =Input!E13 -> 17685.593 | D16: =IF(AND(G6=0,D13=""),C16,"") | E16: =IF(D16="","",D16*12) | F16: =IF(E16="","",IF(E16-$C$23>0,E16-$C$23,"")) | I16: =Input!E15 -> 0
B17: Indkomst pr. måned før skat hos person 2 --> | C17: =Input!E14 -> 176855.93 | D17: =IF(AND(G6=0,G10=2),C17,"") | E17: =IF(D17="","",D17*12) | F17: =IF(E17="","",IF(E17-$C$23>0,E17-$C$23,"")) | I17: =Input!E16 -> 0
B18: Samlet indkomst: | C18: =C16+C17 -> 194541.52 | D18: =SUM(D16:D17) -> 0 | E18: =IF(D18="","",D18*12) -> 0 | F18: =SUM(F16:F17) -> 0 | I18: =Input!E17 -> 0
I19: =Input!E18 -> 0
B20: Den valgte indkomst til aftrapning: | F20: =MAX(F7,F13,F18) -> 0 | I20: =IF(I15<=0,I14,IF(SUM(I16:I19)<=0,MIN(I14:I15),IF(SUM(I17:I19)<=0,MIN(I14:I16),IF(SUM(I18:I19)<=0,MIN(I14:I17),IF(I19<=0,MIN(I14:I18),MIN(I14:I19)))))) -> 17685.593 | J20: Valget af den mindste løn
B21: 2 procent af dette | F21: =F20*2% -> 0
B23: Bundfradraget for 2020 før reduktion med AM-bidrag er: | C23: =C27 -> 869673.91
B25: Beregning af bundfradraget før AM-bidrag:
B26: Bundfradraget i topskattegrundlaget --> | C26: 800100 | D26: <-- 2020
B27: Bundfradraget før AM-bidraget: | C27: =C26/(1-0.08) -> 869673.91
B29: Borger.dk | C29: https://www.borger.dk/familie-og-boern/Familieydelser-oversigt/Boerne-ungeydelse/Boerne-ungeydelse-nedsaettelse
B30: Reglerne - Skatteministeriet: | C30: https://www.retsinformation.dk/Forms/R0710.aspx?id=143287
B31: Personskattelovens § 7 | C31: https://www.retsinformation.dk/forms/r0710.aspx?id=145909
B33: Alt om familie og børn | C33: https://www.borger.dk/familie-og-boern/Familieydelser-oversigt/Boerne-ungeydelse/Boerne-ungeydelse-nedsaettelse

Sheet Dialog
B2: Dialogboks bolig | D2: Dialog varmekilde | G2: Dialog bilforsikring - bil 1 | H2: Kolonne-nummer i Kommunedata | I2: Dialog bilforsikring - bil 2 | J2: Kolonne-nummer i Kommunedata | K2: Dialog bilforsikring - bil 3 | L2: Kolonne-nummer i Kommunedata | M2: Valg af kommune i K-data | N2: Valg af kommune i K-data2 | P2: Dialog - gift/ugift | Q2: Dialog bolig - opført | R2: Indboforsikring | S2: Husforsikring | T2: Vuggestue | U2: Børnehave | V2: SFO
B3: 1 | D3: 5 | G3: 1 | H3: =23+G3 -> 24 | I3: 1 | J3: =23+I3 -> 24 | K3: 1 | L3: =23+K3 -> 24 | M3: 1 | N3: =VLOOKUP(Dialog!M3,Kommunedata!B4:D101,2) -> 165 | P3: 1 | Q3: 4 | R3: Fra K-data: | S3: Fra K-data: | T3: Fra K-data: | U3: Fra K-data: | V3: Fra K-data:
B4: Boligtype: | D4: Varmekilde: | G4: Vælg: | O4: 1 | P4: Ugift | Q4: Vælg byggeår: | R4: 21 | S4: 22 | T4: 7 | U4: 13 | V4: 16
A5: 1 | B5: Alle boliger | C5: 1 | D5: Oliefyr (nyt) | F5: 1 | G5: Ingen bil | I5: Ingen bil | K5: Ingen bil | O5: 2 | P5: Gift | Q5: 1940 | R5: =IF((Input!D8+Input!D29)=0,0,VLOOKUP(Dialog!M3,Kommunedata!B4:W101,21)) -> 3434 | S5: =IF((Input!D8+Input!D29)=0,0,VLOOKUP(Dialog!M3,Kommunedata!B4:W101,22)) -> 5764 | T5: =VLOOKUP(Dialog!M3,Kommunedata!B4:Q101,7)*Modeller!E204 -> 3489 | U5: =VLOOKUP(Dialog!M3,Kommunedata!B4:Q101,13)*Modeller!E205 -> 0 | V5: =VLOOKUP(Dialog!M3,Kommunedata!B4:Q101,16)*Modeller!E206 -> 0
A6: 2 | B6: Eget parcelhus e.l. | C6: 2 | D6: Oliefyr (gammelt) | F6: 2 | G6: Lille bil - skadefri i 0-2 år | I6: Lille bil - skadefri i 0-2 år | K6: Lille bil - skadefri i 0-2 år | Q6: 1960 | R6: Fra K-data2: | S6: Fra K-data2: | T6: Fra K-data2: | U6: Fra K-data2: | V6: Fra K-data2:
A7: 3 | B7: Lejet hus | C7: 3 | D7: Gasfyr (nyt) | F7: 3 | G7: Lille bil - skadefri i 3-4 år | I7: Lille bil - skadefri i 3-4 år | K7: Lille bil - skadefri i 3-4 år | Q7: 1980 | R7: =R4-1 -> 20 | S7: =S4-1 -> 21 | T7: =T4-1 -> 6 | U7: =U4-1 -> 12 | V7: =V4-1 -> 15
A8: 4 | B8: Ejerlejlighed | C8: 4 | D8: Gasfyr (gammelt) | F8: 4 | G8: Lille bil - skadefri i 5 år eller mere (elite) | I8: Lille bil - skadefri i 5 år eller mere (elite) | K8: Lille bil - skadefri i 5 år eller mere (elite) | Q8: 2000 | R8: =IF((Input!D8+Input!D29)=0,0,VLOOKUP(Dialog!N3,Kommunedata2!C4:W101,20)) -> 3434 | S8: =IF((Input!D8+Input!D29)=0,0,VLOOKUP(Dialog!N3,Kommunedata2!C4:W101,21)) -> 5764 | T8: =VLOOKUP(Dialog!N3,Kommunedata2!C4:Q101,6)*Modeller!E204 -> 3489 | U8: =VLOOKUP(Dialog!N3,Kommunedata2!C4:Q101,12)*Modeller!E205 -> 0 | V8: =VLOOKUP(Dialog!N3,Kommunedata2!C4:Q101,15)*Modeller!E206 -> 0
A9: 5 | B9: Lejelejlighed | C9: 5 | D9: Fjernvarme | F9: 5 | G9: Mellem - skadefri i 0-2 år | I9: Mellem - skadefri i 0-2 år | K9: Mellem - skadefri i 0-2 år
A10: 6 | B10: Andelsbolig | C10: 6 | D10: El | F10: 6 | G10: Mellem - skadefri i 3-4 år | I10: Mellem - skadefri i 3-4 år | K10: Mellem - skadefri i 3-4 år
A11: 7 | B11: Lejet værelse | C11: 7 | D11: Træpillefyr | F11: 7 | G11: Mellem - skadefri i 5 år eller mere (elite) | I11: Mellem - skadefri i 5 år eller mere (elite) | K11: Mellem - skadefri i 5 år eller mere (elite)
F12: 8 | G12: Stor - skadefri i 0-2 år | I12: Stor - skadefri i 0-2 år | K12: Stor - skadefri i 0-2 år
B13: Valgt: | F13: 9 | G13: Stor - skadefri i 3-4 år | I13: Stor - skadefri i 3-4 år | K13: Stor - skadefri i 3-4 år
B14: =IF(B3=1,B5,IF(B3=2,B6,IF(B3=3,B7,IF(B3=4,B8,IF(B3=5,B9,IF(B3=6,B10,IF(B3=7,B11,""))))))) -> Alle boliger | F14: 10 | G14: Stor - skadefri i 5 år eller mere (elite) | I14: Stor - skadefri i 5 år eller mere (elite) | K14: Stor - skadefri i 5 år eller mere (elite)
F15: 11 | G15: Meget stor - skadefri i 0-2 år | I15: Meget stor - skadefri i 0-2 år | K15: Meget stor - skadefri i 0-2 år
F16: 12 | G16: Meget stor - skadefri i 3-4 år | I16: Meget stor - skadefri i 3-4 år | K16: Meget stor - skadefri i 3-4 år
F17: 13 | G17: Meget stor- skadefri i 5 år eller mere (elite) | I17: Meget stor- skadefri i 5 år eller mere (elite) | K17: Meget stor- skadefri i 5 år eller mere (elite)
E18: Ingen bil | H18: =IF(G3=1,0,0) -> 0 | J18: =IF(I3=1,0,0) -> 0 | L18: =IF(K3=1,0,0) -> 0
E19: Små biler i alt | F19: =SUM(H19:L19) -> 0 | H19: =IF(AND(G3>1,G3<5),1,0) -> 0 | J19: =IF(AND(I3>1,I3<5),1,0) -> 0 | L19: =IF(AND(K3>1,K3<5),1,0) -> 0
E20: Mellem i alt | F20: =SUM(H20:L20) -> 0 | H20: =IF(AND(G3>4,G3<8),1,0) -> 0 | J20: =IF(AND(I3>4,I3<8),1,0) -> 0 | L20: =IF(AND(K3>4,K3<8),1,0) -> 0
E21: Stor i alt | F21: =SUM(H21:L21) -> 0 | H21: =IF(AND(G3>7,G3<11),1,0) -> 0 | J21: =IF(AND(I3>7,I3<11),1,0) -> 0 | L21: =IF(AND(K3>7,K3<11),1,0) -> 0
E22: Meget stor i alt | F22: =SUM(H22:L22) -> 0 | H22: =IF(AND(G3>10,G3<=13),1,0) -> 0 | J22: =IF(AND(I3>10,I3<=13),1,0) -> 0 | L22: =IF(AND(K3>10,K3<=13),1,0) -> 0
G24: Valgte forsikring for bil 1 i K-data | H24: =VLOOKUP(Dialog!M3,Kommunedata!B4:AK101,H3) -> 0 | I24: K-data | J24: =VLOOKUP(Dialog!M3,Kommunedata!B4:AK101,J3) -> 0 | K24: =I24 -> K-data | L24: =VLOOKUP(Dialog!M3,Kommunedata!B4:AK101,L3) -> 0
