Workbook
Name FEFCO_plot: Plot!$B$136:$J$161
Name FEFCOGEENPRIJS: Mastersheet!$A$64:$B$78
Name Kwaliteit_plot: Plot!$B$99:$E$131
Name Snelheid_plot: Plot!$C$71:$E$74
Name Tape_aantal_plot: Plot!$B$78:$B$92
Name Tape_prijs_plot: Plot!$C$78:$C$92
Name Tapen_plot: Plot!$B$78:$C$92

Sheet BLO
A1: Input | E1: Output | K1: LEVERTIJD
A2: FEFCO | B2: 0201 | C2: 500 | E2: per_price | F2: =Mastersheet!K43 -> 0.85 | K2: Pakketmaten
A3: Lengte | B3: 300 | E3: staffel2_qty | F3: =Mastersheet!L44 -> 1800 | K3: 200 stuks nog niet optimaal
A4: Breedte | B4: 250 | E4: staffel2_price | F4: =Mastersheet!K44 -> 0 | K4: grote dozen te goedkoop
A5: Hoogte | B5: 100 | E5: staffel3_qty | F5: =Mastersheet!L45 -> 1800 | K5: meerdere naar elkaar stapelen pakketmaat
A6: Kwaliteit | B6: 10010 | E6: staffel3_price | F6: =Mastersheet!K45 -> 0.42 | K6: Dozenlaten maken machine 2,5m breed
A7: Bedrukking | B7: onbedrukt | E7: staffel4_qty | F7: =Mastersheet!L46 -> 490
A8: Handgrepen | B8: geen handgrepen / stansbewerking | E8: staffel4_price | F8: =Mastersheet!K46 -> 0.7 | K8: Opmerking nog aanpassen
A9: Aantal | B9: 400 | E9: pallet_qty | F9: =Mastersheet!C88 -> 1800 | K9: Klein 427 bij doosopmaat in E golf te duur
E10: status | F10: =Mastersheet!M53 -> RegularPrice
E11: remark | F11: =Mastersheet!M58
A12: Rekenen bedrukking | B12: =IF(B7="Full color (CMYK)","onbedrukt",B7) -> onbedrukt | E12: deliverytime_from | F12: =Mastersheet!B100 -> 8
E13: deliverytime_to | F13: =Mastersheet!B101 -> 12
E17: Inkoop Fris | F17: =Input!B23 -> 0.72166405
E18: Inkoop Faes | F18: =Plot!D55 -> 1.2092969

Sheet Mastersheet
A1: Aantal gevraagd | D1: =Input!B17 -> 400 | M1: Code actief voor staffel 1 | N1: Code | O1: Tekst
A3: Stansdoos | D3: =VLOOKUP(Input!B6,Plot!FEFCO_plot,9,0) -> 0 | L3: Alleen prijzen van van Plotter gebruiken
A4: Bedrukte doos | D4: =IF(Input!B11="onbedrukt",0,1) -> 0 | L4: Alleen prijzen van van Boxmaker gebruiken | O4: Voor dozen met flexo bedrukking is de prijs exclusief eenmalige cliche kosten, vanaf 300 euro per drukkleur, afhankelijk van het ontwerp. SUPERTIP: Selecteer Full Color voor bedrukking ZONDER opstartkosten
A5: Digitale druk | D5: =IF(BLO!B7="Full color (CMYK)",1,0) -> 0
A6: m2 per verpakking | D6: =Rekenblad!H108 -> 0.402154
A7: 200 m2 is x dozen | D7: =CEILING(200/D6, 10) -> 500
A8: Snelle check | L8: Opmerking
A9: Doostype zonder prijs | D9: =VLOOKUP(Input!B6,A65:B78,2,0) -> 0 | L9: Direct code terug geven en geen berekening | M9: =D9 -> 0 | N9: MustRequestQuote | O9: Vraag een offerte aan voor snel een aanbod, deze samenstelling kunnen we helaas nog niet uitrekenen
A10: Bedrukte stansdoos | D10: =IF(AND(D4=1, D3=1), 1, 0) -> 0 | L10: Direct code terug geven en geen berekening | M10: =D10 -> 0 | N10: MustRequestQuote | O10: Selecteer de optie Full color voor direct een prijs. Bij aantallen boven 3000 stuks vraag een speciale prijs op
A11: Niet-stansdoos en niet maakbaar | D11: =IF(D3=1, 0, IF(Rekenblad!J1075=1, 0, 1)) -> 0 | L11: Direct code terug geven en geen berekening | M11: =D11 -> 0 | N11: MustRequestQuote | O11: Vraag een offerte aan voor snel een aanbod, deze samenstelling kunnen we helaas nog niet uitrekenen
A13: Welk staffels mogen aangeboden worden? | L13: Opmerking
A14: Staffel check | D14: Variabele 1 | F14: Variabele 2 | G14: Staffel 1 | H14: Staffel 2 | I14: Staffel 3 | J14: Staffel 4
A15: Aantal | G15: =VLOOKUP(1,B85:C91,2,0) -> 400 | H15: =VLOOKUP(2,B85:C91,2,0) -> 1800 | I15: =VLOOKUP(3,B85:C91,2,0) -> 1800 | J15: =VLOOKUP(4,B85:C91,2,0) -> 490
A16: Aantal m2 | G16: =G15*D6 -> 160.8616 | H16: =H15*D6 -> 723.8772 | I16: =I15*D6 -> 723.8772 | J16: =D6*J15 -> 197.05546 | L16: Meer m2 dan X voor altijd offerte | M16: =M22 -> 0 | N16: =N22 -> MustRequestQuote | O16: =O22 -> Voor dit aantal maken we graag een speciale aanbieding, vraag een offerte aan en ontvang snel een mooi aanbod.
A17: Meer m2 dan X voor vanaf prijs | B17: M2 | D17: 3500 | G17: =IF(G16>$D$17,1,0) -> 0 | H17: =IF(H16>$D$17,1,0) -> 0 | I17: =IF(I16>$D$17,1,0) -> 0 | J17: =IF(J16>$D$17,1,0) -> 0 | L17: Vanaf prijs | M17: =G17 -> 0 | N17: CanRequestBetterQuote | O17: Dit is een vanaf prijs, deze aantallen kunnen we vaak nóg voordeliger aanbieden. Vraag een offerte aan voor een scherp aanbod.
L19: Wel een prijs bij andere staffel | M19: =IF(AND(J43=0, J47>0), 1, 0) -> 0 | N19: OtherQtyHasPrice | O19: Het gevraagde aantal kunnen we niet aanbieden. SUPERTIP: Selecteer de optie Full color voor direct een prijs in klein oplage. Of kijk hieronder voor het minimale bestelaantal voor deze bedrukte doos.
A20: Meer m2 dan X en stansdoos | B20: M2 | D20: 1000 | E20: Stansdoos | F20: =D3 -> 0 | G20: =IF(G16>$D$20,1,0)*F20 -> 0 | H20: =IF(H16>$D$20,1,0)*F20 -> 0 | I20: =IF(I16>$D$20,1,0)*F20 -> 0 | J20: =IF(J16>$D$20,1,0)*F20 -> 0 | L20: Vanaf prijs | M20: =G20 -> 0 | N20: CanRequestBetterQuote | O20: Dit is een vanaf prijs, deze aantallen kunnen we voordeliger aanbieden met een andere productietechniek. Vraag een offerte aan voor een scherp aanbod.
A21: Minder dan X stuks | B21: Stuks | D21: 10 | G21: =IF(G15<$D$21,1,0) -> 0 | H21: =IF(H15<$D$21,1,0) -> 0 | I21: =IF(I15<$D$21,1,0) -> 0 | J21: =IF(J15<$D$21,1,0) -> 0 | L21: Geen prijs | M21: =G21 -> 0 | N21: NoPricePossible
A22: Meer m2 dan X voor altijd offerte | B22: M2 | D22: 8000 | G22: =IF(G16>$D$22,1,0) -> 0 | H22: =IF(H16>$D$22,1,0) -> 0 | I22: =IF(I16>$D$22,1,0) -> 0 | J22: =IF(J16>$D$22,1,0) -> 0 | L22: Geen prijs, alleen offerte | M22: =G22 -> 0 | N22: MustRequestQuote | O22: Voor dit aantal maken we graag een speciale aanbieding, vraag een offerte aan en ontvang snel een mooi aanbod.
A23: Minder dan X m2 bedrukt | B23: M2 | D23: 300 | E23: Bedrukt | F23: =D4 -> 0 | G23: =IF(G16<$D$23,1,0)*F23 -> 0 | H23: =IF(H16<$D$23,1,0)*F23 -> 0 | I23: =IF(I16<$D$23,1,0)*F23 -> 0 | J23: =IF(J16<$D$23,1,0)*F23 -> 0 | L23: Geen prijs | M23: =G23 -> 0 | N23: NoPricePossible
A24: Staffel staat er dubbel in | H24: =IF(OR(H15=G15, H15=I15, H15=J15), 1, 0) -> 1
A25: Staffel verbergen | G25: =IF(SUM(G21:G24) >= 1, 1, 0) -> 0 | H25: =IF(SUM(H20:H24) >= 1, 1, 0) -> 1 | I25: =IF(SUM(I20:I24) >= 1, 1, 0) -> 0 | J25: =IF(SUM(J20:J24) >= 1, 1, 0) -> 0
A27: Welk leveranciers mogen aangeboden worden?
E28: Diskwalificator
A29: Plotter prijzen gebruiken | B29: Stansdoos | D29: =D3 -> 0 | E29: 1
B30: Bedrukt | D30: =D4 -> 0 | E30: =IF(D30=1,0,1) -> 1
B31: Digitaal bedrukt en te groot | D31: =Digitaaldruk!J3 -> 0 | E31: =IF(AND(D5=1,D31=1),"0",1) -> 1
E32: =E30*E29*E31 -> 1 | F32: =IF(E32=0,"niet gebruiken","prijs gebruiken") -> prijs gebruiken
A34: Boxmaker prijzen gebruiken | B34: Stansdoos | D34: =D3 -> 0 | E34: =IF(D34=1,0,1) -> 1
B35: Bedrukt | D35: =D4 -> 0 | E35: 1
B36: Digitaal bedrukt en te groot | D36: =Digitaaldruk!J3 -> 0 | E36: =IF(AND(D5=1,D36=1),"0",1) -> 1
E37: =E35*E34*E36 -> 1 | F37: =IF(E37=0,"niet gebruiken","prijs gebruiken") -> prijs gebruiken
B38: Marge | E38: =IF(D4=1,E41,IF(D5=1,E40,E39)) -> 1.18
B39: Basismarge | E39: 1.18
B40: Digtale druk marge | E40: 1.35
B41: Flexo marge | E41: 1.22
B42: Staffel tonen | C42: Niet maakbaar | D42: Plotter | E42: Prijs | F42: Te gebruiken | G42: Boxmaker | H42: Prijs | I42: Te gebruiken | J42: Laagste prijs | K42: Afgerond | L42: Staffel hoeveelheid
A43: Staffel 1 | B43: =IF(G25=1,0,1) -> 1 | C43: =IF(D11=1,0,1) -> 1 | D43: =E32 -> 1 | E43: =IFERROR(Plot!F1, 0) -> 1.5720859 | F43: =E43*D43*B43*C43 -> 1.5720859 | G43: =E37 -> 1 | H43: =IFERROR(Input!B23*E38, 0) -> 0.85156357 | I43: =H43*G43*B43*C43 -> 0.85156357 | J43: =IF(AND(F43=0,I43=0),0,IF(F43=0,I43,IF(I43=0,F43,MIN(F43,I43)))) -> 0.85156357 | K43: =ROUND(J43,2) -> 0.85 | L43: =G15 -> 400
A44: Staffel 2 | B44: =IF(H25=1,0,1) -> 0 | C44: =IF(D11=1,0,1) -> 1 | D44: =E32 -> 1 | E44: =IFERROR(Plot!R1, 0) -> 1.2568627 | F44: =E44*D44*B44*C44 -> 0 | G44: =E37 -> 1 | H44: =IFERROR('Input (2)'!B23*E38, 0) -> 0.42205112 | I44: =H44*G44*B44*C44 -> 0 | J44: =IF(AND(F44=0,I44=0),0,IF(F44=0,I44,IF(I44=0,F44,MIN(F44,I44)))) -> 0 | K44: =ROUND(J44,2) -> 0 | L44: =H15 -> 1800
A45: Staffel 3 | B45: =IF(I25=1,0,1) -> 1 | C45: =IF(D11=1,0,1) -> 1 | D45: =E32 -> 1 | E45: =IFERROR(Plot!AB1, 0) -> 1.2568627 | F45: =E45*D45*B45*C45 -> 1.2568627 | G45: =E37 -> 1 | H45: =IFERROR('Input (3)'!B23*E38, 0) -> 0.42205112 | I45: =H45*G45*B45*C45 -> 0.42205112 | J45: =IF(AND(F45=0,I45=0),0,IF(F45=0,I45,IF(I45=0,F45,MIN(F45,I45)))) -> 0.42205112 | K45: =ROUND(J45,2) -> 0.42 | L45: =I15 -> 1800
...

Sheet Digitaaldruk
A2: Aanschaf | B2: 200000
A3: Afschrijving | B3: 60 | C3: maanden | D3: Doos | E3: =BLO!B3 -> 300 | F3: =BLO!B4 -> 250 | G3: =BLO!B5 -> 100 | I3: Te groot | J3: =IF(AND(E46>2500,E47>2500),1,0) -> 0
B4: 80 | C4: uren per maand
A5: Afschijving per maand | B5: =B2/B3 -> 3333.3333
A6: Onderhoud per maand | B6: =(B2*0.1)/12 -> 1666.6667 | D6: Plano | E6: Plano
A7: Kosten afschrijving plus onderhoud | B7: =B5+B6 -> 5000 | D7: Breedte | E7: Lengte | F7: M2
A8: Kosten afschrijving plus onderhoud / uur | B8: =B7/B4 -> 62.5 | D8: =Plot!G9 -> 361 | E8: =Plot!G10 -> 1114 | F8: =D8*E8 -> 402154
D10: 600 | E10: m2/uur
A11: Inkt per maand | B11: 300 | C11: (28 euro per liter)
A12: Prints per maand | B12: 20000 | E12: DPI
A13: Kost inkt per print | B13: =B11/B12 -> 0.015 | D13: Low | E13: 200x600 | G13: =E8/F13/1000 -> #DIV/0! | H13: seconde per product
D14: Middle | E14: 300x600 | G14: =E8/F14/1000 -> #DIV/0! | H14: seconde per product
A15: Instel machine | B15: 20 | C15: minuten | D15: High | E15: 600x600 | F15: 1 | G15: =E8/F15/1000 -> 1.114 | H15: seconde per product
A16: Per order kartoor | B16: 25 | C16: euro
A17: Extra handling | B17: 10 | D17: Tijd totale run | F17: Seconde | G17: =G15*G21 -> 445.6 | H17: =G15*H21 -> 2005.2 | I17: =G15*I21 -> 2005.2 | J17: =G15*J21 -> 545.86
B18: =SUM(B16:B17) -> 35 | F18: Minuten | G18: =G17/60 -> 7.4266667 | H18: =H17/60 -> 33.42 | I18: =I17/60 -> 33.42 | J18: =J17/60 -> 9.0976667
A19: Operator cost per dag | F19: Uren | G19: =G18/60 -> 0.12377778 | H19: =H18/60 -> 0.557 | I19: =I18/60 -> 0.557 | J19: =J18/60 -> 0.15162778
A20: Bruto loon | B20: 4000
A21: Bruto naar kosten | B21: 0.63 | D21: Prijsopbouw | F21: Aantal | G21: =BLO!B9 -> 400 | H21: =Mastersheet!L44 -> 1800 | I21: =Mastersheet!L45 -> 1800 | J21: =Mastersheet!L46 -> 490
B22: =B21*B20 -> 2520 | G22: Per stuk
A23: Totaal kosten | B23: =B20+B22 -> 6520 | D23: Order kosten | E23: =B44 -> 91.336616 | F23: per order | G23: =$E$23/G21 -> 0.22834154 | H23: =$E$23/H21 -> 0.050742565 | I23: =$E$23/I21 -> 0.050742565 | J23: =$E$23/J21 -> 0.18640126
A24: Uren per maand | B24: 165 | D24: Uur kosten | E24: =B57 -> 169.00985 | F24: per uur | G24: =G19*$E$24/G21 -> 0.052299159 | H24: =H19*$E$24/H21 -> 0.052299159 | I24: =I19*$E$24/I21 -> 0.052299159 | J24: =J19*$E$24/J21 -> 0.052299159
A25: Tarief per uur | B25: =B23/165 -> 39.515152 | D25: Inkt kosten | G25: =$B$59 -> 0.015 | H25: =$B$59 -> 0.015 | I25: =$B$59 -> 0.015 | J25: =$B$59 -> 0.015
A26: Marge op tarief | B26: 0.15 | D26: Extra marge | E26: 0.2 | G26: =SUM(G23:G25)*$E$26 -> 0.05912814 | H26: =SUM(H23:H25)*$E$26 -> 0.023608345 | I26: =SUM(I23:I25)*$E$26 -> 0.023608345 | J26: =SUM(J23:J25)*$E$26 -> 0.050740083
A27: Kosten 1* operator / uur | B27: =B25+B25*B26 -> 45.442424
A28: Kosten 2* Operator / uur | B28: =B27*2 -> 90.884848 | D28: Totale extra kosten per stuk | G28: =SUM(G23:G26) -> 0.35476884 | H28: =SUM(H23:H26) -> 0.14165007 | I28: =SUM(I23:I26) -> 0.14165007 | J28: =SUM(J23:J26) -> 0.3044405
F29: afgerond | G29: =ROUND(G28,2) -> 0.35 | H29: =ROUND(H28,2) -> 0.14 | I29: =ROUND(I28,2) -> 0.14 | J29: =ROUND(J28,2) -> 0.3
A30: Huisvesting m2 | B30: 300 | C30: per m2 | E30: Prijs per m2 | G30: =(G28-G23)/F8*1000000 -> 0.31437534 | H30: =(H28-H23)/F8*1000000 -> 0.22605147 | I30: =(I28-I23)/F8*1000000 -> 0.22605147 | J30: =(J28-J23)/F8*1000000 -> 0.29351751
A31: Kosten Huisvesting per uur | B31: =((B30*50)/(B4*12)) -> 15.625
A33: Stroom | B33: 3
D34: Prijs digitaaldruk | G34: =Digitaaldruk!G28 -> 0.35476884 | H34: =Digitaaldruk!H28 -> 0.14165007 | I34: =Digitaaldruk!I28 -> 0.14165007 | J34: =Digitaaldruk!J28 -> 0.3044405
A36: Kosten overzicht per order
A37: Order kosten | B37: =B18 -> 35
A38: Machine instellen | B38: =B15*B57/60 -> 56.336616
D39: Totaalprijs | G39: =SUM(G34) -> 0.35476884 | H39: =SUM(H34) -> 0.14165007 | I39: =SUM(I34) -> 0.14165007 | J39: =SUM(J34) -> 0.3044405
D40: Te gebruiken prijs | G40: =Mastersheet!$D$5*Digitaaldruk!G39 -> 0 | H40: =Mastersheet!$D$5*Digitaaldruk!H39 -> 0 | I40: =Mastersheet!$D$5*Digitaaldruk!I39 -> 0 | J40: =Mastersheet!$D$5*Digitaaldruk!J39 -> 0
D42: Extra marge | E42: Waarde | F42: Voorwaarde | G42: Marge | H42: Toevoegen
D43: Doostype | E43: =BLO!B2 -> 0201 | F43: 0201 | G43: 0.04 | H43: =IF(E43=F43,G43,0) -> 0.04
A44: Totaal | B44: =SUM(B37:B43) -> 91.336616 | D44: Formaat | E44: =BLO!B3*BLO!B4*BLO!B5 -> 7500000 | F44: 100000000 | G44: 0.05 | H44: =IF(E44>F44,G44,0) -> 0
A45: Kosten per uur | D45: Formaat | E45: =BLO!B3*BLO!B4*BLO!B5 -> 7500000 | F45: 200000000 | G45: 0 | H45: =IF(E45>F45,G45,0) -> 0
...

Sheet Plot
A1: Input | B1: FEFCO | C1: =Input!B6 -> 0201 | E1: Verkoopprijs | F1: =D59+Digitaaldruk!G40 -> 1.5720859 | M1: Input | N1: FEFCO | O1: =$C$1 -> 0201 | Q1: Verkoopprijs | R1: =P59+Digitaaldruk!H40 -> 1.2568627 | W1: Input | X1: FEFCO | Y1: =$C$1 -> 0201 | AA1: Verkoopprijs | AB1: =Z59+Digitaaldruk!I40 -> 1.2568627 | AG1: Input | AH1: FEFCO | AI1: =$C$1 -> 0201 | AK1: Verkoopprijs | AL1: =AJ59+Digitaaldruk!J40 -> 1.5092759
B2: Lengte | C2: =Input!B7 -> 300 | N2: Lengte | O2: =$C$2 -> 300 | X2: Lengte | Y2: =$C$2 -> 300 | AH2: Lengte | AI2: =$C$2 -> 300
B3: Breedte | C3: =Input!B8 -> 250 | N3: Breedte | O3: =$C$3 -> 250 | X3: Breedte | Y3: =$C$3 -> 250 | AH3: Breedte | AI3: =$C$3 -> 250
B4: Hoogte | C4: =Input!B9 -> 100 | N4: Hoogte | O4: =$C$4 -> 100 | X4: Hoogte | Y4: =$C$4 -> 100 | AH4: Hoogte | AI4: =$C$4 -> 100
B5: Karton | C5: =Input!B2 -> 10010 | N5: Karton | O5: =$C$5 -> 10010 | X5: Karton | Y5: =$C$5 -> 10010 | AH5: Karton | AI5: =$C$5 -> 10010
B6: Aantal | C6: =Input!B17 -> 400 | N6: Aantal | O6: =Mastersheet!H15 -> 1800 | X6: Aantal | Y6: =Mastersheet!I15 -> 1800 | AH6: Aantal | AI6: =Mastersheet!J15 -> 490
A8: Berekening | C8: Lengte | D8: Breedte | E8: Hoogte | F8: Extra | G8: Totaal | I8: Productformaat | M8: Berekening | O8: Lengte | P8: Breedte | Q8: Hoogte | R8: Extra | S8: Totaal | U8: Productformaat | W8: Berekening | Y8: Lengte | Z8: Breedte | AA8: Hoogte | AB8: Extra | AC8: Totaal | AE8: Productformaat | AG8: Berekening | AI8: Lengte | AJ8: Breedte | AK8: Hoogte | AL8: Extra | AM8: Totaal | AO8: Productformaat
B9: Planobreedte (golfrichting) | G9: =VLOOKUP($C$1,Rekenblad!B74:G107,2,0) -> 361 | I9: =VLOOKUP($C$1,Rekenblad!B74:G107,5,0) -> 361 | S9: =G9 -> 361 | U9: =I9 -> 361 | X9: Planobreedte | AC9: =S9 -> 361 | AE9: =U9 -> 361 | AH9: Planobreedte | AM9: =AC9 -> 361 | AO9: =AE9 -> 361
B10: Planolengte | G10: =VLOOKUP($C$1,Rekenblad!B74:G107,3,0) -> 1114 | I10: =VLOOKUP($C$1,Rekenblad!B74:G107,6,0) -> 557 | S10: =G10 -> 1114 | U10: =I10 -> 557 | X10: Planolengte | AC10: =S10 -> 1114 | AE10: =U10 -> 557 | AH10: Planolengte | AM10: =AC10 -> 1114 | AO10: =AE10 -> 557
B11: M2 | C11: =G9*G10/1000000 -> 0.402154 | N11: M2 | O11: =S9*S10/1000000 -> 0.402154 | X11: M2 | Y11: =AC9*AC10/1000000 -> 0.402154 | AH11: M2 | AI11: =AM9*AM10/1000000 -> 0.402154
B12: M2 totaal | C12: =C11*C6 -> 160.8616 | N12: M2 totaal | O12: =O11*O6 -> 723.8772 | X12: M2 totaal | Y12: =Y11*Y6 -> 723.8772 | AH12: M2 totaal | AI12: =AI11*AI6 -> 197.05546
C14: Lengte | D14: Breedte | E14: Hoogte | F14: Totaal | G14: Snelheid | O14: Lengte | P14: Breedte | Q14: Hoogte | R14: Totaal | S14: Snelheid | Y14: Lengte | Z14: Breedte | AA14: Hoogte | AB14: Totaal | AC14: Snelheid | AI14: Lengte | AJ14: Breedte | AK14: Hoogte | AL14: Totaal | AM14: Snelheid
B15: Snijlengte | C15: =VLOOKUP($C$1,FEFCO_plot,3,0) -> 4 | D15: =VLOOKUP($C$1,FEFCO_plot,4,0) -> 12 | E15: =VLOOKUP($C$1,FEFCO_plot,5,0) -> 2 | F15: =C15*C2+D15*C3+E15*C4 -> 4400 | G15: =VLOOKUP(C11,Snelheid_plot,3,1) -> 300 | N15: Snijlengte | O15: =VLOOKUP($C$1,FEFCO_plot,3,0) -> 4 | P15: =VLOOKUP($C$1,FEFCO_plot,4,0) -> 12 | Q15: =VLOOKUP($C$1,FEFCO_plot,5,0) -> 2 | R15: =O15*O2+P15*O3+Q15*O4 -> 4400 | S15: =VLOOKUP(O11,Snelheid_plot,3,1) -> 300 | X15: Snijlengte | Y15: =VLOOKUP($C$1,FEFCO_plot,3,0) -> 4 | Z15: =VLOOKUP($C$1,FEFCO_plot,4,0) -> 12 | AA15: =VLOOKUP($C$1,FEFCO_plot,5,0) -> 2 | AB15: =Y15*Y2+Z15*Y3+AA15*Y4 -> 4400 | AC15: =VLOOKUP(Y11,Snelheid_plot,3,1) -> 300 | AH15: Snijlengte | AI15: =VLOOKUP($C$1,FEFCO_plot,3,0) -> 4 | AJ15: =VLOOKUP($C$1,FEFCO_plot,4,0) -> 12 | AK15: =VLOOKUP($C$1,FEFCO_plot,5,0) -> 2 | AL15: =AI15*AI2+AJ15*AI3+AK15*AI4 -> 4400 | AM15: =VLOOKUP(AI11,Snelheid_plot,3,1) -> 300
B16: Rillengte | C16: =VLOOKUP($C$1,FEFCO_plot,6,0) -> 4 | D16: =VLOOKUP($C$1,FEFCO_plot,7,0) -> 4 | E16: =VLOOKUP($C$1,FEFCO_plot,8,0) -> 4 | F16: =C16*C2+D16*C3+E16*C4 -> 2600 | G16: =VLOOKUP(C11,Snelheid_plot,2,1) -> 700 | N16: Rillengte | O16: =VLOOKUP($C$1,FEFCO_plot,6,0) -> 4 | P16: =VLOOKUP($C$1,FEFCO_plot,7,0) -> 4 | Q16: =VLOOKUP($C$1,FEFCO_plot,8,0) -> 4 | R16: =O16*O2+P16*O3+Q16*O4 -> 2600 | S16: =VLOOKUP(O11,Snelheid_plot,2,1) -> 700 | X16: Rillengte | Y16: =VLOOKUP($C$1,FEFCO_plot,6,0) -> 4 | Z16: =VLOOKUP($C$1,FEFCO_plot,7,0) -> 4 | AA16: =VLOOKUP($C$1,FEFCO_plot,8,0) -> 4 | AB16: =Y16*Y2+Z16*Y3+AA16*Y4 -> 2600 | AC16: =VLOOKUP(Y11,Snelheid_plot,2,1) -> 700 | AH16: Rillengte | AI16: =VLOOKUP($C$1,FEFCO_plot,6,0) -> 4 | AJ16: =VLOOKUP($C$1,FEFCO_plot,7,0) -> 4 | AK16: =VLOOKUP($C$1,FEFCO_plot,8,0) -> 4 | AL16: =AI16*AI2+AJ16*AI3+AK16*AI4 -> 2600 | AM16: =VLOOKUP(AI11,Snelheid_plot,2,1) -> 700
B18: Seconden per verpakking | D18: =F15/G15+F16/G16 -> 18.380952 | N18: Seconden per verpakking | P18: =R15/S15+R16/S16 -> 18.380952 | X18: Seconden per verpakking | Z18: =AB15/AC15+AB16/AC16 -> 18.380952 | AH18: Seconden per verpakking | AJ18: =AL15/AM15+AL16/AM16 -> 18.380952
B19: Uurtarief | D19: =Plot!C64 -> 65 | N19: Uurtarief | P19: =Plot!$C$64 -> 65 | X19: Uurtarief | Z19: =Plot!$C$64 -> 65 | AH19: Uurtarief | AJ19: =Plot!$C$64 -> 65
B20: Secondetarief | D20: =D19/3600 -> 0.018055556 | N20: Secondetarief | P20: =P19/3600 -> 0.018055556 | X20: Secondetarief | Z20: =Z19/3600 -> 0.018055556 | AH20: Secondetarief | AJ20: =AJ19/3600 -> 0.018055556
B21: Machinetarief | D21: =D20*D18 -> 0.33187831 | N21: Machinetarief | P21: =P20*P18 -> 0.33187831 | X21: Machinetarief | Z21: =Z20*Z18 -> 0.33187831 | AH21: Machinetarief | AJ21: =AJ20*AJ18 -> 0.33187831
B23: Formaat plaat | D23: 3000 | E23: 2200 | N23: Formaat plaat | P23: =$D$23 -> 3000 | Q23: =$E$23 -> 2200 | X23: Formaat plaat | Z23: =$D$23 -> 3000 | AA23: =$E$23 -> 2200 | AH23: Formaat plaat | AJ23: =$D$23 -> 3000 | AK23: =$E$23 -> 2200
B24: Aantal lengte | D24: =D23/G10 -> 2.6929982 | N24: Aantal lengte | P24: =P23/S10 -> 2.6929982 | X24: Aantal lengte | Z24: =Z23/AC10 -> 2.6929982 | AH24: Aantal lengte | AJ24: =AJ23/AM10 -> 2.6929982
B25: Aantal breedte | E25: =E23/G9 -> 6.0941828 | N25: Aantal breedte | Q25: =Q23/S9 -> 6.0941828 | X25: Aantal breedte | AA25: =AA23/AC9 -> 6.0941828 | AH25: Aantal breedte | AK25: =AK23/AM9 -> 6.0941828
B27: Aantal per moederplaat | D27: =INT(D24) -> 2 | E27: =INT(E25) -> 6 | F27: =E27*D27 -> 12 | N27: Aantal per moederplaat | P27: =INT(P24) -> 2 | Q27: =INT(Q25) -> 6 | R27: =Q27*P27 -> 12 | X27: Aantal per moederplaat | Z27: =INT(Z24) -> 2 | AA27: =INT(AA25) -> 6 | AB27: =AA27*Z27 -> 12 | AH27: Aantal per moederplaat | AJ27: =INT(AJ24) -> 2 | AK27: =INT(AK25) -> 6 | AL27: =AK27*AJ27 -> 12
B29: Prijs per moederplaat | D29: =VLOOKUP(C5,B100:E130,4,0) -> 0.50976 | E29: m2 | F29: =D23*E23/1000000*D29 -> 3.364416 | N29: Prijs per moederplaat | P29: =VLOOKUP(C5,B100:E130,4,0) -> 0.50976 | Q29: m2 | R29: =P23*Q23/1000000*P29 -> 3.364416 | X29: Prijs per moederplaat | Z29: =VLOOKUP(C5,B100:E130,4,0) -> 0.50976 | AA29: m2 | AB29: =Z23*AA23/1000000*Z29 -> 3.364416 | AH29: Prijs per moederplaat | AJ29: =VLOOKUP(C5,B100:E130,4,0) -> 0.50976 | AK29: m2 | AL29: =AJ23*AK23/1000000*AJ29 -> 3.364416
D31: Voorraad | E31: Op maat | P31: Voorraad | Q31: Op maat | Z31: Voorraad | AA31: Op maat | AJ31: Voorraad | AK31: Op maat
B32: Materiaal per product | D32: =F29/F27 -> 0.280368 | E32: =C11*D29 -> 0.20500202 | N32: Materiaal per product | P32: =R29/R27 -> 0.280368 | Q32: =O11*P29 -> 0.20500202 | X32: Materiaal per product | Z32: =AB29/AB27 -> 0.280368 | AA32: =Y11*Z29 -> 0.20500202 | AH32: Materiaal per product | AJ32: =AL29/AL27 -> 0.280368 | AK32: =AI11*AJ29 -> 0.20500202
B33: Materiaalprijs | D33: =IF(AND(C12>300, C6>=250), E32, D32) -> 0.280368 | N33: Materiaalprijs | P33: =IF(AND(O12>300, O6>=250), Q32, P32) -> 0.20500202 | X33: Materiaalprijs | Z33: =IF(AND(Y12>300, Y6>=250), AA32, Z32) -> 0.20500202 | AH33: Materiaalprijs | AJ33: =IF(AND(AI12>300, AI6>=250), AK32, AJ32) -> 0.280368
B34: Pallethoogte | D34: 2100 | N34: Pallethoogte | P34: 2100 | X34: Pallethoogte | Z34: 2100 | AH34: Pallethoogte | AJ34: 2100
B35: Product lijmen/tapen | D35: =VLOOKUP(C1,FEFCO_plot,2,0) -> Ja | N35: Product lijmen/tapen | P35: =VLOOKUP(O1,FEFCO_plot,2,0) -> Ja | X35: Product lijmen/tapen | Z35: =VLOOKUP(Y1,FEFCO_plot,2,0) -> Ja | AH35: Product lijmen/tapen | AJ35: =VLOOKUP(AI1,FEFCO_plot,2,0) -> Ja
B36: Kosten lijmen/tapen vast | D36: =IF(D35="Nee",0,E36) -> 0.27333333 | E36: {=IF(COUNTIF(Tape_aantal_plot,">="&C6)>0, VLOOKUP(C6,Tapen_plot,2,TRUE) + (C6 - VLOOKUP(C6,Tape_aantal_plot,1,TRUE)) * (INDEX(Tape_prijs_plot, MATCH(TRUE, Tape_aantal_plot > C6, 0)) - VLOOKUP(C6,Tapen_plot,2,TRUE)) / (INDEX(Tape_aantal_plot, MATCH(TRUE, Tape_aantal_plot > C6, 0)) - VLOOKUP(C6,Tape_aantal_plot,1,TRUE)), VLOOKUP(C6,Tapen_plot,2,TRUE) )} -> 0.27333333 | N36: Kosten lijmen/tapen vast | P36: =IF(P35="Nee",0,Q36) -> 0.26 | Q36: {=IF(COUNTIF(Tape_aantal_plot,">="&O6)>0, VLOOKUP(O6,Tapen_plot,2,TRUE) + (O6 - VLOOKUP(O6,Tape_aantal_plot,1,TRUE)) * (INDEX(Tape_prijs_plot, MATCH(TRUE, Tape_aantal_plot > O6, 0)) - VLOOKUP(O6,Tapen_plot,2,TRUE)) / (INDEX(Tape_aantal_plot, MATCH(TRUE, Tape_aantal_plot > O6, 0)) - VLOOKUP(O6,Tape_aantal_plot,1,TRUE)), VLOOKUP(O6,Tapen_plot,2,TRUE) )} -> 0.26 | X36: Kosten lijmen/tapen vast | Z36: =IF(Z35="Nee",0,AA36) -> 0.26 | AA36: {=IF(COUNTIF(Tape_aantal_plot,">="&Y6)>0, VLOOKUP(Y6,Tapen_plot,2,TRUE) + (Y6 - VLOOKUP(Y6,Tape_aantal_plot,1,TRUE)) * (INDEX(Tape_prijs_plot, MATCH(TRUE, Tape_aantal_plot > Y6, 0)) - VLOOKUP(Y6,Tapen_plot,2,TRUE)) / (INDEX(Tape_aantal_plot, MATCH(TRUE, Tape_aantal_plot > Y6, 0)) - VLOOKUP(Y6,Tape_aantal_plot,1,TRUE)), VLOOKUP(Y6,Tapen_plot,2,TRUE) )} -> 0.26 | AH36: Kosten lijmen/tapen vast | AJ36: =IF(AJ35="Nee",0,AK36) -> 0.26133333 | AK36: {=IF(COUNTIF(Tape_aantal_plot,">="&AI6)>0, VLOOKUP(AI6,Tapen_plot,2,TRUE) + (AI6 - VLOOKUP(AI6,Tape_aantal_plot,1,TRUE)) * (INDEX(Tape_prijs_plot, MATCH(TRUE, Tape_aantal_plot > AI6, 0)) - VLOOKUP(AI6,Tapen_plot,2,TRUE)) / (INDEX(Tape_aantal_plot, MATCH(TRUE, Tape_aantal_plot > AI6, 0)) - VLOOKUP(AI6,Tape_aantal_plot,1,TRUE)), VLOOKUP(AI6,Tapen_plot,2,TRUE) )} -> 0.26133333
B37: Kosten lijmen/tapen variabel | D37: =IF(D35="Ja",C4*Plot!C67,0) -> 0.026 | N37: Kosten lijmen/tapen variabel | P37: =IF(P35="Ja",O4*Plot!C67,0) -> 0.026 | X37: Kosten lijmen/tapen variabel | Z37: =IF(Z35="Ja",Y4*Plot!C67,0) -> 0.026 | AH37: Kosten lijmen/tapen variabel | AJ37: =IF(AJ35="Ja",AI4*Plot!C67,0) -> 0.026
B39: Aantal per pallet | D39: =Input!B31 -> 1800 | N39: Aantal per pallet | P39: =D39 -> 1800 | X39: Aantal per pallet | Z39: =P39 -> 1800 | AH39: Aantal per pallet | AJ39: =Z39 -> 1800
B42: M2 prijs transport | D42: =Plot!C63 -> 50 | N42: M2 prijs transport | P42: =Plot!$C$63 -> 50 | X42: M2 prijs transport | Z42: =Plot!$C$63 -> 50 | AH42: M2 prijs transport | AJ42: =Plot!$C$63 -> 50
B43: Aantal m2 transport | D43: =('Pallet en transport'!D151*'Pallet en transport'!E151)/1000000 -> 1.2996 | N43: Aantal m2 transport | P43: =D43 -> 1.2996 | X43: Aantal m2 transport | Z43: =P43 -> 1.2996 | AH43: Aantal m2 transport | AJ43: =Z43 -> 1.2996
B44: Transport per stuk | D44: =IF(D45=0, 'Pallet en transport'!E196*E44, C68/C6) -> 0.19771723 | E44: 1.05 | N44: Transport per stuk | P44: =IF(P45=0, 'Pallet en transport (2)'!E196*Q44, C68/O6) -> 0.043937163 | Q44: =E44 -> 1.05 | X44: Transport per stuk | Z44: =IF(Z45=0, 'Pallet en transport (3)'!E196*AA44, C68/Y6) -> 0.043937163 | AA44: =Q44 -> 1.05 | AH44: Transport per stuk | AJ44: =IF(AJ45=0, 'Pallet en transport (4)'!E196*AK44, C68/AI6) -> 0.16140182 | AK44: =AA44 -> 1.05
B45: Pakketpost | D45: =I162 -> 0 | N45: Pakketpost | P45: =K162 -> 0 | X45: Pakketpost | Z45: =M162 -> 0 | AH45: Pakketpost | AJ45: =O162 -> 0
B46: Orderkosten | D46: =Plot!C66 -> 0 | N46: Orderkosten | P46: =Plot!$C$66 -> 0 | X46: Orderkosten | Z46: =Plot!$C$66 -> 0 | AH46: Orderkosten | AJ46: =Plot!$C$66 -> 0
B48: Totaalprijs | N48: Totaalprijs | X48: Totaalprijs | AH48: Totaalprijs
B49: Uitbreken | D49: =Plot!C65 -> 0.1 | N49: Uitbreken | P49: =Plot!$C$65 -> 0.1 | X49: Uitbreken | Z49: =Plot!$C$65 -> 0.1 | AH49: Uitbreken | AJ49: =Plot!$C$65 -> 0.1
B50: Machine | D50: =D21 -> 0.33187831 | N50: Machine | P50: =P21 -> 0.33187831 | X50: Machine | Z50: =Z21 -> 0.33187831 | AH50: Machine | AJ50: =AJ21 -> 0.33187831
B51: Lijmen/tapen | D51: =D37+D36 -> 0.29933333 | N51: Lijmen/tapen | P51: =P37+P36 -> 0.286 | X51: Lijmen/tapen | Z51: =Z37+Z36 -> 0.286 | AH51: Lijmen/tapen | AJ51: =AJ37+AJ36 -> 0.28733333
...

Sheet Input
A2: Kwaliteitscode | B2: =BLO!B6 -> 10010 | I2: To do:
A3: Golf | B3: ='Kwaliteit conversie'!B4 -> B | I3: Palletaantallen alsof het een Emba doos is. Check of het een Emba doos is.
A4: Kwaliteit | B4: ='Kwaliteit conversie'!C4 -> Wit extra sterk | I4: Kleine stansdozen gaan snel naar 2 uit een plaat. Verschil met verkoopprijsmodel in berekening.
A6: Fefco | B6: =BLO!B2 -> 0201
A7: Lengte | B7: =BLO!B3 -> 300 | C7: mm
A8: Breedte | B8: =BLO!B4 -> 250 | C8: mm
A9: Hoogte | B9: =BLO!B5 -> 100 | C9: mm
A11: Aantal kleuren | B11: =BLO!B12 -> onbedrukt
A12: Bedrukkingspercentage | B12: Onbedrukt / minder dan 10%
A13: Handgrepen | B13: =BLO!B8 -> geen handgrepen / stansbewerking
A14: Extra rillen | B14: Nee
A15: Pallethoogte (max. 2100 mm), niet verplicht vullen. | C15: mm
A17: Aantal | B17: =BLO!B9 -> 400 | C17: Stuks | I17: Alleen voor prijsvergelijking, niet gebruiken (wordt later weer verwijderd):
I18: Materiaal | L18: =Rekenblad!E1081 -> 0.24320434
I19: Totale productiekosten | L19: =Rekenblad!E1083 -> 0.175 | M19: =L19+L20 -> 0.185 | N19: Totaal productie
I20: Overige kosten (inkt/ tape/pallets) | L20: =Rekenblad!E1082 -> 0.01
A21: Minimale afname | C21: =IF(Rekenblad!I445=0," ",CEILING(Rekenblad!I445,10)) -> 490 | D21: Stuks | I21: Orderkosten | L21: =Rekenblad!E1084 -> 0.05
I22: Transport | L22: =Rekenblad!E1091 -> 0.18830213
A23: Prijs per stuk, bij afname | B23: =Rekenblad!C1094 -> 0.72166405 | C23: =B17 -> 400 | D23: stuks
I24: Totaal marge (marge + variatie inkoop) | L24: =Rekenblad!E1089 -> 0.055157585
I26: Kosten per verpakking | L26: =Rekenblad!E1093 -> 0.72166405
A27: Palletstapeling indicatief:
A28: Formaat colli | B28: =IF(Rekenblad!AV46=1,'Pallet en transport'!D151& " x "&'Pallet en transport'!E151," ") -> 1083 x 1200 | C28: mm
A29: Aantal per bundel | B29: =IF(Rekenblad!AV46=1,IF('Pallet en transport'!D165=0,0,'Pallet en transport'!D166)," ") -> 25 | C29: stuks
A30: Aantal stapels per colli | B30: =IF(Rekenblad!AV46=1,'Pallet en transport'!D170," ") -> 6 | C30: stuks | I30: Hoofdbewerking gekozen:
A31: Aantal per colli | B31: =IF(Rekenblad!AV46=1,'Pallet en transport'!D171," ") -> 1800 | C31: stuks | I31: =Rekenblad!C362 -> 0 | J31: =Rekenblad!D362 -> 0 | K31: =Rekenblad!E362 -> 1 | L31: =Rekenblad!F362 -> 0 | M31: =Rekenblad!G362 -> 0 | N31: =Rekenblad!H362 -> 0 | O31: =Rekenblad!I362 -> 0
A32: Hoogte bij benadering | B32: =IF(Rekenblad!AV46=1,'Pallet en transport'!D160," ") -> 1950 | C32: mm | I32: Mini | J32: Maxi | K32: Emba 170 | L32: Emba 295 | M32: Vlakstans | N32: Roda | O32: Plaat op maat
A33: Aantal colli | B33: =IF(Rekenblad!AV46=1,'Pallet en transport'!D174," ") -> 1 | C33: stuks

Sheet Rekenblad
B2: Fefco geselecteerd | C2: =Input!B6 -> 0201
B3: Aantal | C3: =Input!B17 -> 400
B4: Golfsoort | C4: ='Kwaliteit conversie'!B4 -> B
B6: Lengte | C6: =Input!B7 -> 300
B7: breedte | C7: =Input!B8 -> 250
B8: hoogte | C8: =Input!B9 -> 100
B9: Formaat mogelijk | C9: =IF(SUM(D1072:D1074)=3,1,0) -> 1
B10: L >= B akkoord | C10: =IF(AND(E1071=1,C6>=C7),1,IF(E1071=0,1,0)) -> 1
B12: Toeslag materiaal | C12: =E145 -> 2
B13: Dikte | C13: =F145 -> 3
B14: Bedrukking | C14: =Input!B11 -> onbedrukt
B15: Percentage bedrukking | C15: =Input!B12 -> Onbedrukt / minder dan 10%
B16: Stansbewerking | C16: =Input!B13 -> geen handgrepen / stansbewerking
B17: Pallethoogte | C17: =IF(AND(Input!B15>0,Input!B15<2100),Input!B15,2100) -> 2100 | D17: mm
B19: Minimale breedte F02.. op basis van lengte:
B20: =IF(AND($C$6>B21,$C$6<=B22),1,0) -> 0 | C20: =IF(AND($C$6>C21,$C$6<=C22),1,0) -> 0 | D20: =IF(AND($C$6>D21,$C$6<=D22),1,0) -> 1 | E20: =IF(AND($C$6>E21,$C$6<=E22),1,0) -> 0 | F20: =IF(AND($C$6>F21,$C$6<=F22),1,0) -> 0 | G20: =IF(AND($C$6>G21,$C$6<=G22),1,0) -> 0 | H20: =IF(AND($C$6>H21,$C$6<=H22),1,0) -> 0 | I20: =IF(AND($C$6>I21,$C$6<=I22),1,0) -> 0 | ... L20: =IF(AND($C$6>L21,$C$6<=L22),1,0) -> 0
B21: 0 | C21: 200 | D21: 250 | E21: 300 | F21: 350 | G21: 400 | H21: 500 | I21: 600 | J21: 750 | K21: 1000 | L21: 1250
B22: 200 | C22: 250 | D22: 300 | E22: 350 | F22: 400 | G22: 500 | H22: 600 | I22: 750 | J22: 1000 | K22: 1250 | L22: 99999
A23: Stotende klep | B23: 60 | C23: 65 | D23: 70 | E23: 75 | F23: 80 | G23: 85 | H23: 90 | I23: 95 | J23: 100 | K23: 105 | L23: 110 | M23: =HLOOKUP(1,B20:L24,4,FALSE) -> 70
A24: Overslaande klep | B24: 40 | C24: 40 | D24: 40 | E24: 40 | F24: 40 | G24: 40 | H24: 40 | I24: 40 | J24: 50 | K24: 50 | L24: 60 | M24: =HLOOKUP(1,B20:L24,5,FALSE) -> 40
B26: Lengte / hoogte verhouding:
C27: Lengte tussen | E27: Hoogte minimaal
B28: =IF(AND($C$6>C28,$C$6<=D28),1,0) -> 1 | C28: 0 | D28: 400 | E28: 37
B29: =IF(AND($C$6>C29,$C$6<=D29),1,0) -> 0 | C29: 400 | D29: 450 | E29: 40
B30: =IF(AND($C$6>C30,$C$6<=D30),1,0) -> 0 | C30: 450 | D30: 500 | E30: 43
B31: =IF(AND($C$6>C31,$C$6<=D31),1,0) -> 0 | C31: 500 | D31: 550 | E31: 47
B32: =IF(AND($C$6>C32,$C$6<=D32),1,0) -> 0 | C32: 550 | D32: 600 | E32: 50
B33: =IF(AND($C$6>C33,$C$6<=D33),1,0) -> 0 | C33: 600 | D33: 650 | E33: 54
B34: =IF(AND($C$6>C34,$C$6<=D34),1,0) -> 0 | C34: 650 | D34: 700 | E34: 57
B35: =IF(AND($C$6>C35,$C$6<=D35),1,0) -> 0 | C35: 700 | D35: 850 | E35: 60
B36: =IF(AND($C$6>C36,$C$6<=D36),1,0) -> 0 | C36: 850 | D36: 1000 | E36: 70
B37: =IF(AND($C$6>C37,$C$6<=D37),1,0) -> 0 | C37: 1000 | D37: 1200 | E37: 80
B38: =IF(AND($C$6>C38,$C$6<=D38),1,0) -> 0 | C38: 1200 | D38: 2000 | E38: 95
B39: =IF(AND($C$6>C39,$C$6<=D39),1,0) -> 0 | C39: 2000 | D39: 9999 | E39: 110
B41: Minimale hoogte | E41: =VLOOKUP(1,B28:E39,4,FALSE) -> 37
AG44: Beveiliging | AO44: Beveiliging
B45: 2 | C45: 3 | D45: 4 | E45: 5 | F45: 6 | G45: 7 | H45: 8 | I45: 9 | J45: 10 | K45: 11 | L45: 12 | M45: 13 | N45: 14 | O45: 15 | P45: 16 | Q45: 17 | R45: 18 | S45: 19 | T45: 20 | U45: 21 | V45: 22 | W45: 23 | X45: 24 | Y45: 25 | Z45: 26 | AA45: 27 | AB45: 28 | AC45: 29 | AD45: 30 | AE45: 31 | AF45: 32 | AG45: 33 | AH45: 34 | AI45: 35 | AJ45: 36 | AK45: 37 | AL45: 38 | AM45: 39 | AN45: 40 | AO45: 41 | AP45: 42 | AQ45: 43 | AR45: 44 | AS45: 45 | AT45: 46 | AU45: 47 | AV45: 48 | AW45: 49 | AX45: 50 | AY45: 51 | AZ45: 52
C46: =C6 -> 300 | D46: =C7 -> 250 | E46: =C8 -> 100 | F46: =C13 -> 3 | I46: =C12 -> 2 | K46: =C6 -> 300 | L46: =C7 -> 250 | M46: =C8 -> 100 | N46: =C13 -> 3 | Q46: =C12 -> 2 | T46: =VLOOKUP(1,50:70,T45,FALSE) -> 1 | U46: =VLOOKUP(1,50:70,U45,FALSE) -> 1 | V46: =VLOOKUP(1,50:70,V45,FALSE) -> 0 | W46: =VLOOKUP(1,50:70,W45,FALSE) -> 0 | X46: =VLOOKUP(1,50:70,X45,FALSE) -> 0 | AA46: =VLOOKUP(1,50:70,AA45,FALSE) -> 1 | AB46: =VLOOKUP(1,50:70,AB45,FALSE) -> 1 | AC46: =VLOOKUP(1,50:70,AC45,FALSE) -> 0 | AD46: =VLOOKUP(1,50:70,AD45,FALSE) -> 127 | AE46: =VLOOKUP(1,50:70,AE45,FALSE) -> 127 | AF46: =VLOOKUP(1,50:70,AF45,FALSE) -> 107 | AG46: =VLOOKUP(1,50:70,AG45,FALSE) -> 100 | AH46: =VLOOKUP(1,50:70,AH45,FALSE) -> 2000 | ... AZ46: =VLOOKUP(1,50:70,AZ45,FALSE) -> 1
C47: Breedte plaat | K47: Lengte plaat | S47: Bewerkingen | T47: Machinegroep mogelijk | AA47: Sluiting | AB47: Lijmlip | AC47: Zijafval mini | AD47: Slitmaten | AF47: Ongeslit Emba | AG47: Lengte | AI47: Breedte | AK47: Hoogte | AM47: Lengte > Breedte | AN47: Max. boven elkaar | AO47: H < L | AP47: L > 2xB | AQ47: Handgreep | AR47: Stapel/bundel | AS47: Factoren | AT47: Stanssuport | AU47: Extra marge | AX47: H min 10% van L
B48: Fefco | C48: Lengte | D48: Breedte | E48: Hoogte | F48: Wanddikte | G48: Extra | H48: Extra waarde | I48: Toeslag | J48: Totaal (golfrichting) | K48: Lengte | L48: Breedte | M48: Hoogte | N48: Wanddikte | O48: Extra | P48: Extra waarde | Q48: Toeslag | R48: Totaal (lengte) | T48: Boxmaker | U48: Emba | V48: Stans | W48: Roda | X48: Plaat op maat | Y48: m2 / st | Z48: m2 tot | AA48: Nodig | AB48: Nodig | AC48: Nodig | AD48: Onder | AE48: Boven | AG48: minimaal | AH48: maximaal | AI48: Minimaal | AJ48: Maximaal | AK48: Minimaal | AL48: Maximaal | AM48: verplicht | AN48: Mini | AQ48: Mogelijk | AR48: Berekenen | AS48: Emba | AT48: Boxmaker | AU48: Fefco | AV48: Pallet berekenen | AW48: Afval boxm / product | AY48: Efficientie/ fefco | AZ48: Bedrukking mogelijk
...

Sheet Kwaliteit conversie
B4: =VLOOKUP(BLO!B6,$A$5:$D$70,2,0) -> B | C4: =VLOOKUP(BLO!B6,$A$5:$D$70,3,0) -> Wit extra sterk | D4: =VLOOKUP(BLO!B6,$A$5:$D$70,4,0) -> BKT14WS | G4: Keuze | H4: =IF(H5=Input!$B$3,1,0) -> 0 | I4: =IF(I5=Input!$B$3,1,0) -> 1 | J4: =IF(J5=Input!$B$3,1,0) -> 0 | K4: =IF(K5=Input!$B$3,1,0) -> 0 | L4: =IF(L5=Input!$B$3,1,0) -> 0 | M4: =IF(M5=Input!$B$3,1,0) -> 0 | N4: =IF(N5=Input!$B$3,1,0) -> 0 | O4: =IF(O5=Input!$B$3,1,0) -> 0 | P4: =IF(P5=Input!$B$3,1,0) -> 0
A5: Selectie | B5: Golf | C5: Naam | D5: Code | H5: E | I5: B | J5: C | K5: EE | L5: EB | M5: BE | N5: BC | O5: AC | P5: AAC
A6: 10095 | B6: E | C6: Bruin budget | D6: ET12 | F6: 3 | G6: =HLOOKUP(1,$H$4:$Q$24,F6,FALSE) -> Bruin budget | H6: Bruin budget | I6: Bruin budget | J6: Bruin budget | K6: Bruin standaard | L6: Bruin budget | M6: Bruin budget | N6: Bruin budget | O6: Bruin standaard | P6: Bruin budget
A7: 10097 | B7: E | C7: Bruin standaard | D7: ET13/12 | F7: 4 | G7: =HLOOKUP(1,$H$4:$Q$24,F7,FALSE) -> Bruin standaard | H7: Bruin standaard | I7: Bruin standaard | J7: Bruin standaard | K7: =" " | L7: Bruin standaard | M7: Bruin standaard | N7: Bruin standaard | O7: Bruin extra sterk | P7: Bruin standaard
A8: 10134 | B8: E | C8: Bruin extra sterk | D8: EK13 | F8: 5 | G8: =HLOOKUP(1,$H$4:$Q$24,F8,FALSE) -> bruin extra sterk | H8: bruin extra sterk | I8: bruin extra sterk | J8: bruin extra sterk | K8: =" " | L8: Wit budget | M8: Wit standaard | N8: bruin extra sterk | O8: =" " | P8: bruin extra sterk
A9: 10099 | B9: E | C9: Wit standaard | D9: ETWT14 | F9: 6 | G9: =HLOOKUP(1,$H$4:$Q$24,F9,FALSE) -> Wit standaard | H9: Wit standaard | I9: Wit standaard | J9: Wit standaard | K9: =" " | L9: Wit standaard | M9: =" " | N9: Wit standaard | O9: =" " | P9: =" "
A10: 10131 | B10: E | C10: Wit extra sterk | D10: ETWT14 W2 | F10: 7 | G10: =HLOOKUP(1,$H$4:$Q$24,F10,FALSE) -> Wit extra sterk | H10: Wit extra sterk | I10: Wit extra sterk | J10: =" " | K10: =" " | L10: =" " | M10: =" " | N10: =" " | O10: =" " | P10: =" "
A11: 10326 | B11: B | C11: Bruin budget | D11: BT13 | F11: 8 | G11: =HLOOKUP(1,$H$4:$Q$24,F11,FALSE) | H11: =" " | I11: =" " | J11: =" " | K11: =" " | L11: =" " | M11: =" " | N11: =" " | O11: =" " | P11: =" "
A12: 10005 | B12: B | C12: Bruin standaard | D12: BKT14 | F12: 9 | G12: =HLOOKUP(1,$H$4:$Q$24,F12,FALSE) | H12: =" " | I12: =" " | J12: =" " | K12: =" " | L12: =" " | M12: =" " | N12: =" " | O12: =" " | P12: =" "
A13: 10017 | B13: B | C13: bruin extra sterk | D13: BKT19 | F13: 10 | G13: =HLOOKUP(1,$H$4:$Q$24,F13,FALSE) | H13: =" " | I13: =" " | J13: =" " | K13: =" " | L13: =" " | M13: =" " | N13: =" " | O13: =" " | P13: =" "
A14: 10002 | B14: B | C14: Wit standaard | D14: BDUWT14 | F14: 11 | G14: =HLOOKUP(1,$H$4:$Q$24,F14,FALSE) | H14: =" " | I14: =" " | J14: =" " | K14: =" " | L14: =" " | M14: =" " | N14: =" " | O14: =" " | P14: =" "
A15: 10010 | B15: B | C15: Wit extra sterk | D15: BKT14WS | F15: 12 | G15: =HLOOKUP(1,$H$4:$Q$24,F15,FALSE) | H15: =" " | I15: =" " | J15: =" " | K15: =" " | L15: =" " | M15: =" " | N15: =" " | O15: =" " | P15: =" "
A16: 10053 | B16: C | C16: Bruin budget | D16: CT14 | F16: 13 | G16: =HLOOKUP(1,$H$4:$Q$24,F16,FALSE) | H16: =" " | I16: =" " | J16: =" " | K16: =" " | L16: =" " | M16: =" " | N16: =" " | O16: =" " | P16: =" "
A17: 10193 | B17: C | C17: Bruin standaard | D17: CKT15 W6 | F17: 14 | G17: =HLOOKUP(1,$H$4:$Q$24,F17,FALSE) | H17: =" " | I17: =" " | J17: =" " | K17: =" " | L17: =" " | M17: =" " | N17: =" " | O17: =" " | P17: =" "
A18: 10050 | B18: C | C18: Bruin extra sterk | D18: CKT19 | F18: 15 | G18: =HLOOKUP(1,$H$4:$Q$24,F18,FALSE) | H18: =" " | I18: =" " | J18: =" " | K18: =" " | L18: =" " | M18: =" " | N18: =" " | O18: =" " | P18: =" "
A19: 10221 | B19: C | C19: Wit standaard | D19: CKT14WS | F19: 16 | G19: =HLOOKUP(1,$H$4:$Q$24,F19,FALSE) | H19: =" " | I19: =" " | J19: =" " | K19: =" " | L19: =" " | M19: =" " | N19: =" " | O19: =" " | P19: =" "
A20: 10339 | B20: EE | C20: Bruin standaard | D20: EET13K | F20: 17 | G20: =HLOOKUP(1,$H$4:$Q$24,F20,FALSE) | H20: =" " | I20: =" " | J20: =" " | K20: =" " | L20: =" " | M20: =" " | N20: =" " | O20: =" " | P20: =" "
A21: 10335 | B21: EB | C21: Bruin budget | D21: EBT12 | F21: 18 | G21: =HLOOKUP(1,$H$4:$Q$24,F21,FALSE) | H21: =" " | I21: =" " | J21: =" " | K21: =" " | L21: =" " | M21: =" " | N21: =" " | O21: =" " | P21: =" "
A22: 10368 | B22: EB | C22: Bruin standaard | D22: EBKT15 | F22: 19 | G22: =HLOOKUP(1,$H$4:$Q$24,F22,FALSE) | H22: =" " | I22: =" " | J22: =" " | K22: =" " | L22: =" " | M22: =" " | N22: =" " | O22: =" " | P22: =" "
A23: 10136 | B23: EB | C23: Wit budget | D23: EBT13/10W | F23: 20 | G23: =HLOOKUP(1,$H$4:$Q$24,F23,FALSE) | H23: =" " | I23: =" " | J23: =" " | K23: =" " | L23: =" " | M23: =" " | N23: =" " | O23: =" " | P23: =" "
A24: 10140 | B24: EB | C24: Wit standaard | D24: EBKT13/12W
A25: 10197 | B25: BE | C25: Bruin budget | D25: BET14/12
A26: 10199 | B26: BE | C26: Bruin standaard | D26: BEKT12
A27: 10200 | B27: BE | C27: Wit standaard | D27: BEKT13/12W
A28: 10178 | B28: BC | C28: Bruin budget | D28: DT14 N2
A29: 10158 | B29: BC | C29: Bruin standaard | D29: DKT14 N2
A30: 10183 | B30: BC | C30: bruin extra sterk | D30: DKT19 N2
A31: 10181 | B31: BC | C31: Wit standaard | D31: DKT13/12W N2
A32: 10214 | B32: AC | C32: Bruin standaard | D32: ACK30/30
A33: 10215 | B33: AC | C33: Bruin extra sterk | D33: ACK40
A34: 10216 | B34: AAC | C34: Bruin budget | D34: AACK14
A35: 10218 | B35: AAC | C35: Bruin standaard | D35: AACK30/20
A36: 10220 | B36: AAC | C36: bruin extra sterk | D36: AACKK40/40

Sheet Tarieven
B4: Machine | C4: Geselecteerde prijs
B5: Emba 295 | C5: 550
B6: Emba 170 | C6: 300
B7: Maxi blauw | C7: 190
B8: Mini | C8: 125
B9: Taper (gemiddeld tarief) | C9: 94
B10: Wookil | C10: 150
B11: Roda | C11: 96
B12: Overige | C12: 37
B13: Order kosten | C13: 20
B14: Kosten per pallet | C14: 4
B15: Brandstoftoeslag | C15: 0.195
B16: Tape kosten per meter | C16: 0.0912

Sheet Prijs karton
A1: Prijs Karton | B1: 2 | C1: 3 | D1: 4 | E1: 5 | F1: 6 | G1: 7 | H1: 8 | I1: 9 | J1: 10 | K1: 11 | L1: 12 | M1: 13 | N1: 14 | O1: 15 | P1: 16 | Q1: 17 | R1: 18 | S1: 19 | T1: 20 | U1: 21 | V1: 22 | W1: 23 | X1: 24 | Y1: 25 | Z1: 26 | AA1: 27 | AB1: 28 | AC1: 29
N3: Voorwaarde Pro | T3: Voorwaarde Kappa
C4: Gebruik: | M4: 1 | N4: Plaatlengte korter dan | O4: 600 | P4: 4 | Q4: extra per HQM | S4: 1 | T4: Plaatlengte korter dan | U4: 600 | V4: 4 | W4: extra per HQM
C5: Alle gele cellen vullen door deze te copieren uit verkoopprijsmodel. Altijd plakken "waarde" gebruiken | M5: 2 | N5: Plaatlengte korter dan | O5: 700 | P5: 2 | Q5: extra per HQM | S5: 2 | T5: Plaatlengte korter dan | U5: 750 | V5: 2 | W5: extra per HQM
C6: Cellen kunnen t/m "ECT" in een keer worden gecopieerd. Daarna rij voor rij bekijken. | M6: 3 | N6: Plaatlengte lager dan | O6: 5000 | P6: =VLOOKUP("X",19:254,29,FALSE) -> 0 | Q6: extra per HQM | S6: 3 | T6: Plaatlengte langer dan | U6: 5000 | V6: 5 | W6: extra per HQM
M7: 4 | N7: =" " | O7: =" " | P7: =" " | Q7: =" " | S7: 4 | T7: =" " | U7: =" " | V7: =" " | W7: =" "
M8: 5 | N8: =" " | O8: =" " | P8: =" " | Q8: =" " | S8: 5 | T8: =" "
M9: 6 | N9: =" " | O9: =" " | P9: =" " | Q9: =" " | S9: 6
M10: 7 | N10: =" " | O10: =" " | P10: =" " | Q10: =" " | S10: 7
M11: 8 | N11: =" " | O11: =" " | P11: =" " | Q11: =" " | S11: 8
M12: 9 | N12: =" " | O12: =" " | P12: =" " | Q12: =" " | S12: 9
M13: 10 | N13: =" " | O13: =" " | P13: =" " | Q13: =" " | S13: 10
B15: 2 | C15: 3 | D15: 4 | E15: 5 | F15: 6 | G15: 7 | H15: 8 | I15: 9 | J15: 10 | K15: 11 | L15: 12 | M15: 13 | N15: 14 | O15: 15 | P15: 16 | Q15: 17 | R15: 18 | S15: 19 | T15: 20 | U15: 21 | V15: 22 | W15: 23 | X15: 24 | Y15: 25 | Z15: 26 | AA15: 27 | AB15: 28 | AC15: 29 | AD15: 30 | AE15: 31 | AF15: 32 | AG15: 33 | AH15: 34 | AI15: 35 | AJ15: 36
A16: Keuze | B16: Type golf | C16: Kwaliteitscodering Arifal | D16: kg. per m2 | E16: Dikte (mm) | F16: 0 | G16: 200 | H16: 500 | I16: 1000 | J16: 2000 | K16: 5000 | AC16: Toeslag plaat tussen Pro | AD16: =VLOOKUP("X",19:254,AD15,FALSE) -> 1 | AE16: =VLOOKUP("X",19:254,AE15,FALSE) -> 1 | AF16: =VLOOKUP("X",19:254,AF15,FALSE) -> 1 | AG16: =VLOOKUP("X",19:254,AG15,FALSE) -> 1 | AH16: =VLOOKUP("X",19:254,AH15,FALSE) -> 1 | AI16: =VLOOKUP("X",19:254,AI15,FALSE) -> 1 | AJ16: =VLOOKUP("X",19:254,AJ15,FALSE) -> 1
F17: 200 | G17: 500 | H17: 1000 | I17: 2000 | J17: 5000 | K17: 999999 | T17: LEVERANCIER | AC17: 5000 | AD17: Mini | AE17: Maxi | AF17: Emba 170 | AG17: Emba 295 | AH17: Stans | AI17: Roda | AJ17: Plaat op maat
F18: 0-199 | G18: 200-499 | H18: 500-999 | I18: 1000-1999 | J18: 2000-4999 | K18: >5000 | L18: Code | M18: Buiten | N18: Golf | O18: Tussen | P18: Golf | Q18: Tussen | R18: Golf | S18: Binnen | U18: min plano breedte | V18: max plano breedte | W18: min plano lengte | X18: max plano lengte | Y18: min platen < 550 br | Z18: min platen | AA18: min m2 | AB18: Ect | AC18: 6200 | AD18: mogelijk | AE18: mogelijk | AF18: mogelijk | AG18: mogelijk | AH18: mogelijk | AI18: mogelijk | AJ18: mogelijk
A19: =IF('Kwaliteit conversie'!$D$4='Prijs karton'!C19,"X"," ") | B19: B | C19: BT10 K | D19: 0.351 | E19: 2.84 | F19: 0 | G19: 40.5 | H19: 37.5 | I19: 37.5 | J19: 35.5 | K19: 35.5 | L19: B 70301 | M19: TL 100 | N19: WS 100 | O19: - | P19: - | Q19: - | R19: - | S19: TL 100 | T19: Kappa | U19: 240 | V19: 2450 | W19: 500 | X19: 6000 | Y19: 125 | Z19: 125 | AA19: 200 | AB19: 4.02 | AC19: 0 | AD19: 1 | AE19: 1 | AF19: 1 | AG19: 1 | AH19: 1 | AI19: 1 | AJ19: 1
A20: =IF('Kwaliteit conversie'!$D$4='Prijs karton'!C20,"X"," ") | B20: B | C20: BTS12/11 | D20: 0.305 | E20: 2.7 | F20: 0 | G20: 27.7 | H20: 24.7 | I20: 24.2 | J20: 24.2 | K20: 23.7 | L20: 1.01 B | M20: TL 90 | N20: WS 90 | O20: - | P20: - | Q20: - | R20: - | S20: WS 90 | T20: Pro | U20: 250 | V20: 2450 | W20: 500 | X20: 6200 | Y20: 480 | Z20: 240 | AA20: 200 | AB20: 3 | AC20: 0 | AD20: 1 | AE20: 1 | AF20: 1 | AG20: 1 | AH20: 1 | AI20: 1 | AJ20: 1
A21: =IF('Kwaliteit conversie'!$D$4='Prijs karton'!C21,"X"," ") | B21: B | C21: BT12 | D21: 0.365 | E21: 2.8 | F21: 0 | G21: 31 | H21: 28 | I21: 27.5 | J21: 27.5 | K21: 27 | L21: 1.02 B W1 | M21: TL115 | N21: WS 100 | O21: - | P21: - | Q21: - | R21: - | S21: TL 115 | T21: Pro | U21: 250 | V21: 2450 | W21: 500 | X21: 6200 | Y21: 480 | Z21: 240 | AA21: 200 | AB21: 4 | AC21: 0 | AD21: 1 | AE21: 1 | AF21: 1 | AG21: 1 | AH21: 1 | AI21: 1 | AJ21: 1
A22: =IF('Kwaliteit conversie'!$D$4='Prijs karton'!C22,"X"," ") | B22: B | C22: BT11 | D22: 0.355 | E22: 2.8 | F22: 0 | G22: 28.8 | H22: 25.8 | I22: 25.3 | J22: 25.3 | K22: 24.8 | L22: 1.02 B | M22: TL 115 | N22: WS 90 | O22: - | P22: - | Q22: - | R22: - | S22: TL 115 | T22: Pro | U22: 250 | V22: 2450 | W22: 500 | X22: 6200 | Y22: 480 | Z22: 240 | AA22: 200 | AB22: 3.6 | AC22: 10 | AD22: 1 | AE22: 1 | AF22: 1 | AG22: 1 | AH22: 1 | AI22: 1 | AJ22: 1
A23: =IF('Kwaliteit conversie'!$D$4='Prijs karton'!C23,"X"," ") | B23: B | C23: BT11 K | D23: 0.365 | E23: 2.84 | F23: 0 | G23: 41.1 | H23: 38.1 | I23: 38.1 | J23: 36.1 | K23: 36.1 | L23: B 70303 | M23: TL 110 | N23: WS 100 | O23: - | P23: - | Q23: - | R23: - | S23: TL 110 | T23: Kappa | U23: 240 | V23: 2450 | W23: 500 | X23: 6000 | Y23: 125 | Z23: 125 | AA23: 200 | AB23: 4 | AC23: 0 | AD23: 1 | AE23: 1 | AF23: 1 | AG23: 1 | AH23: 1 | AI23: 1 | AJ23: 1
A24: =IF('Kwaliteit conversie'!$D$4='Prijs karton'!C24,"X"," ") | B24: B
A25: =IF('Kwaliteit conversie'!$D$4='Prijs karton'!C25,"X"," ") | B25: B | C25: BT14 | D25: 0.375 | E25: 2.8 | F25: 0 | G25: 29.8 | H25: 26.8 | I25: 26.3 | J25: 26.3 | K25: 25.8 | L25: 1.03 B | M25: TL 135 | N25: WS 90 | O25: - | P25: - | Q25: - | R25: - | S25: TL 115 | T25: Pro | U25: 250 | V25: 2450 | W25: 500 | X25: 6200 | Y25: 480 | Z25: 240 | AA25: 200 | AB25: 3.9 | AC25: 10 | AD25: 1 | AE25: 1 | AF25: 1 | AG25: 1 | AH25: 1 | AI25: 1 | AJ25: 1
A26: =IF('Kwaliteit conversie'!$D$4='Prijs karton'!C26,"X"," ") | B26: B
A27: =IF('Kwaliteit conversie'!$D$4='Prijs karton'!C27,"X"," ") | B27: B | C27: BT14S K | D27: 0.381 | E27: 2.88 | F27: 0 | G27: 44.9 | H27: 41.9 | I27: 41.9 | J27: 39.9 | K27: 39.9 | L27: B 720 | M27: THP 125 | N27: WS 100 | O27: - | P27: - | Q27: - | R27: - | S27: THP 125 | T27: Kappa | U27: 240 | V27: 2450 | W27: 500 | X27: 6000 | Y27: 125 | Z27: 125 | AA27: 200 | AB27: 4.87 | AC27: 0 | AD27: 1 | AE27: 1 | AF27: 1 | AG27: 1 | AH27: 1 | AI27: 1 | AJ27: 1
A28: =IF('Kwaliteit conversie'!$D$4='Prijs karton'!C28,"X"," ") | B28: B | C28: BT14 N2 | D28: 0.36 | E28: 2.3 | F28: 0 | G28: 29.6 | H28: 26.6 | I28: 26.1 | J28: 26.1 | K28: 25.6 | L28: 1.03 B N2 | M28: TL 135 | N28: WS 80 | O28: - | P28: - | Q28: - | R28: - | S28: TL 115 | T28: Pro | U28: 250 | V28: 2450 | W28: 500 | X28: 6200 | Y28: 480 | Z28: 240 | AA28: 200 | AB28: 4.1 | AC28: 0 | AD28: 1 | AE28: 1 | AF28: 1 | AG28: 1 | AH28: 1 | AI28: 1 | AJ28: 1
A29: =IF('Kwaliteit conversie'!$D$4='Prijs karton'!C29,"X"," ") | B29: B | C29: BT13/14 | D29: 0.43 | E29: 2.8 | F29: 0 | G29: 37.5 | H29: 34.5 | I29: 34 | J29: 34 | K29: 33.5 | L29: 1.03 B W6 | M29: TL 135 | N29: WS 135 | O29: - | P29: - | Q29: - | R29: - | S29: TL 115 | T29: Pro | U29: 250 | V29: 2450 | W29: 500 | X29: 6200 | Y29: 480 | Z29: 240 | AA29: 200 | AB29: 5 | AC29: 0 | AD29: 1 | AE29: 1 | AF29: 1 | AG29: 1 | AH29: 1 | AI29: 1 | AJ29: 1
A30: =IF('Kwaliteit conversie'!$D$4='Prijs karton'!C30,"X"," ") | B30: B | C30: BT14/15 | D30: 0.45 | E30: 2.8 | F30: 0 | G30: 38.5 | H30: 35.5 | I30: 35 | J30: 35 | K30: 34.5 | L30: 1.04 B W6 | M30: TL 135 | N30: WS 135 | O30: - | P30: - | Q30: - | R30: - | S30: TL 135 | T30: Pro | U30: 250 | V30: 2450 | W30: 500 | X30: 6200 | Y30: 480 | Z30: 240 | AA30: 200 | AB30: 5.2 | AC30: 0 | AD30: 1 | AE30: 1 | AF30: 1 | AG30: 1 | AH30: 1 | AI30: 1 | AJ30: 1
A31: =IF('Kwaliteit conversie'!$D$4='Prijs karton'!C31,"X"," ") | B31: B | C31: BDUWT14 | D31: 0.395 | E31: 2.8 | F31: 0 | G31: 39.3 | H31: 36.3 | I31: 35.8 | J31: 35.8 | K31: 35.3 | L31: 1.25 B | M31: TLW 135 | N31: WS 90 | O31: - | P31: - | Q31: - | R31: - | S31: TL 135 | T31: Pro | U31: 250 | V31: 2450 | W31: 500 | X31: 6200 | Y31: 480 | Z31: 240 | AA31: 200 | AB31: 3.9 | AC31: 0 | AD31: 1 | AE31: 1 | AF31: 1 | AG31: 1 | AH31: 1 | AI31: 1 | AJ31: 1
A32: =IF('Kwaliteit conversie'!$D$4='Prijs karton'!C32,"X"," ") | B32: B | C32: BDUWT14 K | D32: 0.391 | E32: 2.85 | F32: 0 | G32: - | H32: 47.3 | I32: 47.3 | J32: 45.3 | K32: 45.3 | L32: B 742 | M32: TLW 135 | N32: WS 100 | O32: - | P32: - | Q32: - | R32: - | S32: THP 125 | T32: Kappa | U32: 240 | V32: 2450 | W32: 500 | X32: 6000 | Y32: 125 | Z32: 125 | AA32: 500 | AB32: 4.55 | AC32: 0 | AD32: 1 | AE32: 1 | AF32: 1 | AG32: 1 | AH32: 1 | AI32: 1 | AJ32: 1
A33: =IF('Kwaliteit conversie'!$D$4='Prijs karton'!C33,"X"," ") | B33: B
A34: =IF('Kwaliteit conversie'!$D$4='Prijs karton'!C34,"X"," ") | B34: B
A35: =IF('Kwaliteit conversie'!$D$4='Prijs karton'!C35,"X"," ") | B35: B | C35: BKT13 | D35: 0.4 | E35: 2.8 | F35: 0 | G35: 38.7 | H35: 35.7 | I35: 35.2 | J35: 35.2 | K35: 34.7 | L35: 1.30 B | M35: PLK 140 | N35: WS 90 | O35: - | P35: - | Q35: - | R35: - | S35: TL 135 | T35: Pro | U35: 250 | V35: 2450 | W35: 500 | X35: 6200 | Y35: 480 | Z35: 240 | AA35: 200 | AB35: 4.6 | AC35: 0 | AD35: 1 | AE35: 1 | AF35: 1 | AG35: 1 | AH35: 1 | AI35: 1 | AJ35: 1
A36: =IF('Kwaliteit conversie'!$D$4='Prijs karton'!C36,"X"," ") | B36: B | C36: BKT13 K | D36: 0.391 | E36: 2.87 | F36: 0 | G36: 50.6 | H36: 47.6 | I36: 47.6 | J36: 45.6 | K36: 45.6 | L36: B 725 | M36: KL 135 | N36: WS 100 | O36: - | P36: - | Q36: - | R36: - | S36: THP 125 | T36: Kappa | U36: 240 | V36: 2450 | W36: 500 | X36: 6000 | Y36: 125 | Z36: 125 | AA36: 200 | AB36: 5.07 | AC36: 0 | AD36: 1 | AE36: 1 | AF36: 1 | AG36: 1 | AH36: 1 | AI36: 1 | AJ36: 1
A37: =IF('Kwaliteit conversie'!$D$4='Prijs karton'!C37,"X"," ") | B37: B
A38: =IF('Kwaliteit conversie'!$D$4='Prijs karton'!C38,"X"," ") | B38: B
A39: =IF('Kwaliteit conversie'!$D$4='Prijs karton'!C39,"X"," ") | B39: B | C39: BT13 | D39: 0.385 | E39: 2.8 | F39: 0 | G39: 33.9 | H39: 30.9 | I39: 30.4 | J39: 30.4 | K39: 29.9 | L39: 1.03 B W1 | M39: TL 135 | N39: WS 100 | O39: - | P39: - | Q39: - | R39: - | S39: TL 115 | T39: Pro | U39: 250 | V39: 2450 | W39: 500 | X39: 6200 | Y39: 480 | Z39: 240 | AA39: 200 | AB39: 4.4 | AC39: 0 | AD39: 1 | AE39: 1 | AF39: 1 | AG39: 1 | AH39: 1 | AI39: 1 | AJ39: 1
A40: =IF('Kwaliteit conversie'!$D$4='Prijs karton'!C40,"X"," ") | B40: B | C40: BKT14 | D40: 0.455 | E40: 2.8 | F40: 0 | G40: 39.4 | H40: 36.4 | I40: 35.9 | J40: 35.9 | K40: 35.4 | L40: 1.30 B W6 | M40: PLK 140 | N40: WS 135 | O40: - | P40: - | Q40: - | R40: - | S40: TL 135 | T40: Pro | U40: 250 | V40: 2450 | W40: 500 | X40: 6200 | Y40: 480 | Z40: 240 | AA40: 200 | AB40: 5.6 | AC40: 10 | AD40: 1 | AE40: 1 | AF40: 1 | AG40: 1 | AH40: 1 | AI40: 1 | AJ40: 1
A41: =IF('Kwaliteit conversie'!$D$4='Prijs karton'!C41,"X"," ") | B41: B | C41: BKT14K | D41: 0.45 | E41: 2.8 | F41: 0 | G41: 44 | H41: 41 | I41: 40.5 | J41: 40.5 | K41: 40 | L41: 1.31 B | M41: KL 135 | N41: WS 135 | O41: - | P41: - | Q41: - | R41: - | S41: TL 135 | T41: Pro | U41: 250 | V41: 2450 | W41: 500 | X41: 6200 | Y41: 480 | Z41: 240 | AA41: 200 | AB41: 5.4 | AC41: 0 | AD41: 1 | AE41: 1 | AF41: 1 | AG41: 1 | AH41: 1 | AI41: 1 | AJ41: 1
A42: =IF('Kwaliteit conversie'!$D$4='Prijs karton'!C42,"X"," ") | B42: B | C42: BT13 N7 | D42: 0.425 | E42: 2.3 | F42: 0 | G42: 36.2 | H42: 33.2 | I42: 32.7 | J42: 32.7 | K42: 32.2 | L42: 1.04 B N7 | M42: TL 135 | N42: WS 115 | O42: - | P42: - | Q42: - | R42: - | S42: TL 135 | T42: Pro | U42: 250 | V42: 2450 | W42: 500 | X42: 6200 | Y42: 480 | Z42: 240 | AA42: 200 | AB42: 5 | AC42: 0 | AD42: 1 | AE42: 1 | AF42: 1 | AG42: 1 | AH42: 1 | AI42: 1 | AJ42: 1
...

Sheet Marge tabel
H1: 0 | J1: 0.01 | K1: Oude instelling
H2: -0.06 | J2: -0.04 | K2: Instelling SD
E3: =IF(OR(Rekenblad!E362=1,Rekenblad!F362=1),1,0) -> 1 | F3: =IF(E3=1,0,1) -> 0
C4: Order bedrag | E4: Marge Emba | F4: Marge Overige | H4: Correctie | I4: Basis | J4: Correctie
C5: tussen | E5: % | F5: % | H5: Marge Emba | I5: marge | J5: Overige
B6: =IF(AND($B$73>C6,$B$73<=D6),1,"") | C6: 1 | D6: 25 | E6: =I6+H6 -> 0.74 | F6: =J6+I6 -> 0.75 | H6: -0.06 | I6: 0.8 | J6: -0.05
B7: =IF(AND($B$73>C7,$B$73<=D7),1,"") | C7: 25 | D7: 50 | E7: =I7+H7 -> 0.34 | F7: =J7+I7 -> 0.35 | H7: -0.06 | I7: 0.4 | J7: -0.05
B8: =IF(AND($B$73>C8,$B$73<=D8),1,"") | C8: 50 | D8: 55 | E8: =I8+H8 -> 0.31 | F8: =J8+I8 -> 0.32 | H8: -0.06 | I8: 0.37 | J8: -0.05
B9: =IF(AND($B$73>C9,$B$73<=D9),1,"") | C9: 55 | D9: 60 | E9: =I9+H9 -> 0.29 | F9: =J9+I9 -> 0.3 | H9: -0.06 | I9: 0.35 | J9: -0.05
B10: =IF(AND($B$73>C10,$B$73<=D10),1,"") | C10: 60 | D10: 65 | E10: =I10+H10 -> 0.23 | F10: =J10+I10 -> 0.24 | H10: -0.06 | I10: 0.29 | J10: -0.05
B11: =IF(AND($B$73>C11,$B$73<=D11),1,"") | C11: 65 | D11: 70 | E11: =I11+H11 -> 0.22 | F11: =J11+I11 -> 0.23 | H11: -0.06 | I11: 0.28 | J11: -0.05
B12: =IF(AND($B$73>C12,$B$73<=D12),1,"") | C12: 70 | D12: 75 | E12: =I12+H12 -> 0.21 | F12: =J12+I12 -> 0.22 | H12: -0.06 | I12: 0.27 | J12: -0.05
B13: =IF(AND($B$73>C13,$B$73<=D13),1,"") | C13: 75 | D13: 80 | E13: =I13+H13 -> 0.2 | F13: =J13+I13 -> 0.21 | H13: -0.06 | I13: 0.26 | J13: -0.05
B14: =IF(AND($B$73>C14,$B$73<=D14),1,"") | C14: 80 | D14: 85 | E14: =I14+H14 -> 0.19 | F14: =J14+I14 -> 0.2 | H14: -0.06 | I14: 0.25 | J14: -0.05
B15: =IF(AND($B$73>C15,$B$73<=D15),1,"") | C15: 85 | D15: 90 | E15: =I15+H15 -> 0.18 | F15: =J15+I15 -> 0.19 | H15: -0.06 | I15: 0.24 | J15: -0.05
B16: =IF(AND($B$73>C16,$B$73<=D16),1,"") | C16: 90 | D16: 95 | E16: =I16+H16 -> 0.17 | F16: =J16+I16 -> 0.18 | H16: -0.06 | I16: 0.23 | J16: -0.05
B17: =IF(AND($B$73>C17,$B$73<=D17),1,"") | C17: 95 | D17: 100 | E17: =I17+H17 -> 0.16 | F17: =J17+I17 -> 0.17 | H17: -0.06 | I17: 0.22 | J17: -0.05
... B65: =IF(AND($B$73>C65,$B$73<=D65),1,"") | C65: 8000 | D65: 1000000 | E65: =I65+H65 -> 0.03 | F65: =J65+I65 -> 0.04 | H65: -0.06 | I65: 0.09 | J65: -0.05
E66: =VLOOKUP(1,B6:F65,4,FALSE) -> 0.095 | F66: =VLOOKUP(1,B6:F65,5,FALSE) -> 0.105
E68: Wellicht nog vullen
D69: 1 | F69: =Rekenblad!J372 -> 0 | G69: =Rekenblad!J373 -> 0 | H69: =H79 -> 0 | I69: =IF(AND(Rekenblad!C2=Rekenblad!B50,Rekenblad!J365=1),1,IF(AND(Rekenblad!C2=Rekenblad!B50,Rekenblad!J369=1),1,0)) -> 0 | J69: =C83 -> 0 | K69: =IF(AND(Rekenblad!F347=1,U93=1,J69=0),1,0) -> 0 | L69: 0 | M69: 0 | N69: 0
B70: Kosten totaal | C70: Basis marge | D70: Extra marge | E70: Extra marge | F70: Extra marge | G70: Extra marge | H70: Kleine doos | I70: Plaatjes | J70: Kokerdozen | K70: Plaatformaat | O70: Totaal
D71: Fefco | E71: Kokerdoos | F71: Stapelen | G71: Bundelen | H71: Emba 170 | I71: Mini / roda | J71: Emba 295 | K71: Emba 295 | O71: Marge
C72: =IF(SUM(B6:B65)>0,HLOOKUP(1,E3:F66,64,FALSE),0) -> 0.095 | D72: =Rekenblad!AU46 -> 0 | E72: 0.03 | F72: 0.03 | G72: 0.03 | H72: 0.1 | I72: 0.08 | J72: =D85*H107 -> 0 | K72: =HLOOKUP(1,Q97:AI100,4,FALSE) -> 0.07
B73: =Rekenblad!C1085 -> 191.28173 | C73: =B73*C72 -> 18.171765 | D73: =IF(D72>0,D72*B73*D69,0) -> 0 | E73: =IF(E72>0,E72*B73*E69,0) -> 0 | F73: =IF(F72>0,F72*B73*F69,0) -> 0 | G73: =IF(G72>0,G72*B73*G69,0) -> 0 | H73: =IF(H72>0,H72*B73*H69,0) -> 0 | I73: =IF(I72>0,I72*B73*I69,0) -> 0 | J73: =IF(J72>0,J72*B73*J69,0) -> 0 | K73: =IF(K72>0,K72*B73*K69,0) -> 0 | L73: =IF(L72>0,L72*B73*L69,0) -> 0 | M73: =IF(M72>0,M72*B73*M69,0) -> 0 | N73: =IF(N72>0,N72*B73*N69,0) -> 0 | O73: =SUM(C73:N73) -> 18.171765
C76: =Rekenblad!B228 -> 361 | D76: =Rekenblad!C228 -> 1150 | E76: 0 | F76: =Rekenblad!C7 -> 250
C77: Plaathoogte < dan | D77: Plaatlengte < dan | E77: Formaat | F77: Breedte < dan | G77: Productie | H77: Klein formaat
C78: 280 | D78: 690 | E78: Klein | F78: 125 | G78: Emba 170 | H78: Emba 170
B79: Kleine doos Emba 170 | C79: =IF(C76<C78,1,0) -> 0 | D79: =IF(D76<D78,1,0) -> 0 | E79: =IF(SUM(C79:D79)=E76,0,1) -> 0 | F79: =IF(F76<F78,1,0) -> 0 | G79: =Rekenblad!J367 -> 1 | H79: =IF(AND(G79=1,SUM(E79:F79)>1),1,0) -> 0
B82: Tabel Kokerdoos Emba 295
B83: Koker / plaat bepalen | C83: =IF(AND(Rekenblad!F347,Rekenblad!AA46=1,SUM(B86:B100)+SUM(E83:N83)=2),1,0) -> 0 | D83: =IF(AND(SUM(B86:B100)=1,SUM(E83:N83)=1),HLOOKUP(1,E83:N101,19,FALSE),0) -> 0 | E83: =IF(AND($C$85>E84,$C$85<=E85),1," ") | F83: =IF(AND($C$85>F84,$C$85<=F85),1," ") | G83: =IF(AND($C$85>G84,$C$85<=G85),1," ") | H83: =IF(AND($C$85>H84,$C$85<=H85),1," ") | I83: =IF(AND($C$85>I84,$C$85<=I85),1," ") | J83: =IF(AND($C$85>J84,$C$85<=J85),1," ") -> 1 | K83: =IF(AND($C$85>K84,$C$85<=K85),1," ") | L83: =IF(AND($C$85>L84,$C$85<=L85),1," ") | ... N83: =IF(AND($C$85>N84,$C$85<=N85),1," ") | Q83: Factor | R83: =HLOOKUP(1,R84:AJ87,4,FALSE) -> 1
B84: Breedte plaat | C84: =Rekenblad!C645 -> 361 | D84: =R83 -> 1 | E84: 0 | F84: 700 | G84: 800 | H84: 900 | I84: 1000 | J84: 1100 | K84: 1200 | L84: 1300 | M84: 1450 | N84: 1600 | Q84: Selecte | R84: =IF(AND($Q$86>=R85,$Q$86<R86),1,0) -> 1 | S84: =IF(AND($Q$86>=S85,$Q$86<S86),1,0) -> 0 | T84: =IF(AND($Q$86>=T85,$Q$86<T86),1,0) -> 0 | U84: =IF(AND($Q$86>=U85,$Q$86<U86),1,0) -> 0 | V84: =IF(AND($Q$86>=V85,$Q$86<V86),1,0) -> 0 | W84: =IF(AND($Q$86>=W85,$Q$86<W86),1,0) -> 0 | X84: =IF(AND($Q$86>=X85,$Q$86<X86),1,0) -> 0 | Y84: =IF(AND($Q$86>=Y85,$Q$86<Y86),1,0) -> 0 | ... AJ84: =IF(AND($Q$86>=AJ85,$Q$86<AJ86),1,0) -> 0
B85: Lengte plaat | C85: =Rekenblad!C646 -> 1150 | D85: =D83*D84 -> 0 | E85: 700 | F85: 800 | G85: 900 | H85: 1000 | I85: 1100 | J85: 1200 | K85: 1300 | L85: 1450 | M85: 1600 | N85: 1700 | Q85: M2 | R85: 0 | S85: 200 | T85: 500 | U85: 750 | V85: 1000 | W85: 1250 | X85: 1500 | Y85: 1750 | Z85: 2000 | AA85: 2250 | AB85: 2500 | AC85: 2750 | AD85: 3000 | AE85: 3500 | AF85: 4000 | AG85: 5000 | AH85: 6000 | AI85: 8000 | AJ85: 10000
B86: =IF(AND($C$84>C86,$C$84<=D86),1," ") -> 1 | C86: 0 | D86: 400 | E86: 0 | F86: 0 | G86: 0 | H86: 0 | I86: 0 | J86: 0 | K86: 0 | L86: 0 | M86: 0 | N86: 0 | Q86: =Rekenblad!I108 -> 160.8616 | R86: 200 | S86: 500 | T86: 750 | U86: 1000 | V86: 1250 | W86: 1500 | X86: 1750 | Y86: 2000 | Z86: 2250 | AA86: 2500 | AB86: 2750 | AC86: 3000 | AD86: 3500 | AE86: 4000 | AF86: 5000 | AG86: 6000 | AH86: 8000 | AI86: 10000 | AJ86: 99999999
B87: =IF(AND($C$84>C87,$C$84<=D87),1," ") | C87: 400 | D87: 450 | E87: 0.03 | F87: 0 | G87: 0 | H87: 0 | I87: 0 | J87: 0 | K87: 0 | L87: 0 | M87: 0 | N87: 0 | Q87: Factor | R87: 1 | S87: 1 | T87: 1 | U87: 1 | V87: 1 | W87: 1 | X87: 1 | Y87: 1 | Z87: 1 | AA87: 1 | AB87: 0.9 | AC87: 0.8 | AD87: 0.7 | AE87: 0.6 | AF87: 0.6 | AG87: 0.6 | AH87: 0.6 | AI87: 0.6 | AJ87: 0.6
B88: =IF(AND($C$84>C88,$C$84<=D88),1," ") | C88: 450 | D88: 500 | E88: 0.05 | F88: 0.03 | G88: 0 | H88: 0 | I88: 0 | J88: 0 | K88: 0 | L88: 0 | M88: 0 | N88: 0
B89: =IF(AND($C$84>C89,$C$84<=D89),1," ") | C89: 500 | D89: 550 | E89: 0.05 | F89: 0.05 | G89: 0.03 | H89: 0.02 | I89: 0.01 | J89: 0 | K89: 0 | L89: 0 | M89: 0 | N89: 0
B90: =IF(AND($C$84>C90,$C$84<=D90),1," ") | C90: 550 | D90: 600 | E90: 0.1 | F90: 0.08 | G90: 0.05 | H90: 0.03 | I90: 0.02 | J90: 0.01 | K90: 0 | L90: 0 | M90: 0 | N90: 0
B91: =IF(AND($C$84>C91,$C$84<=D91),1," ") | C91: 600 | D91: 700 | E91: 0.15 | F91: 0.1 | G91: 0.08 | H91: 0.06 | I91: 0.04 | J91: 0.02 | K91: 0.02 | L91: 0.01 | M91: 0 | N91: 0 | Q91: Plaat t.b.v. extra marge
B92: =IF(AND($C$84>C92,$C$84<=D92),1," ") | C92: 700 | D92: 800 | E92: 0.16 | F92: 0.13 | G92: 0.12 | H92: 0.08 | I92: 0.06 | J92: 0.04 | K92: 0.03 | L92: 0.02 | M92: 0.01 | N92: 0 | Q92: Hoogte | R92: Lengte | S92: =C84 -> 361 | T92: =C85 -> 1150 | U92: selectie | V92: Instelling
...

Sheet Pallet en transport
C1: Palletstapeling berekenen | D1: =IF(SUM(Rekenblad!C362:I362)=0,0,1) -> 1
C3: Breedte product t.b.v. transport | D3: =Rekenblad!F108 -> 361 | E3: mm
C4: Lengte product t.b.v. transport | D4: =Rekenblad!G108 -> 557 | E4: mm
C5: M2 per product | D5: =(D3/1000)*(D4/1000) -> 0.201077 | E5: m2
C7: B | D7: L
C8: =IF(AND($D$3>E8,$D$3<=F8),1,0) -> 0 | D8: =IF(AND($D$4>E8,$D$4<=F8),1,0) -> 0 | E8: 0 | F8: 100 | G8: 30
C9: =IF(AND($D$3>E9,$D$3<=F9),1,0) -> 0 | D9: =IF(AND($D$4>E9,$D$4<=F9),1,0) -> 0 | E9: 100 | F9: 200 | G9: 40
C10: =IF(AND($D$3>E10,$D$3<=F10),1,0) -> 0 | D10: =IF(AND($D$4>E10,$D$4<=F10),1,0) -> 0 | E10: 200 | F10: 300 | G10: 50
C11: =IF(AND($D$3>E11,$D$3<=F11),1,0) -> 1 | D11: =IF(AND($D$4>E11,$D$4<=F11),1,0) -> 0 | E11: 300 | F11: 400 | G11: 60
C12: =IF(AND($D$3>E12,$D$3<=F12),1,0) -> 0 | D12: =IF(AND($D$4>E12,$D$4<=F12),1,0) -> 0 | E12: 400 | F12: 500 | G12: 70
C13: =IF(AND($D$3>E13,$D$3<=F13),1,0) -> 0 | D13: =IF(AND($D$4>E13,$D$4<=F13),1,0) -> 1 | E13: 500 | F13: 600 | G13: 80
