Workbook

Sheet Quote
A1: BusinessLogic — Pricing Quote (v2 modular)
A3: Setting | B3: =B5 | C3: Notes
A4: Quote prepared | B4: 2026-04-17
A5: Display currency | B5: EUR | C5: EUR / USD / DKK
A6: Billing cycle | B6: Monthly | C6: Monthly / Annual
A7: Annual discount | B7: 0.17 | C7: Default 17% (12 for 10)
A9: CALCULATORS
A10: Tier | B10: Growth | C10: None / Starter / Growth / Scale | D10: Slots used | E10: =B11*1+B12*3+B13*8+B14*20
A11: # XS calculators (1 slot each) | B11: 0 | D11: Tier slot allowance | E11: =SUMIFS(Catalog!D:D,Catalog!A:A,"Calculators",Catalog!B:B,B10)
A12: # S calculators (3 slots each) | B12: 0 | D12: Tier request allowance | E12: =SUMIFS(Catalog!E:E,Catalog!A:A,"Calculators",Catalog!B:B,B10)
A13: # M calculators (8 slots each) | B13: 0 | D13: Tier always-on allowance | E13: =SUMIFS(Catalog!F:F,Catalog!A:A,"Calculators",Catalog!B:B,B10)
A14: # L calculators (20 slots each) | B14: 0 | D14: Tier base (EUR/mo) | E14: =SUMIFS(Catalog!C:C,Catalog!A:A,"Calculators",Catalog!B:B,B10)
A15: Always-on slots used | B15: 0 | D15: Slot overage | E15: =MAX(0,E10-E11)
A16: Monthly request volume | B16: 0 | D16: Request overage | E16: =MAX(0,B16-E12)
D17: Always-on overage | E17: =MAX(0,B15-E13)
D18: Slot packs (×25 @ €15) | E18: =IF(E15>0,CEILING(E15/25,1),0)
D19: Always-on packs (×10 @ €25) | E19: =IF(E17>0,CEILING(E17/10,1),0)
D20: Request packs (best fit) | E20: =IF(E16=0,0,IF(E16>=1000000,CEILING(E16/1000000,1),CEILING(E16/100000,1)))
D21: Calculators subtotal (EUR/mo) | E21: =E14+E18*15+E19*25
A23: KNOWLEDGE BASE
A24: Tier | B24: None | C24: None / Starter / Growth / Scale | D24: Tier base (EUR/mo) | E24: =SUMIFS(Catalog!C:C,Catalog!A:A,"KB",Catalog!B:B,B24)
A25: KB storage used (MB) | B25: 0 | D25: Tier storage allowance (MB) | E25: =SUMIFS(Catalog!G:G,Catalog!A:A,"KB",Catalog!B:B,B24)
A26: Monthly Q&A queries | B26: 0 | C26: Q&A draws from AI Wallet — not billed here | D26: Storage overage (MB) | E26: =MAX(0,B25-E25)
D27: Storage packs (×1 GB @ €10) | E27: =IF(E26>0,CEILING(E26/1024,1),0)
D28: KB subtotal (EUR/mo) | E28: =E24+E27*10
A30: FLOWS
A31: Tier | B31: None | C31: None / Starter / Growth / Scale | D31: Tier base (EUR/mo) | E31: =SUMIFS(Catalog!C:C,Catalog!A:A,"Flows",Catalog!B:B,B31)
A32: Monthly executions | B32: 0 | D32: Tier execution allowance | E32: =SUMIFS(Catalog!I:I,Catalog!A:A,"Flows",Catalog!B:B,B31)
D33: Execution overage | E33: =MAX(0,B32-E32)
D34: Execution packs (best fit) | E34: =IF(E33=0,0,IF(E33>=50000,CEILING(E33/50000,1),CEILING(E33/5000,1)))
D35: Flows subtotal (EUR/mo) | E35: =E31
A37: AI WALLET (usage-based, EUR)
A38: Enter projected monthly token consumption per model. Wallet draws from top-ups (€20/€50/€200, 12-mo expiry).
A39: Model | B39: Input M tok | C39: Output M tok | D39: EUR in/M | E39: EUR out/M | F39: EUR cost
A40: Claude Haiku 4.5 | B40: 0 | C40: 0 | D40: =VLOOKUP(A40,Catalog!A39:F42,2,FALSE)*VLOOKUP(A40,Catalog!A39:F42,4,FALSE)*Currency!$B$12 | E40: =VLOOKUP(A40,Catalog!A39:F42,3,FALSE)*VLOOKUP(A40,Catalog!A39:F42,4,FALSE)*Currency!$B$12 | F40: =B40*D40+C40*E40
A41: Claude Sonnet 4.6 | B41: 0 | C41: 0 | D41: =VLOOKUP(A41,Catalog!A39:F42,2,FALSE)*VLOOKUP(A41,Catalog!A39:F42,4,FALSE)*Currency!$B$12 | E41: =VLOOKUP(A41,Catalog!A39:F42,3,FALSE)*VLOOKUP(A41,Catalog!A39:F42,4,FALSE)*Currency!$B$12 | F41: =B41*D41+C41*E41
A42: Claude Opus 4.7 | B42: 0 | C42: 0 | D42: =VLOOKUP(A42,Catalog!A39:F42,2,FALSE)*VLOOKUP(A42,Catalog!A39:F42,4,FALSE)*Currency!$B$12 | E42: =VLOOKUP(A42,Catalog!A39:F42,3,FALSE)*VLOOKUP(A42,Catalog!A39:F42,4,FALSE)*Currency!$B$12 | F42: =B42*D42+C42*E42
A43: GPT-5 (est.) | B43: 0 | C43: 0 | D43: =VLOOKUP(A43,Catalog!A39:F42,2,FALSE)*VLOOKUP(A43,Catalog!A39:F42,4,FALSE)*Currency!$B$12 | E43: =VLOOKUP(A43,Catalog!A39:F42,3,FALSE)*VLOOKUP(A43,Catalog!A39:F42,4,FALSE)*Currency!$B$12 | F43: =B43*D43+C43*E43
E44: AI Wallet subtotal (EUR/mo) | F44: =SUM(F40:F43)
A46: TOTALS
...

Sheet Catalog
A1: Module | B1: Tier | C1: EUR / month | D1: Slots | E1: Requests / mo | F1: Always-on slots | G1: Storage MB | H1: Embed tokens (M) | I1: Executions / mo | J1: Concurrent runs | K1: Notes
A2: Calculators | B2: None | C2: 0 | D2: 0 | E2: 0 | F2: 0 | K2: Module disabled
A3: Calculators | B3: Starter | C3: 19 | D3: 10 | E3: 10000 | F3: 2 | K3: 3 API keys, 5 users
A4: Calculators | B4: Growth | C4: 79 | D4: 50 | E4: 100000 | F4: 10 | K4: 10 keys, per-key sub-limits
A5: Calculators | B5: Scale | C5: 299 | D5: 250 | E5: 1000000 | F5: 50 | K5: Unlimited keys, 99.95% SLA
A6: KB | B6: None | C6: 0 | G6: 0 | H6: 0 | K6: Module disabled
A7: KB | B7: Starter | C7: 15 | G7: 200 | H7: 1 | K7: 50 docs included
A8: KB | B8: Growth | C8: 49 | G8: 2000 | H8: 10 | K8: 500 docs included
A9: KB | B9: Scale | C9: 199 | G9: 20000 | H9: 100 | K9: 5000 docs, audit log 1y
A10: Flows | B10: None | C10: 0 | I10: 0 | J10: 0 | K10: Module disabled
A11: Flows | B11: Starter | C11: 19 | I11: 1000 | J11: 2 | K11: 20 steps/exec, 5 schedules
A12: Flows | B12: Growth | C12: 59 | I12: 10000 | J12: 10 | K12: 50 steps/exec, 50 schedules
A13: Flows | B13: Scale | C13: 249 | I13: 100000 | J13: 50 | K13: 200 steps/exec, unlimited
A16: Size class | B16: Built RSS (MB) | C16: Sheets | D16: Formulas | E16: Slots
A17: XS | B17: ≤ 10 | C17: ≤ 5 | D17: ≤ 500 | E17: 1
A18: S | B18: ≤ 30 | C18: ≤ 15 | D18: ≤ 5,000 | E18: 3
A19: M | B19: ≤ 80 | C19: ≤ 30 | D19: ≤ 20,000 | E19: 8
A20: L | B20: ≤ 200 | C20: ≤ 60 | D20: ≤ 50,000 | E20: 20
A21: XL | B21: > 200 | C21: > 60 | D21: > 50,000 | E21: Enterprise
A24: Module | B24: Add-on key | C24: EUR | D24: Type | E24: Adds | F24: Expiry
A25: Calculators | B25: calc_slots_25 | C25: 15 | D25: recurring | E25: +25 slots | F25: Recurring
A26: Calculators | B26: calc_alwayson_10 | C26: 25 | D26: recurring | E26: +10 always-on slots | F26: Recurring
A27: Calculators | B27: calc_requests_100k | C27: 10 | D27: one-time | E27: +100,000 requests | F27: 12 months
A28: Calculators | B28: calc_requests_1m | C28: 60 | D28: one-time | E28: +1,000,000 requests | F28: 12 months
A29: KB | B29: kb_storage_1gb | C29: 10 | D29: recurring | E29: +1 GB storage | F29: Recurring
A30: KB | B30: kb_embed_10m | C30: 8 | D30: one-time | E30: +10M embed tokens | F30: 12 months
A31: Flows | B31: flows_exec_5k | C31: 15 | D31: one-time | E31: +5,000 executions | F31: 12 months
A32: Flows | B32: flows_exec_50k | C32: 100 | D32: one-time | E32: +50,000 executions | F32: 12 months
A33: AI Wallet | B33: wallet_topup_20 | C33: 20 | D33: one-time | E33: €20 wallet credit | F33: 12 months
A34: AI Wallet | B34: wallet_topup_50 | C34: 50 | D34: one-time | E34: €50 wallet credit | F34: 12 months
A35: AI Wallet | B35: wallet_topup_200 | C35: 200 | D35: one-time | E35: €200 wallet credit | F35: 12 months
A38: Model | B38: Wholesale USD in / M tok | C38: Wholesale USD out / M tok | D38: Markup | E38: BL EUR in / M tok | F38: BL EUR out / M tok
A39: Claude Haiku 4.5 | B39: 1 | C39: 5 | D39: 1.5 | E39: =B39*D39*Currency!$B$12 | F39: =C39*D39*Currency!$B$12
A40: Claude Sonnet 4.6 | B40: 3 | C40: 15 | D40: 1.5 | E40: =B40*D40*Currency!$B$12 | F40: =C40*D40*Currency!$B$12
A41: Claude Opus 4.7 | B41: 15 | C41: 75 | D41: 1.5 | E41: =B41*D41*Currency!$B$12 | F41: =C41*D41*Currency!$B$12
A42: GPT-5 (est.) | B42: 5 | C42: 15 | D42: 1.5 | E42: =B42*D42*Currency!$B$12 | F42: =C42*D42*Currency!$B$12

Sheet Currency
A1: Currency | B1: Rate (1 EUR = ?) | C1: Symbol
A2: EUR | B2: 1 | C2: €
A3: USD | B3: 1.0865 | C3: $
A4: DKK | B4: 7.46 | C4: kr
A6: Last updated: | B6: 2026-04-17
A8: Selected currency rate (used in formulas): | B8: =VLOOKUP(Quote!$B$3,A2:B4,2,FALSE)
A10: AI Wallet rates use the EUR base rate (Currency!B3 above) — display rates are converted on the Quote sheet.
A12: USD → EUR (AI wholesale) | B12: 0.92

Sheet Scenarios
A1: Worked Examples — see businesslogic-api-pricing.md §11 for full descriptions
A3: Scenario | B3: Calc tier | C3: Calc usage | D3: KB tier / GB | E3: Flows tier / exec | F3: AI Wallet projected | G3: Total EUR/mo
A4: A — Solo consultant | B4: Starter | C4: 1×M (8 slots), 3.5k req | D4: None | E4: None | F4: — | G4: €19
A5: B — SMB calc + AI assistant | B5: Growth | C5: 3 calcs (~18 slots), 45k req | D5: None | E5: None | F5: ~€30 | G5: ~€109
A6: C — KB-driven support team | B6: None | C6: — | D6: Growth/1.2GB | E6: None | F6: ~€40 | G6: ~€89
A7: D — Full platform user | B7: Scale | C7: 60 slots, 700k req | D7: Growth/1.5GB | E7: Growth/4k exec | F7: ~€130 | G7: ~€537
A8: E — Large calc, always-on | B8: Growth | C8: 1×L (20 slots) always-on (10 over) | D8: None | E8: None | F8: — | G8: €104
A10: These are static reference scenarios. Use the Quote sheet to compute live.

Sheet COGS (internal)
A1: Internal COGS reference — do NOT show to customers
A3: Hetzner CCX23 reference | B3: 4 vCPU, 16 GB RAM, ≈ €30/mo
A4: Memory cost per MB-month | B4: =30/16384
A5: CPU cost per CPU-hour | B5: =30/(4*730)
A7: Tier | B7: Memory cost (€) | C7: Compute cost (€) | D7: Misc (€) | E7: Est. COGS (€) | F7: Tier price (€) | G7: Margin %
A8: Calc Starter | B8: 0.16 | C8: 0.1 | D8: 0.14 | E8: =B8+C8+D8 | F8: 19 | G8: =(F8-E8)/F8
A9: Calc Growth | B9: 0.8 | C9: 1.1 | D9: 0.2 | E9: =B9+C9+D9 | F9: 79 | G9: =(F9-E9)/F9
A10: Calc Scale | B10: 4.1 | C10: 5.5 | D10: 0.9 | E10: =B10+C10+D10 | F10: 299 | G10: =(F10-E10)/F10
A11: KB Starter | B11: 0.02 | C11: 0.1 | D11: 0.03 | E11: =B11+C11+D11 | F11: 15 | G11: =(F11-E11)/F11
A12: KB Growth | B12: 0.2 | C12: 1 | D12: 0.3 | E12: =B12+C12+D12 | F12: 49 | G12: =(F12-E12)/F12
A13: KB Scale | B13: 2 | C13: 10 | D13: 1 | E13: =B13+C13+D13 | F13: 199 | G13: =(F13-E13)/F13
A14: Flows Starter | B14: 0.05 | C14: 0.2 | D14: 0.05 | E14: =B14+C14+D14 | F14: 19 | G14: =(F14-E14)/F14
A15: Flows Growth | B15: 0.2 | C15: 1.1 | D15: 0.2 | E15: =B15+C15+D15 | F15: 59 | G15: =(F15-E15)/F15
A16: Flows Scale | B16: 2 | C16: 5.5 | D16: 0.5 | E16: =B16+C16+D16 | F16: 249 | G16: =(F16-E16)/F16
A18: AI Wallet
A19: Markup factor | B19: 1.5
A20: Gross margin on AI Wallet revenue | B20: =(B19-1)/B19
A21: After overhead (~5% of revenue) | B21: =B20-0.05
A23: Healthy revenue mix target: AI Wallet 25–40% of total. Modules carry margin; AI carries engagement.
